 * Tip: There are .env files present. Install python-dotenv to use them.
Starting AlphaVox system...
 * Serving Flask app 'simple_alphavox'
 * Debug mode: on
INFO:werkzeug:[31m[1mWARNING: This is a development server. Do not use it in a production deployment. Use a production WSGI server instead.[0m
 * Running on all addresses (0.0.0.0)
 * Running on http://127.0.0.1:8080
 * Running on http://172.31.128.50:8080
INFO:werkzeug:[33mPress CTRL+C to quit[0m
INFO:werkzeug: * Restarting with stat
 * Tip: There are .env files present. Install python-dotenv to use them.
WARNING:werkzeug: * Debugger is active!
INFO:werkzeug: * Debugger PIN: 130-386-459
2025-05-03 23:24:35,721 - __main__ - INFO - Starting AlphaVox System...
2025-05-03 23:24:36,028 - learning_engine - INFO - Loaded 5 topics
2025-05-03 23:24:36,029 - learning_engine - INFO - Loaded 5 facts
2025-05-03 23:24:36,029 - learning_engine - INFO - Loaded knowledge base with 3 entries
2025-05-03 23:24:36,029 - learning_engine - INFO - Loaded knowledge graph with 5 nodes and 0 links
2025-05-03 23:24:36,029 - learning_engine - INFO - Loaded learning log with 0 entries
2025-05-03 23:24:36,030 - learning_engine - INFO - Loaded crawler status
2025-05-03 23:24:36,030 - learning_engine - INFO - Learning Engine initialized successfully
2025-05-03 23:24:36,035 - learning_engine - INFO - Loaded 5 topics
2025-05-03 23:24:36,036 - learning_engine - INFO - Loaded 5 facts
2025-05-03 23:24:36,036 - learning_engine - INFO - Loaded knowledge base with 3 entries
2025-05-03 23:24:36,036 - learning_engine - INFO - Loaded knowledge graph with 5 nodes and 0 links
2025-05-03 23:24:36,036 - learning_engine - INFO - Loaded learning log with 0 entries
2025-05-03 23:24:36,036 - learning_engine - INFO - Loaded crawler status
2025-05-03 23:24:36,036 - learning_engine - INFO - Learning Engine initialized successfully
2025-05-03 23:26:47,546 - __main__ - INFO - Starting AlphaVox System...
2025-05-03 23:26:47,793 - learning_engine - INFO - Loaded 5 topics
2025-05-03 23:26:47,793 - learning_engine - INFO - Loaded 5 facts
2025-05-03 23:26:47,793 - learning_engine - INFO - Loaded knowledge base with 3 entries
2025-05-03 23:26:47,793 - learning_engine - INFO - Loaded knowledge graph with 5 nodes and 0 links
2025-05-03 23:26:47,794 - learning_engine - INFO - Loaded learning log with 0 entries
2025-05-03 23:26:47,794 - learning_engine - INFO - Loaded crawler status
2025-05-03 23:26:47,794 - learning_engine - INFO - Learning Engine initialized successfully
2025-05-03 23:26:47,800 - learning_engine - INFO - Loaded 5 topics
2025-05-03 23:26:47,800 - learning_engine - INFO - Loaded 5 facts
2025-05-03 23:26:47,800 - learning_engine - INFO - Loaded knowledge base with 3 entries
2025-05-03 23:26:47,800 - learning_engine - INFO - Loaded knowledge graph with 5 nodes and 0 links
2025-05-03 23:26:47,801 - learning_engine - INFO - Loaded learning log with 0 entries
2025-05-03 23:26:47,801 - learning_engine - INFO - Loaded crawler status
2025-05-03 23:26:47,801 - learning_engine - INFO - Learning Engine initialized successfully
2025-05-03 23:32:05,105 - __main__ - INFO - Starting AlphaVox System...
2025-05-03 23:32:05,290 - learning_engine - INFO - Loaded 5 topics
2025-05-03 23:32:05,290 - learning_engine - INFO - Loaded 5 facts
2025-05-03 23:32:05,291 - learning_engine - INFO - Loaded knowledge base with 3 entries
2025-05-03 23:32:05,291 - learning_engine - INFO - Loaded knowledge graph with 5 nodes and 0 links
2025-05-03 23:32:05,291 - learning_engine - INFO - Loaded learning log with 0 entries
2025-05-03 23:32:05,291 - learning_engine - INFO - Loaded crawler status
2025-05-03 23:32:05,291 - learning_engine - INFO - Learning Engine initialized successfully
2025-05-03 23:32:05,297 - learning_engine - INFO - Loaded 5 topics
2025-05-03 23:32:05,297 - learning_engine - INFO - Loaded 5 facts
2025-05-03 23:32:05,297 - learning_engine - INFO - Loaded knowledge base with 3 entries
2025-05-03 23:32:05,297 - learning_engine - INFO - Loaded knowledge graph with 5 nodes and 0 links
2025-05-03 23:32:05,297 - learning_engine - INFO - Loaded learning log with 0 entries
2025-05-03 23:32:05,297 - learning_engine - INFO - Loaded crawler status
2025-05-03 23:32:05,297 - learning_engine - INFO - Learning Engine initialized successfully
2025-05-03 23:32:48,214 - __main__ - INFO - Starting AlphaVox System...
2025-05-03 23:32:48,538 - learning_engine - INFO - Loaded 5 topics
2025-05-03 23:32:48,538 - learning_engine - INFO - Loaded 5 facts
2025-05-03 23:32:48,539 - learning_engine - INFO - Loaded knowledge base with 3 entries
2025-05-03 23:32:48,539 - learning_engine - INFO - Loaded knowledge graph with 5 nodes and 0 links
2025-05-03 23:32:48,539 - learning_engine - INFO - Loaded learning log with 0 entries
2025-05-03 23:32:48,539 - learning_engine - INFO - Loaded crawler status
2025-05-03 23:32:48,539 - learning_engine - INFO - Learning Engine initialized successfully
2025-05-03 23:32:48,548 - learning_engine - INFO - Loaded 5 topics
2025-05-03 23:32:48,549 - learning_engine - INFO - Loaded 5 facts
2025-05-03 23:32:48,549 - learning_engine - INFO - Loaded knowledge base with 3 entries
2025-05-03 23:32:48,549 - learning_engine - INFO - Loaded knowledge graph with 5 nodes and 0 links
2025-05-03 23:32:48,549 - learning_engine - INFO - Loaded learning log with 0 entries
2025-05-03 23:32:48,550 - learning_engine - INFO - Loaded crawler status
2025-05-03 23:32:48,550 - learning_engine - INFO - Learning Engine initialized successfully
2025-05-05 03:41:43,159 - __main__ - INFO - Starting AlphaVox service initialization in background
2025-05-05 03:41:55,117 - __main__ - INFO - Starting AlphaVox service initialization in background
2025-05-05 03:41:55,118 - __main__ - INFO - Attempting to start on port 8080
2025-05-05 03:41:55,267 - werkzeug - INFO - [31m[1mWARNING: This is a development server. Do not use it in a production deployment. Use a production WSGI server instead.[0m
 * Running on all addresses (0.0.0.0)
 * Running on http://127.0.0.1:8080
 * Running on http://172.31.128.64:8080
2025-05-05 03:41:55,267 - werkzeug - INFO - [33mPress CTRL+C to quit[0m
2025-05-05 03:41:55,272 - werkzeug - INFO -  * Restarting with stat
2025-05-05 03:41:55,549 - eye_tracking_service - WARNING - Real eye tracking not available: cannot import name 'RealEyeTracking' from 'real_eye_tracking' (/home/runner/workspace/real_eye_tracking.py)
2025-05-05 03:41:55,549 - eye_tracking_service - INFO - Using simulated eye tracking
2025-05-05 03:41:55,550 - __main__ - INFO - Eye tracking service initialized
2025-05-05 03:41:55,870 - __main__ - INFO - Starting AlphaVox service initialization in background
2025-05-05 03:41:55,871 - __main__ - INFO - Attempting to start on port 8080
2025-05-05 03:41:56,106 - werkzeug - WARNING -  * Debugger is active!
2025-05-05 03:41:56,188 - werkzeug - INFO -  * Debugger PIN: 678-281-929
2025-05-05 03:41:56,224 - sound_recognition_service - WARNING - Real sound recognition not available: cannot import name 'RealSpeechRecognition' from 'real_speech_recognition' (/home/runner/workspace/real_speech_recognition.py)
2025-05-05 03:41:56,227 - sound_recognition_service - INFO - Using simulated sound recognition
2025-05-05 03:41:56,228 - __main__ - INFO - Sound recognition service initialized
2025-05-05 03:41:56,233 - __main__ - WARNING - Error initializing learning journey: cannot import name 'get_learning_journey_service' from 'learning_journey' (/home/runner/workspace/learning_journey.py)
2025-05-05 03:41:56,239 - nonverbal_engine - INFO - Successfully imported NonverbalEngine from nonverbal_bull
2025-05-05 03:41:56,240 - nonverbal_bull - INFO - Initializing NonverbalEngine with self-learning capabilities
2025-05-05 03:41:56,240 - nonverbal_bull - INFO - NonverbalEngine initialized with self-modification capabilities
2025-05-05 03:41:56,241 - __main__ - INFO - Nonverbal engine initialized
2025-05-05 03:41:56,244 - conversation_engine - INFO - Using advanced NLP mode
2025-05-05 03:41:56,244 - root - WARNING - Perplexity API not available: No module named 'perplexity'
2025-05-05 03:41:56,250 - conversation_engine - INFO - Conversation engine initialized
2025-05-05 03:41:56,250 - __main__ - INFO - Conversation engine initialized
2025-05-05 03:41:56,251 - __main__ - INFO - AlphaVox services initialization completed successfully
2025-05-05 03:41:56,413 - eye_tracking_service - WARNING - Real eye tracking not available: cannot import name 'RealEyeTracking' from 'real_eye_tracking' (/home/runner/workspace/real_eye_tracking.py)
2025-05-05 03:41:56,414 - eye_tracking_service - INFO - Using simulated eye tracking
2025-05-05 03:41:56,414 - __main__ - INFO - Eye tracking service initialized
2025-05-05 03:41:56,820 - werkzeug - INFO - 172.31.128.64 - - [05/May/2025 03:41:56] "[35m[1mGET / HTTP/1.1[0m" 500 -
2025-05-05 03:41:57,069 - sound_recognition_service - WARNING - Real sound recognition not available: cannot import name 'RealSpeechRecognition' from 'real_speech_recognition' (/home/runner/workspace/real_speech_recognition.py)
2025-05-05 03:41:57,071 - sound_recognition_service - INFO - Using simulated sound recognition
2025-05-05 03:41:57,072 - __main__ - INFO - Sound recognition service initialized
2025-05-05 03:41:57,078 - __main__ - WARNING - Error initializing learning journey: cannot import name 'get_learning_journey_service' from 'learning_journey' (/home/runner/workspace/learning_journey.py)
2025-05-05 03:41:57,085 - nonverbal_engine - INFO - Successfully imported NonverbalEngine from nonverbal_bull
2025-05-05 03:41:57,087 - nonverbal_bull - INFO - Initializing NonverbalEngine with self-learning capabilities
2025-05-05 03:41:57,091 - nonverbal_bull - INFO - NonverbalEngine initialized with self-modification capabilities
2025-05-05 03:41:57,092 - __main__ - INFO - Nonverbal engine initialized
2025-05-05 03:41:57,096 - conversation_engine - INFO - Using advanced NLP mode
2025-05-05 03:41:57,101 - root - WARNING - Perplexity API not available: No module named 'perplexity'
2025-05-05 03:41:57,104 - conversation_engine - INFO - Conversation engine initialized
2025-05-05 03:41:57,106 - __main__ - INFO - Conversation engine initialized
2025-05-05 03:41:57,106 - __main__ - INFO - AlphaVox services initialization completed successfully
2025-05-05 03:41:57,288 - werkzeug - INFO - 172.31.128.64 - - [05/May/2025 03:41:57] "[36mGET /?__debugger__=yes&cmd=resource&f=debugger.js HTTP/1.1[0m" 304 -
2025-05-05 03:41:57,334 - werkzeug - INFO - 172.31.128.64 - - [05/May/2025 03:41:57] "[36mGET /?__debugger__=yes&cmd=resource&f=style.css HTTP/1.1[0m" 304 -
2025-05-05 03:42:27,001 - __main__ - INFO - Starting AlphaVox service initialization in background
2025-05-05 03:42:27,001 - __main__ - INFO - Attempting to start on port 8080
2025-05-05 03:42:27,154 - werkzeug - INFO - [31m[1mWARNING: This is a development server. Do not use it in a production deployment. Use a production WSGI server instead.[0m
 * Running on all addresses (0.0.0.0)
 * Running on http://127.0.0.1:8080
 * Running on http://172.31.128.64:8080
2025-05-05 03:42:27,154 - werkzeug - INFO - [33mPress CTRL+C to quit[0m
2025-05-05 03:42:27,165 - werkzeug - INFO -  * Restarting with stat
2025-05-05 03:42:27,364 - eye_tracking_service - WARNING - Real eye tracking not available: cannot import name 'RealEyeTracking' from 'real_eye_tracking' (/home/runner/workspace/real_eye_tracking.py)
2025-05-05 03:42:27,365 - eye_tracking_service - INFO - Using simulated eye tracking
2025-05-05 03:42:27,365 - __main__ - INFO - Eye tracking service initialized
2025-05-05 03:42:27,756 - __main__ - INFO - Starting AlphaVox service initialization in background
2025-05-05 03:42:27,757 - __main__ - INFO - Attempting to start on port 8080
2025-05-05 03:42:27,889 - werkzeug - WARNING -  * Debugger is active!
2025-05-05 03:42:27,971 - werkzeug - INFO -  * Debugger PIN: 724-934-093
2025-05-05 03:42:28,111 - sound_recognition_service - WARNING - Real sound recognition not available: cannot import name 'RealSpeechRecognition' from 'real_speech_recognition' (/home/runner/workspace/real_speech_recognition.py)
2025-05-05 03:42:28,111 - sound_recognition_service - INFO - Using simulated sound recognition
2025-05-05 03:42:28,112 - __main__ - INFO - Sound recognition service initialized
2025-05-05 03:42:28,114 - __main__ - WARNING - Error initializing learning journey: cannot import name 'get_learning_journey_service' from 'learning_journey' (/home/runner/workspace/learning_journey.py)
2025-05-05 03:42:28,118 - nonverbal_engine - INFO - Successfully imported NonverbalEngine from nonverbal_bull
2025-05-05 03:42:28,118 - nonverbal_bull - INFO - Initializing NonverbalEngine with self-learning capabilities
2025-05-05 03:42:28,119 - nonverbal_bull - INFO - NonverbalEngine initialized with self-modification capabilities
2025-05-05 03:42:28,120 - __main__ - INFO - Nonverbal engine initialized
2025-05-05 03:42:28,123 - conversation_engine - INFO - Using advanced NLP mode
2025-05-05 03:42:28,125 - root - WARNING - Perplexity API not available: No module named 'perplexity'
2025-05-05 03:42:28,127 - conversation_engine - INFO - Conversation engine initialized
2025-05-05 03:42:28,127 - __main__ - INFO - Conversation engine initialized
2025-05-05 03:42:28,128 - __main__ - INFO - AlphaVox services initialization completed successfully
2025-05-05 03:42:28,252 - eye_tracking_service - WARNING - Real eye tracking not available: cannot import name 'RealEyeTracking' from 'real_eye_tracking' (/home/runner/workspace/real_eye_tracking.py)
2025-05-05 03:42:28,253 - eye_tracking_service - INFO - Using simulated eye tracking
2025-05-05 03:42:28,254 - __main__ - INFO - Eye tracking service initialized
2025-05-05 03:42:28,602 - werkzeug - INFO - 172.31.128.64 - - [05/May/2025 03:42:28] "GET / HTTP/1.1" 200 -
2025-05-05 03:42:29,021 - sound_recognition_service - WARNING - Real sound recognition not available: cannot import name 'RealSpeechRecognition' from 'real_speech_recognition' (/home/runner/workspace/real_speech_recognition.py)
2025-05-05 03:42:29,022 - sound_recognition_service - INFO - Using simulated sound recognition
2025-05-05 03:42:29,022 - __main__ - INFO - Sound recognition service initialized
2025-05-05 03:42:29,029 - __main__ - WARNING - Error initializing learning journey: cannot import name 'get_learning_journey_service' from 'learning_journey' (/home/runner/workspace/learning_journey.py)
2025-05-05 03:42:29,037 - nonverbal_engine - INFO - Successfully imported NonverbalEngine from nonverbal_bull
2025-05-05 03:42:29,038 - nonverbal_bull - INFO - Initializing NonverbalEngine with self-learning capabilities
2025-05-05 03:42:29,047 - nonverbal_bull - INFO - NonverbalEngine initialized with self-modification capabilities
2025-05-05 03:42:29,050 - __main__ - INFO - Nonverbal engine initialized
2025-05-05 03:42:29,062 - conversation_engine - INFO - Using advanced NLP mode
2025-05-05 03:42:29,066 - root - WARNING - Perplexity API not available: No module named 'perplexity'
2025-05-05 03:42:29,068 - conversation_engine - INFO - Conversation engine initialized
2025-05-05 03:42:29,068 - __main__ - INFO - Conversation engine initialized
2025-05-05 03:42:29,068 - __main__ - INFO - AlphaVox services initialization completed successfully
2025-05-05 03:42:32,037 - werkzeug - INFO - 172.31.128.64 - - [05/May/2025 03:42:32] "GET /api/status HTTP/1.1" 200 -
2025-05-05 03:45:43,682 - __main__ - INFO - AlphaVox launcher initializing...
2025-05-05 03:45:43,682 - __main__ - INFO - Database URL configured: postgresql...
2025-05-05 03:45:43,682 - __main__ - INFO - OPENAI_API_KEY is set
2025-05-05 03:45:43,682 - __main__ - INFO - ANTHROPIC_API_KEY is set
2025-05-05 03:45:43,682 - __main__ - INFO - Starting AlphaVox System...
2025-05-05 03:46:17,102 - root - INFO - Connecting to database: neondb_owner:npg_IxHh7rq0jAcT@[hidden]
2025-05-05 03:46:18,187 - __main__ - INFO - Successfully imported app from app_init
2025-05-05 03:46:18,199 - __main__ - INFO - Starting AlphaVox service initialization in background
2025-05-05 03:46:18,200 - __main__ - INFO - 🚀 Starting AlphaVox on http://0.0.0.0:8080
2025-05-05 03:46:18,201 - __main__ - INFO - AlphaVox services initialization completed successfully
2025-05-05 03:46:18,275 - werkzeug - INFO - [31m[1mWARNING: This is a development server. Do not use it in a production deployment. Use a production WSGI server instead.[0m
 * Running on all addresses (0.0.0.0)
 * Running on http://127.0.0.1:8080
 * Running on http://172.31.128.64:8080
2025-05-05 03:46:18,275 - werkzeug - INFO - [33mPress CTRL+C to quit[0m
2025-05-05 03:46:18,280 - werkzeug - INFO -  * Restarting with stat
2025-05-05 03:46:19,285 - root - INFO - Connecting to database: neondb_owner:npg_IxHh7rq0jAcT@[hidden]
2025-05-05 03:46:20,271 - __main__ - INFO - Successfully imported app from app_init
2025-05-05 03:46:20,274 - __main__ - INFO - Starting AlphaVox service initialization in background
2025-05-05 03:46:20,274 - __main__ - INFO - 🚀 Starting AlphaVox on http://0.0.0.0:8080
2025-05-05 03:46:20,275 - __main__ - INFO - AlphaVox services initialization completed successfully
2025-05-05 03:46:20,334 - werkzeug - WARNING -  * Debugger is active!
2025-05-05 03:46:20,357 - werkzeug - INFO -  * Debugger PIN: 106-793-734
2025-05-05 03:51:34,644 - __main__ - INFO - Starting AlphaVox service initialization in background
2025-05-05 03:51:34,644 - __main__ - INFO - Attempting to start on port 8080
2025-05-05 03:51:34,881 - werkzeug - INFO - [31m[1mWARNING: This is a development server. Do not use it in a production deployment. Use a production WSGI server instead.[0m
 * Running on all addresses (0.0.0.0)
 * Running on http://127.0.0.1:8080
 * Running on http://172.31.128.64:8080
2025-05-05 03:51:34,882 - werkzeug - INFO - [33mPress CTRL+C to quit[0m
2025-05-05 03:51:34,889 - werkzeug - INFO -  * Restarting with stat
2025-05-05 03:51:35,176 - eye_tracking_service - WARNING - Real eye tracking not available: cannot import name 'RealEyeTracking' from 'real_eye_tracking' (/home/runner/workspace/real_eye_tracking.py)
2025-05-05 03:51:35,181 - eye_tracking_service - INFO - Using simulated eye tracking
2025-05-05 03:51:35,183 - __main__ - INFO - Eye tracking service initialized
2025-05-05 03:51:35,928 - __main__ - INFO - Starting AlphaVox service initialization in background
2025-05-05 03:51:35,928 - __main__ - INFO - Attempting to start on port 8080
2025-05-05 03:51:36,113 - werkzeug - WARNING -  * Debugger is active!
2025-05-05 03:51:36,154 - werkzeug - INFO -  * Debugger PIN: 207-563-633
2025-05-05 03:51:36,199 - sound_recognition_service - WARNING - Real sound recognition not available: cannot import name 'RealSpeechRecognition' from 'real_speech_recognition' (/home/runner/workspace/real_speech_recognition.py)
2025-05-05 03:51:36,202 - sound_recognition_service - INFO - Using simulated sound recognition
2025-05-05 03:51:36,204 - __main__ - INFO - Sound recognition service initialized
2025-05-05 03:51:36,208 - __main__ - WARNING - Error initializing learning journey: cannot import name 'get_learning_journey_service' from 'learning_journey' (/home/runner/workspace/learning_journey.py)
2025-05-05 03:51:36,233 - nonverbal_engine - INFO - Successfully imported NonverbalEngine from nonverbal_bull
2025-05-05 03:51:36,241 - nonverbal_bull - INFO - Initializing NonverbalEngine with self-learning capabilities
2025-05-05 03:51:36,258 - nonverbal_bull - INFO - NonverbalEngine initialized with self-modification capabilities
2025-05-05 03:51:36,258 - __main__ - INFO - Nonverbal engine initialized
2025-05-05 03:51:36,261 - conversation_engine - INFO - Using advanced NLP mode
2025-05-05 03:51:36,263 - root - WARNING - Perplexity API not available: No module named 'perplexity'
2025-05-05 03:51:36,271 - conversation_engine - INFO - Conversation engine initialized
2025-05-05 03:51:36,271 - __main__ - INFO - Conversation engine initialized
2025-05-05 03:51:36,271 - __main__ - INFO - AlphaVox services initialization completed successfully
2025-05-05 03:51:36,556 - eye_tracking_service - WARNING - Real eye tracking not available: cannot import name 'RealEyeTracking' from 'real_eye_tracking' (/home/runner/workspace/real_eye_tracking.py)
2025-05-05 03:51:36,558 - eye_tracking_service - INFO - Using simulated eye tracking
2025-05-05 03:51:36,561 - __main__ - INFO - Eye tracking service initialized
2025-05-05 03:51:37,391 - sound_recognition_service - WARNING - Real sound recognition not available: cannot import name 'RealSpeechRecognition' from 'real_speech_recognition' (/home/runner/workspace/real_speech_recognition.py)
2025-05-05 03:51:37,392 - sound_recognition_service - INFO - Using simulated sound recognition
2025-05-05 03:51:37,393 - __main__ - INFO - Sound recognition service initialized
2025-05-05 03:51:37,394 - __main__ - WARNING - Error initializing learning journey: cannot import name 'get_learning_journey_service' from 'learning_journey' (/home/runner/workspace/learning_journey.py)
2025-05-05 03:51:37,396 - nonverbal_engine - INFO - Successfully imported NonverbalEngine from nonverbal_bull
2025-05-05 03:51:37,397 - nonverbal_bull - INFO - Initializing NonverbalEngine with self-learning capabilities
2025-05-05 03:51:37,398 - nonverbal_bull - INFO - NonverbalEngine initialized with self-modification capabilities
2025-05-05 03:51:37,398 - __main__ - INFO - Nonverbal engine initialized
2025-05-05 03:51:37,402 - conversation_engine - INFO - Using advanced NLP mode
2025-05-05 03:51:37,404 - root - WARNING - Perplexity API not available: No module named 'perplexity'
2025-05-05 03:51:37,405 - conversation_engine - INFO - Conversation engine initialized
2025-05-05 03:51:37,406 - __main__ - INFO - Conversation engine initialized
2025-05-05 03:51:37,422 - __main__ - INFO - AlphaVox services initialization completed successfully
2025-05-05 03:52:00,119 - __main__ - INFO - Starting AlphaVox service initialization in background
2025-05-05 03:52:00,119 - __main__ - INFO - Attempting to start on port 8080
2025-05-05 03:52:00,269 - werkzeug - INFO - [31m[1mWARNING: This is a development server. Do not use it in a production deployment. Use a production WSGI server instead.[0m
 * Running on all addresses (0.0.0.0)
 * Running on http://127.0.0.1:8080
 * Running on http://172.31.128.64:8080
2025-05-05 03:52:00,271 - werkzeug - INFO - [33mPress CTRL+C to quit[0m
2025-05-05 03:52:00,276 - werkzeug - INFO -  * Restarting with stat
2025-05-05 03:52:00,668 - eye_tracking_service - WARNING - Real eye tracking not available: cannot import name 'RealEyeTracking' from 'real_eye_tracking' (/home/runner/workspace/real_eye_tracking.py)
2025-05-05 03:52:00,670 - eye_tracking_service - INFO - Using simulated eye tracking
2025-05-05 03:52:00,671 - __main__ - INFO - Eye tracking service initialized
2025-05-05 03:52:01,169 - __main__ - INFO - Starting AlphaVox service initialization in background
2025-05-05 03:52:01,169 - __main__ - INFO - Attempting to start on port 8080
2025-05-05 03:52:01,384 - werkzeug - WARNING -  * Debugger is active!
2025-05-05 03:52:01,425 - werkzeug - INFO -  * Debugger PIN: 121-334-798
2025-05-05 03:52:01,707 - eye_tracking_service - WARNING - Real eye tracking not available: cannot import name 'RealEyeTracking' from 'real_eye_tracking' (/home/runner/workspace/real_eye_tracking.py)
2025-05-05 03:52:01,708 - eye_tracking_service - INFO - Using simulated eye tracking
2025-05-05 03:52:01,710 - __main__ - INFO - Eye tracking service initialized
2025-05-05 03:52:02,359 - sound_recognition_service - WARNING - Real sound recognition not available: cannot import name 'RealSpeechRecognition' from 'real_speech_recognition' (/home/runner/workspace/real_speech_recognition.py)
2025-05-05 03:52:02,361 - sound_recognition_service - INFO - Using simulated sound recognition
2025-05-05 03:52:02,361 - __main__ - INFO - Sound recognition service initialized
2025-05-05 03:52:02,369 - __main__ - WARNING - Error initializing learning journey: cannot import name 'get_learning_journey_service' from 'learning_journey' (/home/runner/workspace/learning_journey.py)
2025-05-05 03:52:02,391 - nonverbal_engine - INFO - Successfully imported NonverbalEngine from nonverbal_bull
2025-05-05 03:52:02,391 - nonverbal_bull - INFO - Initializing NonverbalEngine with self-learning capabilities
2025-05-05 03:52:02,397 - nonverbal_bull - INFO - NonverbalEngine initialized with self-modification capabilities
2025-05-05 03:52:02,398 - __main__ - INFO - Nonverbal engine initialized
2025-05-05 03:52:02,399 - conversation_engine - INFO - Using advanced NLP mode
2025-05-05 03:52:02,400 - root - WARNING - Perplexity API not available: No module named 'perplexity'
2025-05-05 03:52:02,401 - conversation_engine - INFO - Conversation engine initialized
2025-05-05 03:52:02,401 - __main__ - INFO - Conversation engine initialized
2025-05-05 03:52:02,402 - __main__ - INFO - AlphaVox services initialization completed successfully
2025-05-05 03:52:02,554 - sound_recognition_service - WARNING - Real sound recognition not available: cannot import name 'RealSpeechRecognition' from 'real_speech_recognition' (/home/runner/workspace/real_speech_recognition.py)
2025-05-05 03:52:02,554 - sound_recognition_service - INFO - Using simulated sound recognition
2025-05-05 03:52:02,554 - __main__ - INFO - Sound recognition service initialized
2025-05-05 03:52:02,558 - __main__ - WARNING - Error initializing learning journey: cannot import name 'get_learning_journey_service' from 'learning_journey' (/home/runner/workspace/learning_journey.py)
2025-05-05 03:52:02,561 - nonverbal_engine - INFO - Successfully imported NonverbalEngine from nonverbal_bull
2025-05-05 03:52:02,562 - nonverbal_bull - INFO - Initializing NonverbalEngine with self-learning capabilities
2025-05-05 03:52:02,563 - nonverbal_bull - INFO - NonverbalEngine initialized with self-modification capabilities
2025-05-05 03:52:02,563 - __main__ - INFO - Nonverbal engine initialized
2025-05-05 03:52:02,565 - conversation_engine - INFO - Using advanced NLP mode
2025-05-05 03:52:02,566 - root - WARNING - Perplexity API not available: No module named 'perplexity'
2025-05-05 03:52:02,567 - conversation_engine - INFO - Conversation engine initialized
2025-05-05 03:52:02,568 - __main__ - INFO - Conversation engine initialized
2025-05-05 03:52:02,568 - __main__ - INFO - AlphaVox services initialization completed successfully
2025-05-05 03:52:29,782 - root - INFO - Connecting to database: neondb_owner:npg_IxHh7rq0jAcT@[hidden]
2025-05-05 03:52:30,822 - __main__ - INFO - Successfully imported app from app_init
2025-05-05 03:52:30,823 - __main__ - INFO - Starting AlphaVox service initialization in background
2025-05-05 03:52:30,823 - __main__ - INFO - AlphaVox services initialization completed successfully
2025-05-05 03:52:30,823 - __main__ - INFO - 🚀 Starting AlphaVox on http://0.0.0.0:8080
2025-05-05 03:52:30,898 - werkzeug - INFO - [31m[1mWARNING: This is a development server. Do not use it in a production deployment. Use a production WSGI server instead.[0m
 * Running on all addresses (0.0.0.0)
 * Running on http://127.0.0.1:8080
 * Running on http://172.31.128.64:8080
2025-05-05 03:52:30,898 - werkzeug - INFO - [33mPress CTRL+C to quit[0m
2025-05-05 03:52:30,899 - werkzeug - INFO -  * Restarting with stat
2025-05-05 03:52:31,598 - root - INFO - Connecting to database: neondb_owner:npg_IxHh7rq0jAcT@[hidden]
2025-05-05 03:52:32,487 - __main__ - INFO - Successfully imported app from app_init
2025-05-05 03:52:32,489 - __main__ - INFO - Starting AlphaVox service initialization in background
2025-05-05 03:52:32,489 - __main__ - INFO - 🚀 Starting AlphaVox on http://0.0.0.0:8080
2025-05-05 03:52:32,489 - __main__ - INFO - AlphaVox services initialization completed successfully
2025-05-05 03:52:32,545 - werkzeug - WARNING -  * Debugger is active!
2025-05-05 03:52:32,553 - werkzeug - INFO -  * Debugger PIN: 655-859-991
2025-05-05 03:52:37,018 - werkzeug - INFO -  * Detected change in '/home/runner/workspace/alphavox_server.py', reloading
2025-05-05 03:52:37,117 - werkzeug - INFO -  * Restarting with stat
2025-05-05 03:52:37,764 - root - INFO - Connecting to database: neondb_owner:npg_IxHh7rq0jAcT@[hidden]
2025-05-05 03:52:38,628 - __main__ - INFO - Successfully imported app from app_init
2025-05-05 03:52:38,629 - __main__ - INFO - Starting AlphaVox service initialization in background
2025-05-05 03:52:38,630 - __main__ - INFO - AlphaVox services initialization completed successfully
2025-05-05 03:52:38,630 - __main__ - INFO - 🚀 Starting AlphaVox on http://0.0.0.0:8080
2025-05-05 03:52:38,666 - werkzeug - WARNING -  * Debugger is active!
2025-05-05 03:52:38,671 - werkzeug - INFO -  * Debugger PIN: 572-600-407
2025-05-05 03:55:29,253 - root - INFO - Connecting to database: neondb_owner:npg_IxHh7rq0jAcT@[hidden]
2025-05-05 03:55:32,584 - __main__ - INFO - Successfully imported app from app_init
2025-05-05 03:55:32,584 - __main__ - INFO - Starting AlphaVox service initialization in background
2025-05-05 03:55:32,584 - __main__ - INFO - 🚀 Starting AlphaVox on http://0.0.0.0:8080
2025-05-05 03:55:32,585 - __main__ - INFO - AlphaVox services initialization completed successfully
2025-05-05 03:55:32,620 - werkzeug - INFO - [31m[1mWARNING: This is a development server. Do not use it in a production deployment. Use a production WSGI server instead.[0m
 * Running on all addresses (0.0.0.0)
 * Running on http://127.0.0.1:8080
 * Running on http://172.31.128.64:8080
2025-05-05 03:55:32,621 - werkzeug - INFO - [33mPress CTRL+C to quit[0m
2025-05-05 03:55:32,621 - werkzeug - INFO -  * Restarting with stat
2025-05-05 03:55:33,045 - root - INFO - Connecting to database: neondb_owner:npg_IxHh7rq0jAcT@[hidden]
2025-05-05 03:55:33,915 - __main__ - INFO - Successfully imported app from app_init
2025-05-05 03:55:33,915 - __main__ - INFO - Starting AlphaVox service initialization in background
2025-05-05 03:55:33,916 - __main__ - INFO - AlphaVox services initialization completed successfully
2025-05-05 03:55:33,916 - __main__ - INFO - 🚀 Starting AlphaVox on http://0.0.0.0:8080
2025-05-05 03:55:33,942 - werkzeug - WARNING -  * Debugger is active!
2025-05-05 03:55:33,945 - werkzeug - INFO -  * Debugger PIN: 132-625-710
2025-05-05 03:57:05,515 - werkzeug - INFO -  * Detected change in '/home/runner/workspace/app_simple.py', reloading
2025-05-05 03:57:05,624 - werkzeug - INFO -  * Restarting with stat
2025-05-05 03:57:06,121 - root - INFO - Connecting to database: neondb_owner:npg_IxHh7rq0jAcT@[hidden]
2025-05-05 03:57:07,034 - __main__ - INFO - Successfully imported app from app_init
2025-05-05 03:57:07,034 - __main__ - INFO - Starting AlphaVox service initialization in background
2025-05-05 03:57:07,034 - __main__ - INFO - 🚀 Starting AlphaVox on http://0.0.0.0:8080
2025-05-05 03:57:07,034 - __main__ - INFO - AlphaVox services initialization completed successfully
2025-05-05 03:57:07,065 - werkzeug - WARNING -  * Debugger is active!
2025-05-05 03:57:07,072 - werkzeug - INFO -  * Debugger PIN: 847-048-920
2025-05-05 03:57:51,866 - werkzeug - INFO -  * Detected change in '/home/runner/workspace/app_simple.py', reloading
2025-05-05 03:57:51,935 - werkzeug - INFO -  * Restarting with stat
2025-05-05 03:57:52,371 - root - INFO - Connecting to database: neondb_owner:npg_IxHh7rq0jAcT@[hidden]
2025-05-05 03:57:53,251 - __main__ - INFO - Successfully imported app from app_init
2025-05-05 03:57:53,253 - __main__ - INFO - Starting AlphaVox service initialization in background
2025-05-05 03:57:53,253 - __main__ - INFO - 🚀 Starting AlphaVox on http://0.0.0.0:8080
2025-05-05 03:57:53,253 - __main__ - INFO - AlphaVox services initialization completed successfully
2025-05-05 03:57:53,276 - werkzeug - WARNING -  * Debugger is active!
2025-05-05 03:57:53,280 - werkzeug - INFO -  * Debugger PIN: 798-043-223
[2025-05-09 02:19:42] [INFO] [root] - Default logging configuration applied
[2025-05-09 02:19:42] [INFO] [adaptive_conversation] - Conversation Complexity Engine initialized
[2025-05-09 02:19:42] [INFO] [routes.learning_routes] - Learning routes registered
[2025-05-09 02:19:42] [INFO] [routes.health_routes] - Health routes registered
[2025-05-09 02:19:42] [INFO] [main] - AlphaVox application initialized
[2025-05-09 02:19:48] [INFO] [root] - Default logging configuration applied
[2025-05-09 02:19:48] [INFO] [adaptive_conversation] - Conversation Complexity Engine initialized
[2025-05-09 02:19:48] [INFO] [routes.learning_routes] - Learning routes registered
[2025-05-09 02:19:48] [INFO] [routes.health_routes] - Health routes registered
[2025-05-09 02:19:48] [INFO] [main] - AlphaVox application initialized
[2025-05-09 02:19:48] [INFO] [main] - Test route accessed
[2025-05-09 02:20:01] [INFO] [root] - Default logging configuration applied
[2025-05-09 02:20:01] [INFO] [adaptive_conversation] - Conversation Complexity Engine initialized
[2025-05-09 02:20:01] [INFO] [routes.learning_routes] - Learning routes registered
[2025-05-09 02:20:01] [INFO] [routes.health_routes] - Health routes registered
[2025-05-09 02:20:01] [INFO] [main] - AlphaVox application initialized
[2025-05-09 02:23:00] [INFO] [root] - Default logging configuration applied
[2025-05-09 02:23:00] [INFO] [adaptive_conversation] - Conversation Complexity Engine initialized
[2025-05-09 02:23:00] [INFO] [routes.learning_routes] - Learning routes registered
[2025-05-09 02:23:00] [INFO] [routes.health_routes] - Health routes registered
[2025-05-09 02:23:00] [INFO] [main] - AlphaVox application initialized
[2025-05-09 02:26:24] [INFO] [root] - Default logging configuration applied
[2025-05-09 02:26:24] [INFO] [adaptive_conversation] - Conversation Complexity Engine initialized
[2025-05-09 02:26:24] [INFO] [routes.learning_routes] - Learning routes registered
[2025-05-09 02:26:24] [INFO] [routes.health_routes] - Health routes registered
[2025-05-09 02:26:24] [INFO] [main] - AlphaVox application initialized
[2025-05-09 02:30:55] [INFO] [root] - Default logging configuration applied
[2025-05-09 02:30:55] [INFO] [adaptive_conversation] - Conversation Complexity Engine initialized
[2025-05-09 02:30:55] [INFO] [routes.learning_routes] - Learning routes registered
[2025-05-09 02:30:55] [INFO] [routes.health_routes] - Health routes registered
[2025-05-09 02:30:55] [INFO] [main] - AlphaVox application initialized
[2025-05-09 02:33:52] [INFO] [root] - Default logging configuration applied
[2025-05-09 02:33:52] [INFO] [adaptive_conversation] - Conversation Complexity Engine initialized
[2025-05-09 02:33:52] [INFO] [routes.learning_routes] - Learning routes registered
[2025-05-09 02:33:52] [INFO] [routes.health_routes] - Health routes registered
[2025-05-09 02:33:52] [INFO] [main] - AlphaVox application initialized
[2025-05-09 02:34:27] [INFO] [root] - Default logging configuration applied
[2025-05-09 02:34:27] [INFO] [adaptive_conversation] - Conversation Complexity Engine initialized
[2025-05-09 02:41:52] [INFO] [root] - Default logging configuration applied
[2025-05-09 02:41:52] [INFO] [adaptive_conversation] - Conversation Complexity Engine initialized
[2025-05-09 02:42:06] [INFO] [root] - Default logging configuration applied
[2025-05-09 02:42:06] [INFO] [adaptive_conversation] - Conversation Complexity Engine initialized
[2025-05-09 02:42:06] [INFO] [routes.adaptive_conversation_routes] - Adaptive conversation routes registered
[2025-05-09 02:42:06] [INFO] [routes.learning_routes] - Learning routes registered
[2025-05-09 02:42:06] [INFO] [routes.health_routes] - Health routes registered
[2025-05-09 02:42:06] [INFO] [main] - AlphaVox application initialized
[2025-05-09 02:42:22] [INFO] [root] - Default logging configuration applied
[2025-05-09 02:42:22] [INFO] [adaptive_conversation] - Conversation Complexity Engine initialized
[2025-05-09 02:42:22] [INFO] [routes.adaptive_conversation_routes] - Adaptive conversation routes registered
[2025-05-09 02:42:22] [INFO] [routes.learning_routes] - Learning routes registered
[2025-05-09 02:42:22] [INFO] [routes.health_routes] - Health routes registered
[2025-05-09 02:42:22] [INFO] [main] - AlphaVox application initialized
[2025-05-09 02:42:39] [ERROR] [routes.health_routes] - Database health check failed: The current Flask app is not registered with this 'SQLAlchemy' instance. Did you forget to call 'init_app', or did you create multiple 'SQLAlchemy' instances?
[2025-05-09 02:42:53] [INFO] [root] - Default logging configuration applied
[2025-05-09 02:42:53] [INFO] [adaptive_conversation] - Conversation Complexity Engine initialized
[2025-05-09 02:42:53] [INFO] [routes.adaptive_conversation_routes] - Adaptive conversation routes registered
[2025-05-09 02:42:53] [INFO] [routes.learning_routes] - Learning routes registered
[2025-05-09 02:42:53] [INFO] [routes.health_routes] - Health routes registered
[2025-05-09 02:42:53] [INFO] [main] - AlphaVox application initialized
[2025-05-09 02:42:59] [INFO] [root] - Default logging configuration applied
[2025-05-09 02:42:59] [INFO] [adaptive_conversation] - Conversation Complexity Engine initialized
[2025-05-09 02:42:59] [INFO] [routes.adaptive_conversation_routes] - Adaptive conversation routes registered
[2025-05-09 02:42:59] [INFO] [routes.learning_routes] - Learning routes registered
[2025-05-09 02:42:59] [INFO] [routes.health_routes] - Health routes registered
[2025-05-09 02:42:59] [INFO] [main] - AlphaVox application initialized
[2025-05-09 02:43:10] [ERROR] [app_init] - Exception on /learning/ [GET]
Traceback (most recent call last):
  File "/home/runner/workspace/.pythonlibs/lib/python3.11/site-packages/flask/app.py", line 1511, in wsgi_app
    response = self.full_dispatch_request()
               ^^^^^^^^^^^^^^^^^^^^^^^^^^^^
  File "/home/runner/workspace/.pythonlibs/lib/python3.11/site-packages/flask/app.py", line 919, in full_dispatch_request
    rv = self.handle_user_exception(e)
         ^^^^^^^^^^^^^^^^^^^^^^^^^^^^^
  File "/home/runner/workspace/.pythonlibs/lib/python3.11/site-packages/flask/app.py", line 917, in full_dispatch_request
    rv = self.dispatch_request()
         ^^^^^^^^^^^^^^^^^^^^^^^
  File "/home/runner/workspace/.pythonlibs/lib/python3.11/site-packages/flask/app.py", line 902, in dispatch_request
    return self.ensure_sync(self.view_functions[rule.endpoint])(**view_args)  # type: ignore[no-any-return]
           ^^^^^^^^^^^^^^^^^^^^^^^^^^^^^^^^^^^^^^^^^^^^^^^^^^^^^^^^^^^^^^^^^
  File "/home/runner/workspace/routes/learning_routes.py", line 19, in learning_hub
    return render_template('learning/hub.html', title="Learning Hub")
           ^^^^^^^^^^^^^^^^^^^^^^^^^^^^^^^^^^^^^^^^^^^^^^^^^^^^^^^^^^
  File "/home/runner/workspace/.pythonlibs/lib/python3.11/site-packages/flask/templating.py", line 150, in render_template
    return _render(app, template, context)
           ^^^^^^^^^^^^^^^^^^^^^^^^^^^^^^^
  File "/home/runner/workspace/.pythonlibs/lib/python3.11/site-packages/flask/templating.py", line 131, in _render
    rv = template.render(context)
         ^^^^^^^^^^^^^^^^^^^^^^^^
  File "/home/runner/workspace/.pythonlibs/lib/python3.11/site-packages/jinja2/environment.py", line 1295, in render
    self.environment.handle_exception()
  File "/home/runner/workspace/.pythonlibs/lib/python3.11/site-packages/jinja2/environment.py", line 942, in handle_exception
    raise rewrite_traceback_stack(source=source)
  File "/home/runner/workspace/templates/learning/hub.html", line 1, in top-level template code
    {% extends "layout.html" %}
    ^^^^^^^^^^^^^^^^^^^^^^^^^
  File "/home/runner/workspace/templates/layout.html", line 133, in top-level template code
    {% block content %}{% endblock %}
    ^^^^^^^^^^^^^^^^^^^^^^^^^
  File "/home/runner/workspace/templates/learning/hub.html", line 94, in block 'content'
    {% for topic in topics[:3] %}
    ^^^^^^^^^^^^^^^^^^^^^^^^^
jinja2.exceptions.UndefinedError: 'topics' is undefined
[2025-05-09 02:43:30] [INFO] [root] - Default logging configuration applied
[2025-05-09 02:43:30] [INFO] [adaptive_conversation] - Conversation Complexity Engine initialized
[2025-05-09 02:43:30] [INFO] [routes.adaptive_conversation_routes] - Adaptive conversation routes registered
[2025-05-09 02:43:30] [INFO] [routes.learning_routes] - Learning routes registered
[2025-05-09 02:43:30] [INFO] [routes.health_routes] - Health routes registered
[2025-05-09 02:43:30] [INFO] [main] - AlphaVox application initialized
[2025-05-09 02:43:38] [INFO] [root] - Default logging configuration applied
[2025-05-09 02:43:38] [INFO] [adaptive_conversation] - Conversation Complexity Engine initialized
[2025-05-09 02:43:38] [INFO] [routes.adaptive_conversation_routes] - Adaptive conversation routes registered
[2025-05-09 02:43:38] [INFO] [routes.learning_routes] - Learning routes registered
[2025-05-09 02:43:38] [INFO] [routes.health_routes] - Health routes registered
[2025-05-09 02:43:38] [INFO] [main] - AlphaVox application initialized
[2025-05-09 02:43:47] [INFO] [root] - Default logging configuration applied
[2025-05-09 02:43:47] [INFO] [adaptive_conversation] - Conversation Complexity Engine initialized
[2025-05-09 02:43:47] [INFO] [routes.adaptive_conversation_routes] - Adaptive conversation routes registered
[2025-05-09 02:43:47] [INFO] [routes.learning_routes] - Learning routes registered
[2025-05-09 02:43:47] [INFO] [routes.health_routes] - Health routes registered
[2025-05-09 02:43:47] [INFO] [main] - AlphaVox application initialized
[2025-05-09 02:43:59] [INFO] [learning_journey] - LearningJourney initialized
[2025-05-09 02:44:04] [ERROR] [app_init] - Exception on /color-scheme/ [GET]
Traceback (most recent call last):
  File "/home/runner/workspace/.pythonlibs/lib/python3.11/site-packages/flask/app.py", line 1511, in wsgi_app
    response = self.full_dispatch_request()
               ^^^^^^^^^^^^^^^^^^^^^^^^^^^^
  File "/home/runner/workspace/.pythonlibs/lib/python3.11/site-packages/flask/app.py", line 919, in full_dispatch_request
    rv = self.handle_user_exception(e)
         ^^^^^^^^^^^^^^^^^^^^^^^^^^^^^
  File "/home/runner/workspace/.pythonlibs/lib/python3.11/site-packages/flask/app.py", line 917, in full_dispatch_request
    rv = self.dispatch_request()
         ^^^^^^^^^^^^^^^^^^^^^^^
  File "/home/runner/workspace/.pythonlibs/lib/python3.11/site-packages/flask/app.py", line 902, in dispatch_request
    return self.ensure_sync(self.view_functions[rule.endpoint])(**view_args)  # type: ignore[no-any-return]
           ^^^^^^^^^^^^^^^^^^^^^^^^^^^^^^^^^^^^^^^^^^^^^^^^^^^^^^^^^^^^^^^^^
  File "/home/runner/workspace/routes/color_scheme_routes.py", line 120, in color_scheme_home
    return render_template('color_scheme/home.html', title="Color Scheme")
           ^^^^^^^^^^^^^^^^^^^^^^^^^^^^^^^^^^^^^^^^^^^^^^^^^^^^^^^^^^^^^^^
  File "/home/runner/workspace/.pythonlibs/lib/python3.11/site-packages/flask/templating.py", line 149, in render_template
    template = app.jinja_env.get_or_select_template(template_name_or_list)
               ^^^^^^^^^^^^^^^^^^^^^^^^^^^^^^^^^^^^^^^^^^^^^^^^^^^^^^^^^^^
  File "/home/runner/workspace/.pythonlibs/lib/python3.11/site-packages/jinja2/environment.py", line 1087, in get_or_select_template
    return self.get_template(template_name_or_list, parent, globals)
           ^^^^^^^^^^^^^^^^^^^^^^^^^^^^^^^^^^^^^^^^^^^^^^^^^^^^^^^^^
  File "/home/runner/workspace/.pythonlibs/lib/python3.11/site-packages/jinja2/environment.py", line 1016, in get_template
    return self._load_template(name, globals)
           ^^^^^^^^^^^^^^^^^^^^^^^^^^^^^^^^^^
  File "/home/runner/workspace/.pythonlibs/lib/python3.11/site-packages/jinja2/environment.py", line 975, in _load_template
    template = self.loader.load(self, name, self.make_globals(globals))
               ^^^^^^^^^^^^^^^^^^^^^^^^^^^^^^^^^^^^^^^^^^^^^^^^^^^^^^^^
  File "/home/runner/workspace/.pythonlibs/lib/python3.11/site-packages/jinja2/loaders.py", line 126, in load
    source, filename, uptodate = self.get_source(environment, name)
                                 ^^^^^^^^^^^^^^^^^^^^^^^^^^^^^^^^^^
  File "/home/runner/workspace/.pythonlibs/lib/python3.11/site-packages/flask/templating.py", line 65, in get_source
    return self._get_source_fast(environment, template)
           ^^^^^^^^^^^^^^^^^^^^^^^^^^^^^^^^^^^^^^^^^^^^
  File "/home/runner/workspace/.pythonlibs/lib/python3.11/site-packages/flask/templating.py", line 99, in _get_source_fast
    raise TemplateNotFound(template)
jinja2.exceptions.TemplateNotFound: color_scheme/home.html
[2025-05-09 02:45:48] [INFO] [root] - Default logging configuration applied
[2025-05-09 02:45:48] [INFO] [adaptive_conversation] - Conversation Complexity Engine initialized
[2025-05-09 02:45:48] [INFO] [routes.adaptive_conversation_routes] - Adaptive conversation routes registered
[2025-05-09 02:45:48] [INFO] [routes.learning_routes] - Learning routes registered
[2025-05-09 02:45:48] [INFO] [routes.health_routes] - Health routes registered
[2025-05-09 02:45:48] [INFO] [main] - AlphaVox application initialized
[2025-05-09 02:45:57] [INFO] [root] - Default logging configuration applied
[2025-05-09 02:45:57] [INFO] [adaptive_conversation] - Conversation Complexity Engine initialized
[2025-05-09 02:45:57] [INFO] [routes.adaptive_conversation_routes] - Adaptive conversation routes registered
[2025-05-09 02:45:57] [INFO] [routes.learning_routes] - Learning routes registered
[2025-05-09 02:45:57] [INFO] [routes.health_routes] - Health routes registered
[2025-05-09 02:45:57] [INFO] [main] - AlphaVox application initialized
[2025-05-09 02:45:57] [ERROR] [routes.color_scheme_routes] - Error getting user color scheme preference: (psycopg2.errors.InvalidTextRepresentation) invalid input syntax for type integer: "default_user"
LINE 3: WHERE user_preference.user_id = 'default_user' AND user_pref...
                                        ^

[SQL: SELECT user_preference.id AS user_preference_id, user_preference.user_id AS user_preference_user_id, user_preference.type AS user_preference_type, user_preference.value AS user_preference_value, user_preference.is_active AS user_preference_is_active, user_preference.created_at AS user_preference_created_at, user_preference.updated_at AS user_preference_updated_at, user_preference.source AS user_preference_source, user_preference.confidence AS user_preference_confidence 
FROM user_preference 
WHERE user_preference.user_id = %(user_id_1)s AND user_preference.type = %(type_1)s AND user_preference.is_active = true 
 LIMIT %(param_1)s]
[parameters: {'user_id_1': 'default_user', 'type_1': 'color_scheme', 'param_1': 1}]
(Background on this error at: https://sqlalche.me/e/20/9h9h)
[2025-05-09 02:45:57] [ERROR] [routes.color_scheme_routes] - Error getting user color scheme preference: (psycopg2.errors.InFailedSqlTransaction) current transaction is aborted, commands ignored until end of transaction block

[SQL: SELECT user_preference.id AS user_preference_id, user_preference.user_id AS user_preference_user_id, user_preference.type AS user_preference_type, user_preference.value AS user_preference_value, user_preference.is_active AS user_preference_is_active, user_preference.created_at AS user_preference_created_at, user_preference.updated_at AS user_preference_updated_at, user_preference.source AS user_preference_source, user_preference.confidence AS user_preference_confidence 
FROM user_preference 
WHERE user_preference.user_id = %(user_id_1)s AND user_preference.type = %(type_1)s AND user_preference.is_active = true 
 LIMIT %(param_1)s]
[parameters: {'user_id_1': 'default_user', 'type_1': 'color_scheme', 'param_1': 1}]
(Background on this error at: https://sqlalche.me/e/20/2j85)
[2025-05-09 02:45:57] [ERROR] [routes.color_scheme_routes] - Error getting user color scheme preference: (psycopg2.errors.InFailedSqlTransaction) current transaction is aborted, commands ignored until end of transaction block

[SQL: SELECT user_preference.id AS user_preference_id, user_preference.user_id AS user_preference_user_id, user_preference.type AS user_preference_type, user_preference.value AS user_preference_value, user_preference.is_active AS user_preference_is_active, user_preference.created_at AS user_preference_created_at, user_preference.updated_at AS user_preference_updated_at, user_preference.source AS user_preference_source, user_preference.confidence AS user_preference_confidence 
FROM user_preference 
WHERE user_preference.user_id = %(user_id_1)s AND user_preference.type = %(type_1)s AND user_preference.is_active = true 
 LIMIT %(param_1)s]
[parameters: {'user_id_1': 'default_user', 'type_1': 'color_scheme', 'param_1': 1}]
(Background on this error at: https://sqlalche.me/e/20/2j85)
[2025-05-09 02:45:58] [ERROR] [routes.color_scheme_routes] - Error getting user color scheme preference: (psycopg2.errors.InFailedSqlTransaction) current transaction is aborted, commands ignored until end of transaction block

[SQL: SELECT user_preference.id AS user_preference_id, user_preference.user_id AS user_preference_user_id, user_preference.type AS user_preference_type, user_preference.value AS user_preference_value, user_preference.is_active AS user_preference_is_active, user_preference.created_at AS user_preference_created_at, user_preference.updated_at AS user_preference_updated_at, user_preference.source AS user_preference_source, user_preference.confidence AS user_preference_confidence 
FROM user_preference 
WHERE user_preference.user_id = %(user_id_1)s AND user_preference.type = %(type_1)s AND user_preference.is_active = true 
 LIMIT %(param_1)s]
[parameters: {'user_id_1': 'default_user', 'type_1': 'color_scheme', 'param_1': 1}]
(Background on this error at: https://sqlalche.me/e/20/2j85)
[2025-05-09 02:45:58] [ERROR] [routes.color_scheme_routes] - Error getting user color scheme preference: (psycopg2.errors.InFailedSqlTransaction) current transaction is aborted, commands ignored until end of transaction block

[SQL: SELECT user_preference.id AS user_preference_id, user_preference.user_id AS user_preference_user_id, user_preference.type AS user_preference_type, user_preference.value AS user_preference_value, user_preference.is_active AS user_preference_is_active, user_preference.created_at AS user_preference_created_at, user_preference.updated_at AS user_preference_updated_at, user_preference.source AS user_preference_source, user_preference.confidence AS user_preference_confidence 
FROM user_preference 
WHERE user_preference.user_id = %(user_id_1)s AND user_preference.type = %(type_1)s AND user_preference.is_active = true 
 LIMIT %(param_1)s]
[parameters: {'user_id_1': 'default_user', 'type_1': 'color_scheme', 'param_1': 1}]
(Background on this error at: https://sqlalche.me/e/20/2j85)
[2025-05-09 02:45:58] [ERROR] [routes.color_scheme_routes] - Error getting user color scheme preference: (psycopg2.errors.InFailedSqlTransaction) current transaction is aborted, commands ignored until end of transaction block

[SQL: SELECT user_preference.id AS user_preference_id, user_preference.user_id AS user_preference_user_id, user_preference.type AS user_preference_type, user_preference.value AS user_preference_value, user_preference.is_active AS user_preference_is_active, user_preference.created_at AS user_preference_created_at, user_preference.updated_at AS user_preference_updated_at, user_preference.source AS user_preference_source, user_preference.confidence AS user_preference_confidence 
FROM user_preference 
WHERE user_preference.user_id = %(user_id_1)s AND user_preference.type = %(type_1)s AND user_preference.is_active = true 
 LIMIT %(param_1)s]
[parameters: {'user_id_1': 'default_user', 'type_1': 'color_scheme', 'param_1': 1}]
(Background on this error at: https://sqlalche.me/e/20/2j85)
[2025-05-09 02:45:58] [ERROR] [routes.color_scheme_routes] - Error getting user color scheme preference: (psycopg2.errors.InFailedSqlTransaction) current transaction is aborted, commands ignored until end of transaction block

[SQL: SELECT user_preference.id AS user_preference_id, user_preference.user_id AS user_preference_user_id, user_preference.type AS user_preference_type, user_preference.value AS user_preference_value, user_preference.is_active AS user_preference_is_active, user_preference.created_at AS user_preference_created_at, user_preference.updated_at AS user_preference_updated_at, user_preference.source AS user_preference_source, user_preference.confidence AS user_preference_confidence 
FROM user_preference 
WHERE user_preference.user_id = %(user_id_1)s AND user_preference.type = %(type_1)s AND user_preference.is_active = true 
 LIMIT %(param_1)s]
[parameters: {'user_id_1': 'default_user', 'type_1': 'color_scheme', 'param_1': 1}]
(Background on this error at: https://sqlalche.me/e/20/2j85)
[2025-05-09 02:45:58] [ERROR] [routes.color_scheme_routes] - Error getting user color scheme preference: (psycopg2.errors.InFailedSqlTransaction) current transaction is aborted, commands ignored until end of transaction block

[SQL: SELECT user_preference.id AS user_preference_id, user_preference.user_id AS user_preference_user_id, user_preference.type AS user_preference_type, user_preference.value AS user_preference_value, user_preference.is_active AS user_preference_is_active, user_preference.created_at AS user_preference_created_at, user_preference.updated_at AS user_preference_updated_at, user_preference.source AS user_preference_source, user_preference.confidence AS user_preference_confidence 
FROM user_preference 
WHERE user_preference.user_id = %(user_id_1)s AND user_preference.type = %(type_1)s AND user_preference.is_active = true 
 LIMIT %(param_1)s]
[parameters: {'user_id_1': 'default_user', 'type_1': 'color_scheme', 'param_1': 1}]
(Background on this error at: https://sqlalche.me/e/20/2j85)
[2025-05-09 02:45:58] [ERROR] [routes.color_scheme_routes] - Error getting user color scheme preference: (psycopg2.errors.InFailedSqlTransaction) current transaction is aborted, commands ignored until end of transaction block

[SQL: SELECT user_preference.id AS user_preference_id, user_preference.user_id AS user_preference_user_id, user_preference.type AS user_preference_type, user_preference.value AS user_preference_value, user_preference.is_active AS user_preference_is_active, user_preference.created_at AS user_preference_created_at, user_preference.updated_at AS user_preference_updated_at, user_preference.source AS user_preference_source, user_preference.confidence AS user_preference_confidence 
FROM user_preference 
WHERE user_preference.user_id = %(user_id_1)s AND user_preference.type = %(type_1)s AND user_preference.is_active = true 
 LIMIT %(param_1)s]
[parameters: {'user_id_1': 'default_user', 'type_1': 'color_scheme', 'param_1': 1}]
(Background on this error at: https://sqlalche.me/e/20/2j85)
[2025-05-09 02:45:58] [ERROR] [routes.color_scheme_routes] - Error getting user color scheme preference: (psycopg2.errors.InFailedSqlTransaction) current transaction is aborted, commands ignored until end of transaction block

[SQL: SELECT user_preference.id AS user_preference_id, user_preference.user_id AS user_preference_user_id, user_preference.type AS user_preference_type, user_preference.value AS user_preference_value, user_preference.is_active AS user_preference_is_active, user_preference.created_at AS user_preference_created_at, user_preference.updated_at AS user_preference_updated_at, user_preference.source AS user_preference_source, user_preference.confidence AS user_preference_confidence 
FROM user_preference 
WHERE user_preference.user_id = %(user_id_1)s AND user_preference.type = %(type_1)s AND user_preference.is_active = true 
 LIMIT %(param_1)s]
[parameters: {'user_id_1': 'default_user', 'type_1': 'color_scheme', 'param_1': 1}]
(Background on this error at: https://sqlalche.me/e/20/2j85)
[2025-05-09 02:45:58] [ERROR] [routes.color_scheme_routes] - Error getting user color scheme preference: (psycopg2.errors.InFailedSqlTransaction) current transaction is aborted, commands ignored until end of transaction block

[SQL: SELECT user_preference.id AS user_preference_id, user_preference.user_id AS user_preference_user_id, user_preference.type AS user_preference_type, user_preference.value AS user_preference_value, user_preference.is_active AS user_preference_is_active, user_preference.created_at AS user_preference_created_at, user_preference.updated_at AS user_preference_updated_at, user_preference.source AS user_preference_source, user_preference.confidence AS user_preference_confidence 
FROM user_preference 
WHERE user_preference.user_id = %(user_id_1)s AND user_preference.type = %(type_1)s AND user_preference.is_active = true 
 LIMIT %(param_1)s]
[parameters: {'user_id_1': 'default_user', 'type_1': 'color_scheme', 'param_1': 1}]
(Background on this error at: https://sqlalche.me/e/20/2j85)
[2025-05-09 02:45:58] [ERROR] [routes.color_scheme_routes] - Error getting user color scheme preference: (psycopg2.errors.InFailedSqlTransaction) current transaction is aborted, commands ignored until end of transaction block

[SQL: SELECT user_preference.id AS user_preference_id, user_preference.user_id AS user_preference_user_id, user_preference.type AS user_preference_type, user_preference.value AS user_preference_value, user_preference.is_active AS user_preference_is_active, user_preference.created_at AS user_preference_created_at, user_preference.updated_at AS user_preference_updated_at, user_preference.source AS user_preference_source, user_preference.confidence AS user_preference_confidence 
FROM user_preference 
WHERE user_preference.user_id = %(user_id_1)s AND user_preference.type = %(type_1)s AND user_preference.is_active = true 
 LIMIT %(param_1)s]
[parameters: {'user_id_1': 'default_user', 'type_1': 'color_scheme', 'param_1': 1}]
(Background on this error at: https://sqlalche.me/e/20/2j85)
[2025-05-09 02:45:58] [ERROR] [routes.color_scheme_routes] - Error getting user color scheme preference: (psycopg2.errors.InFailedSqlTransaction) current transaction is aborted, commands ignored until end of transaction block

[SQL: SELECT user_preference.id AS user_preference_id, user_preference.user_id AS user_preference_user_id, user_preference.type AS user_preference_type, user_preference.value AS user_preference_value, user_preference.is_active AS user_preference_is_active, user_preference.created_at AS user_preference_created_at, user_preference.updated_at AS user_preference_updated_at, user_preference.source AS user_preference_source, user_preference.confidence AS user_preference_confidence 
FROM user_preference 
WHERE user_preference.user_id = %(user_id_1)s AND user_preference.type = %(type_1)s AND user_preference.is_active = true 
 LIMIT %(param_1)s]
[parameters: {'user_id_1': 'default_user', 'type_1': 'color_scheme', 'param_1': 1}]
(Background on this error at: https://sqlalche.me/e/20/2j85)
[2025-05-09 02:45:58] [ERROR] [routes.color_scheme_routes] - Error getting user color scheme preference: (psycopg2.errors.InFailedSqlTransaction) current transaction is aborted, commands ignored until end of transaction block

[SQL: SELECT user_preference.id AS user_preference_id, user_preference.user_id AS user_preference_user_id, user_preference.type AS user_preference_type, user_preference.value AS user_preference_value, user_preference.is_active AS user_preference_is_active, user_preference.created_at AS user_preference_created_at, user_preference.updated_at AS user_preference_updated_at, user_preference.source AS user_preference_source, user_preference.confidence AS user_preference_confidence 
FROM user_preference 
WHERE user_preference.user_id = %(user_id_1)s AND user_preference.type = %(type_1)s AND user_preference.is_active = true 
 LIMIT %(param_1)s]
[parameters: {'user_id_1': 'default_user', 'type_1': 'color_scheme', 'param_1': 1}]
(Background on this error at: https://sqlalche.me/e/20/2j85)
[2025-05-09 02:45:58] [ERROR] [routes.color_scheme_routes] - Error getting user color scheme preference: (psycopg2.errors.InFailedSqlTransaction) current transaction is aborted, commands ignored until end of transaction block

[SQL: SELECT user_preference.id AS user_preference_id, user_preference.user_id AS user_preference_user_id, user_preference.type AS user_preference_type, user_preference.value AS user_preference_value, user_preference.is_active AS user_preference_is_active, user_preference.created_at AS user_preference_created_at, user_preference.updated_at AS user_preference_updated_at, user_preference.source AS user_preference_source, user_preference.confidence AS user_preference_confidence 
FROM user_preference 
WHERE user_preference.user_id = %(user_id_1)s AND user_preference.type = %(type_1)s AND user_preference.is_active = true 
 LIMIT %(param_1)s]
[parameters: {'user_id_1': 'default_user', 'type_1': 'color_scheme', 'param_1': 1}]
(Background on this error at: https://sqlalche.me/e/20/2j85)
[2025-05-09 02:45:58] [ERROR] [routes.color_scheme_routes] - Error getting user color scheme preference: (psycopg2.errors.InFailedSqlTransaction) current transaction is aborted, commands ignored until end of transaction block

[SQL: SELECT user_preference.id AS user_preference_id, user_preference.user_id AS user_preference_user_id, user_preference.type AS user_preference_type, user_preference.value AS user_preference_value, user_preference.is_active AS user_preference_is_active, user_preference.created_at AS user_preference_created_at, user_preference.updated_at AS user_preference_updated_at, user_preference.source AS user_preference_source, user_preference.confidence AS user_preference_confidence 
FROM user_preference 
WHERE user_preference.user_id = %(user_id_1)s AND user_preference.type = %(type_1)s AND user_preference.is_active = true 
 LIMIT %(param_1)s]
[parameters: {'user_id_1': 'default_user', 'type_1': 'color_scheme', 'param_1': 1}]
(Background on this error at: https://sqlalche.me/e/20/2j85)
[2025-05-13 22:28:14] [INFO] [root] - Default logging configuration applied
[2025-05-13 22:28:14] [INFO] [adaptive_conversation] - Conversation Complexity Engine initialized
[2025-05-13 22:28:14] [INFO] [routes.adaptive_conversation_routes] - Adaptive conversation routes registered
[2025-05-13 22:28:14] [INFO] [routes.learning_routes] - Learning routes registered
[2025-05-13 22:28:14] [INFO] [routes.health_routes] - Health routes registered
[2025-05-13 22:28:14] [INFO] [main] - AlphaVox application initialized
[2025-05-13 22:28:49] [INFO] [learning_analytics] - Initializing LearningAnalytics for user None
[2025-05-13 22:28:49] [INFO] [nonverbal_engine] - Initializing NonverbalEngine with self-learning capabilities
[2025-05-13 22:28:49] [INFO] [nonverbal_engine] - NonverbalEngine initialized with self-modification capabilities
[2025-05-13 22:28:49] [INFO] [real_eye_tracking] - Real eye tracking service initialized
[2025-05-13 22:28:49] [INFO] [root] - Using real eye tracking service
[2025-05-13 22:28:49] [WARNING] [root] - Real speech recognition not available: No module named 'sounddevice', using simulated service
[2025-05-13 22:28:49] [INFO] [sound_recognition_service] - Initializing SoundRecognitionService
[2025-05-13 22:28:49] [INFO] [sound_recognition_service] - Using simulated sound recognition
[2025-05-13 22:28:49] [INFO] [sound_recognition_service] - SoundRecognitionService initialized
[2025-05-13 22:28:49] [INFO] [behavior_capture] - Initialized behavior capture processors
[2025-05-13 22:28:49] [INFO] [root] - Behavior capture system initialized
[2025-05-13 22:28:49] [INFO] [root] - Initialized AI self-learning and self-modification capabilities
[2025-05-13 22:28:49] [INFO] [nonverbal_engine] - Initializing NonverbalEngine with self-learning capabilities
[2025-05-13 22:28:49] [INFO] [nonverbal_engine] - NonverbalEngine initialized with self-modification capabilities
[2025-05-13 22:28:49] [INFO] [conversation_engine] - Conversation engine initialized
[2025-05-13 22:28:49] [INFO] [input_analyzer] - Input analyzer initialized
[2025-05-13 22:28:49] [INFO] [behavioral_interpreter] - Behavioral interpreter initialized
[2025-05-13 22:28:49] [INFO] [interpreter] - Interpreter initialized
[2025-05-13 22:28:49] [INFO] [root] - Advanced AI interpreter initialized
[2025-05-13 22:28:49] [INFO] [root] - All advanced AI components initialized
[2025-05-13 22:28:49] [INFO] [modules.knowledge_integration] - Knowledge engine loaded
[2025-05-13 22:28:49] [INFO] [modules.knowledge_integration] - Loaded 15 facts from knowledge base
[2025-05-13 22:28:49] [INFO] [modules.knowledge_integration] - Loaded 10 topics from knowledge base
[2025-05-13 22:28:49] [INFO] [modules.knowledge_integration] - Loaded knowledge graph with 2 nodes
[2025-05-13 22:28:49] [INFO] [modules.knowledge_integration] - Knowledge Integration initialized
[2025-05-13 22:28:49] [INFO] [root] - Knowledge integration initialized
[2025-05-13 22:28:49] [WARNING] [modules.speech_integration] - Real speech recognition engine not available
[2025-05-13 22:28:49] [INFO] [attached_assets.enhanced_speech_recognition] - Initializing EnhancedSpeechRecognition
[2025-05-13 22:28:49] [INFO] [sound_recognition_service] - Initializing SoundRecognitionService
[2025-05-13 22:28:49] [INFO] [sound_recognition_service] - Using simulated sound recognition
[2025-05-13 22:28:49] [INFO] [sound_recognition_service] - SoundRecognitionService initialized
[2025-05-13 22:28:49] [INFO] [attached_assets.enhanced_speech_recognition] - Sound recognition service loaded
[2025-05-13 22:28:49] [INFO] [attached_assets.enhanced_speech_recognition] - EnhancedSpeechRecognition initialized
[2025-05-13 22:28:49] [INFO] [modules.speech_integration] - Enhanced speech recognition loaded
[2025-05-13 22:28:49] [INFO] [modules.speech_integration] - Speech Integration initialized
[2025-05-13 22:28:49] [INFO] [root] - Speech integration initialized
[2025-05-13 22:28:49] [WARNING] [attached_assets.caregiver_interface] - Eye tracking service not available
[2025-05-13 22:28:49] [WARNING] [attached_assets.caregiver_interface] - Learning analytics not available
[2025-05-13 22:28:49] [WARNING] [attached_assets.caregiver_interface] - Nonverbal expertise not available
[2025-05-13 22:28:49] [INFO] [attached_assets.caregiver_interface] - Loaded 1 user profiles
[2025-05-13 22:28:49] [INFO] [attached_assets.caregiver_interface] - Loaded communication history for 1 users
[2025-05-13 22:28:49] [INFO] [attached_assets.caregiver_interface] - Caregiver Interface initialized
[2025-05-13 22:28:49] [INFO] [modules.caregiver_dashboard] - Caregiver Interface loaded successfully
[2025-05-13 22:28:49] [INFO] [modules.caregiver_dashboard] - Caregiver Dashboard module initialized
[2025-05-13 22:28:49] [INFO] [root] - Caregiver dashboard initialized
[2025-05-13 22:28:49] [WARNING] [root] - Real speech recognition not available
[2025-05-13 22:28:49] [WARNING] [root] - Using simulated speech recognition
[2025-05-13 22:28:49] [INFO] [root] - Audio processor initialized with real speech: False
[2025-05-13 22:28:49] [INFO] [root] - Audio processor initialized
[2025-05-13 22:28:49] [INFO] [attached_assets.engine_temporal] - Language map loaded successfully
[2025-05-13 22:28:49] [WARNING] [attached_assets.engine_temporal] - LSTM model directory not found at lstm_models
[2025-05-13 22:28:49] [INFO] [attached_assets.engine_temporal] - TemporalNonverbalEngine initialized successfully
[2025-05-13 22:28:49] [INFO] [root] - Temporal nonverbal engine initialized
[2025-05-13 22:28:49] [ERROR] [attached_assets.conversation_integration] - Failed to load required components: cannot import name 'alphavox' from 'alphavox' (unknown location)
[2025-05-13 22:28:49] [WARNING] [attached_assets.conversation_integration] - Some functionality may be limited
[2025-05-13 22:28:49] [INFO] [attached_assets.conversation_integration] - Conversation Integration initialized for user: default_user
[2025-05-13 22:28:49] [INFO] [root] - Conversation integration initialized
[2025-05-13 22:28:49] [ERROR] [root] - Error initializing integration modules: The setup method 'route' can no longer be called on the application. It has already handled its first request, any changes will not be applied consistently.
Make sure all imports, decorators, functions, etc. needed to set up the application are done before running it.
[2025-05-13 22:28:49] [ERROR] [root] - Traceback (most recent call last):
  File "/home/runner/workspace/app.py", line 200, in init_services
    register_caregiver_routes(app)
  File "/home/runner/workspace/modules/caregiver_dashboard.py", line 180, in register_caregiver_routes
    @app.route('/caregiver')
     ^^^^^^^^^^^^^^^^^^^^^^^
  File "/home/runner/workspace/.pythonlibs/lib/python3.11/site-packages/flask/sansio/scaffold.py", line 46, in wrapper_func
    self._check_setup_finished(f_name)
  File "/home/runner/workspace/.pythonlibs/lib/python3.11/site-packages/flask/sansio/app.py", line 415, in _check_setup_finished
    raise AssertionError(
AssertionError: The setup method 'route' can no longer be called on the application. It has already handled its first request, any changes will not be applied consistently.
Make sure all imports, decorators, functions, etc. needed to set up the application are done before running it.

[2025-05-13 22:28:50] [ERROR] [app_init] - Exception on /home [GET]
Traceback (most recent call last):
  File "/home/runner/workspace/.pythonlibs/lib/python3.11/site-packages/flask/app.py", line 1511, in wsgi_app
    response = self.full_dispatch_request()
               ^^^^^^^^^^^^^^^^^^^^^^^^^^^^
  File "/home/runner/workspace/.pythonlibs/lib/python3.11/site-packages/flask/app.py", line 919, in full_dispatch_request
    rv = self.handle_user_exception(e)
         ^^^^^^^^^^^^^^^^^^^^^^^^^^^^^
  File "/home/runner/workspace/.pythonlibs/lib/python3.11/site-packages/flask/app.py", line 917, in full_dispatch_request
    rv = self.dispatch_request()
         ^^^^^^^^^^^^^^^^^^^^^^^
  File "/home/runner/workspace/.pythonlibs/lib/python3.11/site-packages/flask/app.py", line 902, in dispatch_request
    return self.ensure_sync(self.view_functions[rule.endpoint])(**view_args)  # type: ignore[no-any-return]
           ^^^^^^^^^^^^^^^^^^^^^^^^^^^^^^^^^^^^^^^^^^^^^^^^^^^^^^^^^^^^^^^^^
  File "/home/runner/workspace/app.py", line 713, in home
    return render_template('home.html', name=session.get('name', 'User'))
           ^^^^^^^^^^^^^^^^^^^^^^^^^^^^^^^^^^^^^^^^^^^^^^^^^^^^^^^^^^^^^^
  File "/home/runner/workspace/.pythonlibs/lib/python3.11/site-packages/flask/templating.py", line 150, in render_template
    return _render(app, template, context)
           ^^^^^^^^^^^^^^^^^^^^^^^^^^^^^^^
  File "/home/runner/workspace/.pythonlibs/lib/python3.11/site-packages/flask/templating.py", line 131, in _render
    rv = template.render(context)
         ^^^^^^^^^^^^^^^^^^^^^^^^
  File "/home/runner/workspace/.pythonlibs/lib/python3.11/site-packages/jinja2/environment.py", line 1295, in render
    self.environment.handle_exception()
  File "/home/runner/workspace/.pythonlibs/lib/python3.11/site-packages/jinja2/environment.py", line 942, in handle_exception
    raise rewrite_traceback_stack(source=source)
  File "/home/runner/workspace/templates/home.html", line 1, in top-level template code
    {% extends 'layout.html' %}
    ^^^^^^^^^^^^^^^^^^^^^^^^^
  File "/home/runner/workspace/templates/layout.html", line 69, in top-level template code
    <a class="nav-link text-light" href="{{ url_for('color_scheme.color_preferences') }}">
    ^^^^^^^^^^^^^^^^^^^^^^^^^
  File "/home/runner/workspace/.pythonlibs/lib/python3.11/site-packages/flask/app.py", line 1121, in url_for
    return self.handle_url_build_error(error, endpoint, values)
           ^^^^^^^^^^^^^^^^^^^^^^^^^^^^^^^^^^^^^^^^^^^^^^^^^^^^
  File "/home/runner/workspace/.pythonlibs/lib/python3.11/site-packages/flask/app.py", line 1110, in url_for
    rv = url_adapter.build(  # type: ignore[union-attr]
         ^^^^^^^^^^^^^^^^^^^^^^^^^^^^^^^^^^^^^^^^^^^^^^
  File "/home/runner/workspace/.pythonlibs/lib/python3.11/site-packages/werkzeug/routing/map.py", line 924, in build
    raise BuildError(endpoint, values, method, self)
werkzeug.routing.exceptions.BuildError: Could not build url for endpoint 'color_scheme.color_preferences'. Did you mean 'color_scheme.color_scheme_home' instead?
[2025-05-13 22:31:21] [INFO] [root] - Default logging configuration applied
[2025-05-13 22:31:21] [INFO] [adaptive_conversation] - Conversation Complexity Engine initialized
[2025-05-13 22:31:21] [INFO] [routes.adaptive_conversation_routes] - Adaptive conversation routes registered
[2025-05-13 22:31:21] [INFO] [routes.learning_routes] - Learning routes registered
[2025-05-13 22:31:21] [INFO] [routes.health_routes] - Health routes registered
[2025-05-13 22:31:21] [INFO] [main] - AlphaVox application initialized
[2025-05-13 22:32:01] [INFO] [nonverbal_engine] - Initializing NonverbalEngine with self-learning capabilities
[2025-05-13 22:32:01] [INFO] [nonverbal_engine] - NonverbalEngine initialized with self-modification capabilities
[2025-05-13 22:32:01] [INFO] [real_eye_tracking] - Real eye tracking service initialized
[2025-05-13 22:32:01] [INFO] [root] - Using real eye tracking service
[2025-05-13 22:32:01] [WARNING] [root] - Real speech recognition not available: No module named 'sounddevice', using simulated service
[2025-05-13 22:32:01] [INFO] [sound_recognition_service] - Initializing SoundRecognitionService
[2025-05-13 22:32:01] [INFO] [sound_recognition_service] - Using simulated sound recognition
[2025-05-13 22:32:01] [INFO] [sound_recognition_service] - SoundRecognitionService initialized
[2025-05-13 22:32:01] [INFO] [behavior_capture] - Initialized behavior capture processors
[2025-05-13 22:32:01] [INFO] [root] - Behavior capture system initialized
[2025-05-13 22:32:01] [INFO] [root] - Initialized AI self-learning and self-modification capabilities
[2025-05-13 22:32:01] [INFO] [nonverbal_engine] - Initializing NonverbalEngine with self-learning capabilities
[2025-05-13 22:32:01] [INFO] [nonverbal_engine] - NonverbalEngine initialized with self-modification capabilities
[2025-05-13 22:32:01] [INFO] [conversation_engine] - Conversation engine initialized
[2025-05-13 22:32:01] [INFO] [input_analyzer] - Input analyzer initialized
[2025-05-13 22:32:01] [INFO] [behavioral_interpreter] - Behavioral interpreter initialized
[2025-05-13 22:32:01] [INFO] [interpreter] - Interpreter initialized
[2025-05-13 22:32:01] [INFO] [root] - Advanced AI interpreter initialized
[2025-05-13 22:32:01] [INFO] [root] - All advanced AI components initialized
[2025-05-13 22:32:01] [INFO] [modules.knowledge_integration] - Knowledge engine loaded
[2025-05-13 22:32:01] [INFO] [modules.knowledge_integration] - Loaded 15 facts from knowledge base
[2025-05-13 22:32:01] [INFO] [modules.knowledge_integration] - Loaded 10 topics from knowledge base
[2025-05-13 22:32:01] [INFO] [modules.knowledge_integration] - Loaded knowledge graph with 2 nodes
[2025-05-13 22:32:01] [INFO] [modules.knowledge_integration] - Knowledge Integration initialized
[2025-05-13 22:32:01] [INFO] [root] - Knowledge integration initialized
[2025-05-13 22:32:01] [WARNING] [modules.speech_integration] - Real speech recognition engine not available
[2025-05-13 22:32:01] [INFO] [attached_assets.enhanced_speech_recognition] - Initializing EnhancedSpeechRecognition
[2025-05-13 22:32:01] [INFO] [sound_recognition_service] - Initializing SoundRecognitionService
[2025-05-13 22:32:01] [INFO] [sound_recognition_service] - Using simulated sound recognition
[2025-05-13 22:32:01] [INFO] [sound_recognition_service] - SoundRecognitionService initialized
[2025-05-13 22:32:01] [INFO] [attached_assets.enhanced_speech_recognition] - Sound recognition service loaded
[2025-05-13 22:32:01] [INFO] [attached_assets.enhanced_speech_recognition] - EnhancedSpeechRecognition initialized
[2025-05-13 22:32:01] [INFO] [modules.speech_integration] - Enhanced speech recognition loaded
[2025-05-13 22:32:01] [INFO] [modules.speech_integration] - Speech Integration initialized
[2025-05-13 22:32:01] [INFO] [root] - Speech integration initialized
[2025-05-13 22:32:01] [WARNING] [attached_assets.caregiver_interface] - Eye tracking service not available
[2025-05-13 22:32:01] [WARNING] [attached_assets.caregiver_interface] - Learning analytics not available
[2025-05-13 22:32:01] [WARNING] [attached_assets.caregiver_interface] - Nonverbal expertise not available
[2025-05-13 22:32:01] [INFO] [attached_assets.caregiver_interface] - Loaded 1 user profiles
[2025-05-13 22:32:01] [INFO] [attached_assets.caregiver_interface] - Loaded communication history for 1 users
[2025-05-13 22:32:01] [INFO] [attached_assets.caregiver_interface] - Caregiver Interface initialized
[2025-05-13 22:32:01] [INFO] [modules.caregiver_dashboard] - Caregiver Interface loaded successfully
[2025-05-13 22:32:01] [INFO] [modules.caregiver_dashboard] - Caregiver Dashboard module initialized
[2025-05-13 22:32:01] [INFO] [root] - Caregiver dashboard initialized
[2025-05-13 22:32:01] [WARNING] [root] - Real speech recognition not available
[2025-05-13 22:32:01] [WARNING] [root] - Using simulated speech recognition
[2025-05-13 22:32:01] [INFO] [root] - Audio processor initialized with real speech: False
[2025-05-13 22:32:01] [INFO] [root] - Audio processor initialized
[2025-05-13 22:32:01] [INFO] [attached_assets.engine_temporal] - Language map loaded successfully
[2025-05-13 22:32:01] [WARNING] [attached_assets.engine_temporal] - LSTM model directory not found at lstm_models
[2025-05-13 22:32:01] [INFO] [attached_assets.engine_temporal] - TemporalNonverbalEngine initialized successfully
[2025-05-13 22:32:01] [INFO] [root] - Temporal nonverbal engine initialized
[2025-05-13 22:32:01] [ERROR] [attached_assets.conversation_integration] - Failed to load required components: cannot import name 'alphavox' from 'alphavox' (unknown location)
[2025-05-13 22:32:01] [WARNING] [attached_assets.conversation_integration] - Some functionality may be limited
[2025-05-13 22:32:01] [INFO] [attached_assets.conversation_integration] - Conversation Integration initialized for user: default_user
[2025-05-13 22:32:01] [INFO] [root] - Conversation integration initialized
[2025-05-13 22:32:01] [ERROR] [root] - Error initializing integration modules: The setup method 'route' can no longer be called on the application. It has already handled its first request, any changes will not be applied consistently.
Make sure all imports, decorators, functions, etc. needed to set up the application are done before running it.
[2025-05-13 22:32:01] [ERROR] [root] - Traceback (most recent call last):
  File "/home/runner/workspace/app.py", line 200, in init_services
    register_caregiver_routes(app)
  File "/home/runner/workspace/modules/caregiver_dashboard.py", line 180, in register_caregiver_routes
    @app.route('/caregiver')
     ^^^^^^^^^^^^^^^^^^^^^^^
  File "/home/runner/workspace/.pythonlibs/lib/python3.11/site-packages/flask/sansio/scaffold.py", line 46, in wrapper_func
    self._check_setup_finished(f_name)
  File "/home/runner/workspace/.pythonlibs/lib/python3.11/site-packages/flask/sansio/app.py", line 415, in _check_setup_finished
    raise AssertionError(
AssertionError: The setup method 'route' can no longer be called on the application. It has already handled its first request, any changes will not be applied consistently.
Make sure all imports, decorators, functions, etc. needed to set up the application are done before running it.

[2025-05-13 22:32:34] [INFO] [root] - Default logging configuration applied
[2025-05-13 22:32:34] [INFO] [adaptive_conversation] - Conversation Complexity Engine initialized
[2025-05-13 22:32:34] [INFO] [routes.adaptive_conversation_routes] - Adaptive conversation routes registered
[2025-05-13 22:32:34] [INFO] [routes.learning_routes] - Learning routes registered
[2025-05-13 22:32:34] [INFO] [routes.health_routes] - Health routes registered
[2025-05-13 22:32:34] [INFO] [main] - AlphaVox application initialized
[2025-05-13 22:32:34] [INFO] [root] - Using voice: US Male (us_male)
[2025-05-13 22:32:34] [INFO] [root] - Generated speech with advanced TTS: 2e565dc8de98e0705a86dd0c1641289b.mp3
[2025-05-13 22:32:34] [INFO] [root] - Speaking greeting: Good evening! Welcome back, Ev...
[2025-05-13 22:32:35] [INFO] [root] - Using voice: US Male (us_male)
[2025-05-13 22:32:35] [INFO] [root] - Generated speech with advanced TTS: 2e565dc8de98e0705a86dd0c1641289b.mp3
[2025-05-13 22:32:35] [INFO] [root] - Speaking greeting: Good evening! Welcome back, Ev...
[2025-05-13 22:33:21] [ERROR] [root] - Error using AlphaVox NLU for gesture: No module named 'sklearn'
[2025-05-13 22:33:21] [ERROR] [root] - Traceback (most recent call last):
  File "/home/runner/workspace/app.py", line 903, in speak
    from alphavox_input_nlu import get_input_processor
  File "/home/runner/workspace/alphavox_input_nlu.py", line 10, in <module>
    from neural_learning_core import NeuralLearningCore
  File "/home/runner/workspace/neural_learning_core.py", line 9, in <module>
    from sklearn.ensemble import RandomForestClassifier
ModuleNotFoundError: No module named 'sklearn'

[2025-05-13 22:33:21] [INFO] [root] - Using voice: US Male (us_male)
[2025-05-13 22:33:21] [INFO] [root] - Generated speech with advanced TTS: 94ad3b543c95daee980e2dc1427206a6.mp3
[2025-05-13 22:33:21] [ERROR] [root] - Error using AlphaVox NLU for gesture: No module named 'sklearn'
[2025-05-13 22:33:21] [ERROR] [root] - Traceback (most recent call last):
  File "/home/runner/workspace/app.py", line 903, in speak
    from alphavox_input_nlu import get_input_processor
  File "/home/runner/workspace/alphavox_input_nlu.py", line 10, in <module>
    from neural_learning_core import NeuralLearningCore
  File "/home/runner/workspace/neural_learning_core.py", line 9, in <module>
    from sklearn.ensemble import RandomForestClassifier
ModuleNotFoundError: No module named 'sklearn'

[2025-05-13 22:33:22] [INFO] [root] - Using voice: US Male (us_male)
[2025-05-13 22:33:22] [INFO] [root] - Generated speech with advanced TTS: 94ad3b543c95daee980e2dc1427206a6.mp3
[2025-05-13 22:33:26] [ERROR] [root] - Error using AlphaVox NLU for gesture: No module named 'sklearn'
[2025-05-13 22:33:26] [ERROR] [root] - Traceback (most recent call last):
  File "/home/runner/workspace/app.py", line 903, in speak
    from alphavox_input_nlu import get_input_processor
  File "/home/runner/workspace/alphavox_input_nlu.py", line 10, in <module>
    from neural_learning_core import NeuralLearningCore
  File "/home/runner/workspace/neural_learning_core.py", line 9, in <module>
    from sklearn.ensemble import RandomForestClassifier
ModuleNotFoundError: No module named 'sklearn'

[2025-05-13 22:33:26] [INFO] [root] - Using voice: US Male (us_male)
[2025-05-13 22:33:26] [INFO] [root] - Generated speech with advanced TTS: 95442782f93e1edd95d9cf04005a67ea.mp3
[2025-05-13 22:33:26] [ERROR] [root] - Error using AlphaVox NLU for gesture: No module named 'sklearn'
[2025-05-13 22:33:26] [ERROR] [root] - Traceback (most recent call last):
  File "/home/runner/workspace/app.py", line 903, in speak
    from alphavox_input_nlu import get_input_processor
  File "/home/runner/workspace/alphavox_input_nlu.py", line 10, in <module>
    from neural_learning_core import NeuralLearningCore
  File "/home/runner/workspace/neural_learning_core.py", line 9, in <module>
    from sklearn.ensemble import RandomForestClassifier
ModuleNotFoundError: No module named 'sklearn'

[2025-05-13 22:33:26] [INFO] [root] - Using voice: US Male (us_male)
[2025-05-13 22:33:26] [INFO] [root] - Generated speech with advanced TTS: 95442782f93e1edd95d9cf04005a67ea.mp3
[2025-05-13 22:33:30] [ERROR] [root] - Error using AlphaVox NLU for gesture: No module named 'sklearn'
[2025-05-13 22:33:30] [ERROR] [root] - Traceback (most recent call last):
  File "/home/runner/workspace/app.py", line 903, in speak
    from alphavox_input_nlu import get_input_processor
  File "/home/runner/workspace/alphavox_input_nlu.py", line 10, in <module>
    from neural_learning_core import NeuralLearningCore
  File "/home/runner/workspace/neural_learning_core.py", line 9, in <module>
    from sklearn.ensemble import RandomForestClassifier
ModuleNotFoundError: No module named 'sklearn'

[2025-05-13 22:33:30] [INFO] [root] - Using voice: US Male (us_male)
[2025-05-13 22:33:30] [INFO] [root] - Generated speech with advanced TTS: 1f764bbdb9e8adc611a04c28fabe30d3.mp3
[2025-05-13 22:33:30] [ERROR] [root] - Error using AlphaVox NLU for gesture: No module named 'sklearn'
[2025-05-13 22:33:30] [ERROR] [root] - Traceback (most recent call last):
  File "/home/runner/workspace/app.py", line 903, in speak
    from alphavox_input_nlu import get_input_processor
  File "/home/runner/workspace/alphavox_input_nlu.py", line 10, in <module>
    from neural_learning_core import NeuralLearningCore
  File "/home/runner/workspace/neural_learning_core.py", line 9, in <module>
    from sklearn.ensemble import RandomForestClassifier
ModuleNotFoundError: No module named 'sklearn'

[2025-05-13 22:33:30] [INFO] [root] - Using voice: US Male (us_male)
[2025-05-13 22:33:30] [INFO] [root] - Generated speech with advanced TTS: 1f764bbdb9e8adc611a04c28fabe30d3.mp3
[2025-05-13 22:33:34] [ERROR] [root] - Error using AlphaVox NLU for gesture: No module named 'sklearn'
[2025-05-13 22:33:34] [ERROR] [root] - Traceback (most recent call last):
  File "/home/runner/workspace/app.py", line 903, in speak
    from alphavox_input_nlu import get_input_processor
  File "/home/runner/workspace/alphavox_input_nlu.py", line 10, in <module>
    from neural_learning_core import NeuralLearningCore
  File "/home/runner/workspace/neural_learning_core.py", line 9, in <module>
    from sklearn.ensemble import RandomForestClassifier
ModuleNotFoundError: No module named 'sklearn'

[2025-05-13 22:33:34] [INFO] [root] - Using voice: US Male (us_male)
[2025-05-13 22:33:34] [INFO] [root] - Generated speech with advanced TTS: a6c65af7bd05a61760df28da99901099.mp3
[2025-05-13 22:33:34] [ERROR] [root] - Error using AlphaVox NLU for gesture: No module named 'sklearn'
[2025-05-13 22:33:34] [ERROR] [root] - Traceback (most recent call last):
  File "/home/runner/workspace/app.py", line 903, in speak
    from alphavox_input_nlu import get_input_processor
  File "/home/runner/workspace/alphavox_input_nlu.py", line 10, in <module>
    from neural_learning_core import NeuralLearningCore
  File "/home/runner/workspace/neural_learning_core.py", line 9, in <module>
    from sklearn.ensemble import RandomForestClassifier
ModuleNotFoundError: No module named 'sklearn'

[2025-05-13 22:33:34] [INFO] [root] - Using voice: US Male (us_male)
[2025-05-13 22:33:34] [INFO] [root] - Generated speech with advanced TTS: a6c65af7bd05a61760df28da99901099.mp3
[2025-05-13 22:33:37] [ERROR] [root] - Error using AlphaVox NLU for gesture: No module named 'sklearn'
[2025-05-13 22:33:37] [ERROR] [root] - Traceback (most recent call last):
  File "/home/runner/workspace/app.py", line 903, in speak
    from alphavox_input_nlu import get_input_processor
  File "/home/runner/workspace/alphavox_input_nlu.py", line 10, in <module>
    from neural_learning_core import NeuralLearningCore
  File "/home/runner/workspace/neural_learning_core.py", line 9, in <module>
    from sklearn.ensemble import RandomForestClassifier
ModuleNotFoundError: No module named 'sklearn'

[2025-05-13 22:33:37] [INFO] [root] - Using voice: US Male (us_male)
[2025-05-13 22:33:37] [INFO] [root] - Generated speech with advanced TTS: 92ea85578df65f9c48a073affdea72b1.mp3
[2025-05-13 22:33:37] [ERROR] [root] - Error using AlphaVox NLU for gesture: No module named 'sklearn'
[2025-05-13 22:33:37] [ERROR] [root] - Traceback (most recent call last):
  File "/home/runner/workspace/app.py", line 903, in speak
    from alphavox_input_nlu import get_input_processor
  File "/home/runner/workspace/alphavox_input_nlu.py", line 10, in <module>
    from neural_learning_core import NeuralLearningCore
  File "/home/runner/workspace/neural_learning_core.py", line 9, in <module>
    from sklearn.ensemble import RandomForestClassifier
ModuleNotFoundError: No module named 'sklearn'

[2025-05-13 22:33:37] [INFO] [root] - Using voice: US Male (us_male)
[2025-05-13 22:33:37] [INFO] [root] - Generated speech with advanced TTS: 92ea85578df65f9c48a073affdea72b1.mp3
[2025-05-13 22:33:39] [ERROR] [root] - Error using AlphaVox NLU for gesture: No module named 'sklearn'
[2025-05-13 22:33:39] [ERROR] [root] - Traceback (most recent call last):
  File "/home/runner/workspace/app.py", line 903, in speak
    from alphavox_input_nlu import get_input_processor
  File "/home/runner/workspace/alphavox_input_nlu.py", line 10, in <module>
    from neural_learning_core import NeuralLearningCore
  File "/home/runner/workspace/neural_learning_core.py", line 9, in <module>
    from sklearn.ensemble import RandomForestClassifier
ModuleNotFoundError: No module named 'sklearn'

[2025-05-13 22:33:39] [INFO] [root] - Using voice: US Male (us_male)
[2025-05-13 22:33:39] [INFO] [root] - Generated speech with advanced TTS: 35162daf3800c9bf4198dec35a032c45.mp3
[2025-05-13 22:33:39] [ERROR] [root] - Error using AlphaVox NLU for gesture: No module named 'sklearn'
[2025-05-13 22:33:39] [ERROR] [root] - Traceback (most recent call last):
  File "/home/runner/workspace/app.py", line 903, in speak
    from alphavox_input_nlu import get_input_processor
  File "/home/runner/workspace/alphavox_input_nlu.py", line 10, in <module>
    from neural_learning_core import NeuralLearningCore
  File "/home/runner/workspace/neural_learning_core.py", line 9, in <module>
    from sklearn.ensemble import RandomForestClassifier
ModuleNotFoundError: No module named 'sklearn'

[2025-05-13 22:33:39] [INFO] [root] - Using voice: US Male (us_male)
[2025-05-13 22:33:39] [INFO] [root] - Generated speech with advanced TTS: 35162daf3800c9bf4198dec35a032c45.mp3
[2025-05-13 22:33:41] [ERROR] [root] - Error using AlphaVox NLU for gesture: No module named 'sklearn'
[2025-05-13 22:33:41] [ERROR] [root] - Traceback (most recent call last):
  File "/home/runner/workspace/app.py", line 903, in speak
    from alphavox_input_nlu import get_input_processor
  File "/home/runner/workspace/alphavox_input_nlu.py", line 10, in <module>
    from neural_learning_core import NeuralLearningCore
  File "/home/runner/workspace/neural_learning_core.py", line 9, in <module>
    from sklearn.ensemble import RandomForestClassifier
ModuleNotFoundError: No module named 'sklearn'

[2025-05-13 22:33:41] [INFO] [root] - Using voice: US Male (us_male)
[2025-05-13 22:33:41] [INFO] [root] - Generated speech with advanced TTS: d028fbe058f5cbd7a8708ba923fa3098.mp3
[2025-05-13 22:33:41] [ERROR] [root] - Error using AlphaVox NLU for gesture: No module named 'sklearn'
[2025-05-13 22:33:41] [ERROR] [root] - Traceback (most recent call last):
  File "/home/runner/workspace/app.py", line 903, in speak
    from alphavox_input_nlu import get_input_processor
  File "/home/runner/workspace/alphavox_input_nlu.py", line 10, in <module>
    from neural_learning_core import NeuralLearningCore
  File "/home/runner/workspace/neural_learning_core.py", line 9, in <module>
    from sklearn.ensemble import RandomForestClassifier
ModuleNotFoundError: No module named 'sklearn'

[2025-05-13 22:33:42] [INFO] [root] - Using voice: US Male (us_male)
[2025-05-13 22:33:42] [INFO] [root] - Generated speech with advanced TTS: d028fbe058f5cbd7a8708ba923fa3098.mp3
[2025-05-13 22:33:44] [ERROR] [root] - Error using AlphaVox NLU for gesture: No module named 'sklearn'
[2025-05-13 22:33:44] [ERROR] [root] - Traceback (most recent call last):
  File "/home/runner/workspace/app.py", line 903, in speak
    from alphavox_input_nlu import get_input_processor
  File "/home/runner/workspace/alphavox_input_nlu.py", line 10, in <module>
    from neural_learning_core import NeuralLearningCore
  File "/home/runner/workspace/neural_learning_core.py", line 9, in <module>
    from sklearn.ensemble import RandomForestClassifier
ModuleNotFoundError: No module named 'sklearn'

[2025-05-13 22:33:44] [INFO] [root] - Using voice: US Male (us_male)
[2025-05-13 22:33:44] [INFO] [root] - Generated speech with advanced TTS: d028fbe058f5cbd7a8708ba923fa3098.mp3
[2025-05-13 22:33:44] [ERROR] [root] - Error using AlphaVox NLU for gesture: No module named 'sklearn'
[2025-05-13 22:33:44] [ERROR] [root] - Traceback (most recent call last):
  File "/home/runner/workspace/app.py", line 903, in speak
    from alphavox_input_nlu import get_input_processor
  File "/home/runner/workspace/alphavox_input_nlu.py", line 10, in <module>
    from neural_learning_core import NeuralLearningCore
  File "/home/runner/workspace/neural_learning_core.py", line 9, in <module>
    from sklearn.ensemble import RandomForestClassifier
ModuleNotFoundError: No module named 'sklearn'

[2025-05-13 22:33:44] [INFO] [root] - Using voice: US Male (us_male)
[2025-05-13 22:33:44] [INFO] [root] - Generated speech with advanced TTS: d028fbe058f5cbd7a8708ba923fa3098.mp3
[2025-05-13 22:34:56] [INFO] [root] - Default logging configuration applied
[2025-05-13 22:34:56] [INFO] [adaptive_conversation] - Conversation Complexity Engine initialized
[2025-05-13 22:34:56] [INFO] [routes.adaptive_conversation_routes] - Adaptive conversation routes registered
[2025-05-13 22:34:56] [INFO] [routes.learning_routes] - Learning routes registered
[2025-05-13 22:34:56] [INFO] [routes.health_routes] - Health routes registered
[2025-05-13 22:34:56] [INFO] [main] - AlphaVox application initialized
[2025-05-13 22:35:40] [INFO] [root] - Default logging configuration applied
[2025-05-13 22:35:40] [INFO] [adaptive_conversation] - Conversation Complexity Engine initialized
[2025-05-13 22:35:40] [INFO] [routes.adaptive_conversation_routes] - Adaptive conversation routes registered
[2025-05-13 22:35:40] [INFO] [routes.learning_routes] - Learning routes registered
[2025-05-13 22:35:40] [INFO] [routes.health_routes] - Health routes registered
[2025-05-13 22:35:40] [INFO] [main] - AlphaVox application initialized
[2025-05-13 22:35:40] [INFO] [root] - Using voice: US Male (us_male)
[2025-05-13 22:35:40] [INFO] [root] - Generated speech with advanced TTS: 2e565dc8de98e0705a86dd0c1641289b.mp3
[2025-05-13 22:35:40] [INFO] [root] - Speaking greeting: Good evening! Welcome back, Ev...
[2025-05-13 22:35:41] [INFO] [root] - Using voice: US Male (us_male)
[2025-05-13 22:35:41] [INFO] [root] - Generated speech with advanced TTS: 2e565dc8de98e0705a86dd0c1641289b.mp3
[2025-05-13 22:35:41] [INFO] [root] - Speaking greeting: Good evening! Welcome back, Ev...
[2025-05-13 22:35:53] [INFO] [nonverbal_engine] - Initializing NonverbalEngine with self-learning capabilities
[2025-05-13 22:35:53] [INFO] [nonverbal_engine] - NonverbalEngine initialized with self-modification capabilities
[2025-05-13 22:35:53] [INFO] [real_eye_tracking] - Real eye tracking service initialized
[2025-05-13 22:35:53] [INFO] [root] - Using real eye tracking service
[2025-05-13 22:35:53] [WARNING] [root] - Real speech recognition not available: No module named 'sounddevice', using simulated service
[2025-05-13 22:35:53] [INFO] [sound_recognition_service] - Initializing SoundRecognitionService
[2025-05-13 22:35:53] [INFO] [sound_recognition_service] - Using simulated sound recognition
[2025-05-13 22:35:53] [INFO] [sound_recognition_service] - SoundRecognitionService initialized
[2025-05-13 22:35:53] [INFO] [behavior_capture] - Initialized behavior capture processors
[2025-05-13 22:35:53] [INFO] [root] - Behavior capture system initialized
[2025-05-13 22:35:53] [INFO] [root] - Initialized AI self-learning and self-modification capabilities
[2025-05-13 22:35:53] [INFO] [nonverbal_engine] - Initializing NonverbalEngine with self-learning capabilities
[2025-05-13 22:35:53] [INFO] [nonverbal_engine] - NonverbalEngine initialized with self-modification capabilities
[2025-05-13 22:35:53] [INFO] [conversation_engine] - Conversation engine initialized
[2025-05-13 22:35:53] [INFO] [input_analyzer] - Input analyzer initialized
[2025-05-13 22:35:53] [INFO] [behavioral_interpreter] - Behavioral interpreter initialized
[2025-05-13 22:35:53] [INFO] [interpreter] - Interpreter initialized
[2025-05-13 22:35:53] [INFO] [root] - Advanced AI interpreter initialized
[2025-05-13 22:35:53] [INFO] [root] - All advanced AI components initialized
[2025-05-13 22:35:53] [INFO] [modules.knowledge_integration] - Knowledge engine loaded
[2025-05-13 22:35:53] [INFO] [modules.knowledge_integration] - Loaded 15 facts from knowledge base
[2025-05-13 22:35:53] [INFO] [modules.knowledge_integration] - Loaded 10 topics from knowledge base
[2025-05-13 22:35:53] [INFO] [modules.knowledge_integration] - Loaded knowledge graph with 2 nodes
[2025-05-13 22:35:53] [INFO] [modules.knowledge_integration] - Knowledge Integration initialized
[2025-05-13 22:35:53] [INFO] [root] - Knowledge integration initialized
[2025-05-13 22:35:53] [WARNING] [modules.speech_integration] - Real speech recognition engine not available
[2025-05-13 22:35:54] [INFO] [attached_assets.enhanced_speech_recognition] - Initializing EnhancedSpeechRecognition
[2025-05-13 22:35:54] [INFO] [sound_recognition_service] - Initializing SoundRecognitionService
[2025-05-13 22:35:54] [INFO] [sound_recognition_service] - Using simulated sound recognition
[2025-05-13 22:35:54] [INFO] [sound_recognition_service] - SoundRecognitionService initialized
[2025-05-13 22:35:54] [INFO] [attached_assets.enhanced_speech_recognition] - Sound recognition service loaded
[2025-05-13 22:35:54] [INFO] [attached_assets.enhanced_speech_recognition] - EnhancedSpeechRecognition initialized
[2025-05-13 22:35:54] [INFO] [modules.speech_integration] - Enhanced speech recognition loaded
[2025-05-13 22:35:54] [INFO] [modules.speech_integration] - Speech Integration initialized
[2025-05-13 22:35:54] [INFO] [root] - Speech integration initialized
[2025-05-13 22:35:54] [WARNING] [attached_assets.caregiver_interface] - Eye tracking service not available
[2025-05-13 22:35:54] [WARNING] [attached_assets.caregiver_interface] - Learning analytics not available
[2025-05-13 22:35:54] [WARNING] [attached_assets.caregiver_interface] - Nonverbal expertise not available
[2025-05-13 22:35:54] [INFO] [attached_assets.caregiver_interface] - Loaded 1 user profiles
[2025-05-13 22:35:54] [INFO] [attached_assets.caregiver_interface] - Loaded communication history for 1 users
[2025-05-13 22:35:54] [INFO] [attached_assets.caregiver_interface] - Caregiver Interface initialized
[2025-05-13 22:35:54] [INFO] [modules.caregiver_dashboard] - Caregiver Interface loaded successfully
[2025-05-13 22:35:54] [INFO] [modules.caregiver_dashboard] - Caregiver Dashboard module initialized
[2025-05-13 22:35:54] [INFO] [root] - Caregiver dashboard initialized
[2025-05-13 22:35:54] [WARNING] [root] - Real speech recognition not available
[2025-05-13 22:35:54] [WARNING] [root] - Using simulated speech recognition
[2025-05-13 22:35:54] [INFO] [root] - Audio processor initialized with real speech: False
[2025-05-13 22:35:54] [INFO] [root] - Audio processor initialized
[2025-05-13 22:35:54] [INFO] [attached_assets.engine_temporal] - Language map loaded successfully
[2025-05-13 22:35:54] [WARNING] [attached_assets.engine_temporal] - LSTM model directory not found at lstm_models
[2025-05-13 22:35:54] [INFO] [attached_assets.engine_temporal] - TemporalNonverbalEngine initialized successfully
[2025-05-13 22:35:54] [INFO] [root] - Temporal nonverbal engine initialized
[2025-05-13 22:35:54] [ERROR] [attached_assets.conversation_integration] - Failed to load required components: cannot import name 'alphavox' from 'alphavox' (unknown location)
[2025-05-13 22:35:54] [WARNING] [attached_assets.conversation_integration] - Some functionality may be limited
[2025-05-13 22:35:54] [INFO] [attached_assets.conversation_integration] - Conversation Integration initialized for user: default_user
[2025-05-13 22:35:54] [INFO] [root] - Conversation integration initialized
[2025-05-13 22:35:54] [ERROR] [root] - Error initializing integration modules: The setup method 'route' can no longer be called on the application. It has already handled its first request, any changes will not be applied consistently.
Make sure all imports, decorators, functions, etc. needed to set up the application are done before running it.
[2025-05-13 22:35:54] [ERROR] [root] - Traceback (most recent call last):
  File "/home/runner/workspace/app.py", line 200, in init_services
    register_caregiver_routes(app)
  File "/home/runner/workspace/modules/caregiver_dashboard.py", line 180, in register_caregiver_routes
    @app.route('/caregiver')
     ^^^^^^^^^^^^^^^^^^^^^^^
  File "/home/runner/workspace/.pythonlibs/lib/python3.11/site-packages/flask/sansio/scaffold.py", line 46, in wrapper_func
    self._check_setup_finished(f_name)
  File "/home/runner/workspace/.pythonlibs/lib/python3.11/site-packages/flask/sansio/app.py", line 415, in _check_setup_finished
    raise AssertionError(
AssertionError: The setup method 'route' can no longer be called on the application. It has already handled its first request, any changes will not be applied consistently.
Make sure all imports, decorators, functions, etc. needed to set up the application are done before running it.

[2025-05-13 22:35:54] [INFO] [behavior_capture] - Started behavior tracking
[2025-05-13 22:36:18] [INFO] [behavior_capture] - Stopped behavior tracking
[2025-05-13 22:41:17] [INFO] [root] - Default logging configuration applied
[2025-05-13 22:41:17] [INFO] [adaptive_conversation] - Conversation Complexity Engine initialized
[2025-05-13 22:41:17] [INFO] [routes.adaptive_conversation_routes] - Adaptive conversation routes registered
[2025-05-13 22:41:17] [INFO] [routes.learning_routes] - Learning routes registered
[2025-05-13 22:41:17] [INFO] [routes.health_routes] - Health routes registered
[2025-05-13 22:41:17] [INFO] [main] - AlphaVox application initialized
[2025-05-13 22:41:25] [INFO] [root] - Default logging configuration applied
[2025-05-13 22:41:25] [INFO] [adaptive_conversation] - Conversation Complexity Engine initialized
[2025-05-13 22:41:25] [INFO] [routes.adaptive_conversation_routes] - Adaptive conversation routes registered
[2025-05-13 22:41:25] [INFO] [routes.learning_routes] - Learning routes registered
[2025-05-13 22:41:25] [INFO] [routes.health_routes] - Health routes registered
[2025-05-13 22:41:25] [INFO] [main] - AlphaVox application initialized
[2025-05-13 22:41:37] [INFO] [root] - Default logging configuration applied
[2025-05-13 22:41:37] [INFO] [adaptive_conversation] - Conversation Complexity Engine initialized
[2025-05-13 22:41:37] [INFO] [routes.adaptive_conversation_routes] - Adaptive conversation routes registered
[2025-05-13 22:41:37] [INFO] [routes.learning_routes] - Learning routes registered
[2025-05-13 22:41:37] [INFO] [routes.health_routes] - Health routes registered
[2025-05-13 22:41:37] [INFO] [main] - AlphaVox application initialized
[2025-05-13 22:41:47] [INFO] [root] - Default logging configuration applied
[2025-05-13 22:41:48] [INFO] [adaptive_conversation] - Conversation Complexity Engine initialized
[2025-05-13 22:41:48] [INFO] [routes.adaptive_conversation_routes] - Adaptive conversation routes registered
[2025-05-13 22:41:48] [INFO] [routes.learning_routes] - Learning routes registered
[2025-05-13 22:41:48] [INFO] [routes.health_routes] - Health routes registered
[2025-05-13 22:41:48] [INFO] [main] - AlphaVox application initialized
[2025-05-13 23:04:49] [INFO] [root] - Default logging configuration applied
[2025-05-13 23:04:49] [INFO] [adaptive_conversation] - Conversation Complexity Engine initialized
[2025-05-13 23:04:49] [INFO] [routes.adaptive_conversation_routes] - Adaptive conversation routes registered
[2025-05-13 23:04:49] [INFO] [routes.learning_routes] - Learning routes registered
[2025-05-13 23:04:49] [INFO] [routes.health_routes] - Health routes registered
[2025-05-13 23:04:49] [INFO] [main] - AlphaVox application initialized
[2025-05-13 23:05:10] [INFO] [nonverbal_engine] - Initializing NonverbalEngine with self-learning capabilities
[2025-05-13 23:05:10] [INFO] [nonverbal_engine] - NonverbalEngine initialized with self-modification capabilities
[2025-05-13 23:05:10] [INFO] [real_eye_tracking] - Real eye tracking service initialized
[2025-05-13 23:05:10] [INFO] [root] - Using real eye tracking service
[2025-05-13 23:05:11] [WARNING] [root] - Real speech recognition not available: PortAudio library not found, using simulated service
[2025-05-13 23:05:11] [INFO] [sound_recognition_service] - Initializing SoundRecognitionService
[2025-05-13 23:05:11] [INFO] [attached_assets.speech_recognition_engine] - Speech Recognition Engine initialized with language: en-US
[2025-05-13 23:05:11] [INFO] [sound_recognition_service] - Using simulated speech recognition engine
[2025-05-13 23:05:11] [INFO] [sound_recognition_service] - Using real speech recognition engine
[2025-05-13 23:05:11] [INFO] [sound_recognition_service] - SoundRecognitionService initialized
[2025-05-13 23:05:11] [INFO] [behavior_capture] - Initialized behavior capture processors
[2025-05-13 23:05:11] [INFO] [root] - Behavior capture system initialized
[2025-05-13 23:05:11] [INFO] [root] - Initialized AI self-learning and self-modification capabilities
[2025-05-13 23:05:11] [INFO] [nonverbal_engine] - Initializing NonverbalEngine with self-learning capabilities
[2025-05-13 23:05:11] [INFO] [nonverbal_engine] - NonverbalEngine initialized with self-modification capabilities
[2025-05-13 23:05:11] [INFO] [conversation_engine] - Conversation engine initialized
[2025-05-13 23:05:11] [INFO] [input_analyzer] - Input analyzer initialized
[2025-05-13 23:05:11] [INFO] [behavioral_interpreter] - Behavioral interpreter initialized
[2025-05-13 23:05:11] [INFO] [interpreter] - Interpreter initialized
[2025-05-13 23:05:11] [INFO] [root] - Advanced AI interpreter initialized
[2025-05-13 23:05:11] [INFO] [root] - All advanced AI components initialized
[2025-05-13 23:05:11] [INFO] [modules.knowledge_integration] - Knowledge engine loaded
[2025-05-13 23:05:11] [INFO] [modules.knowledge_integration] - Loaded 15 facts from knowledge base
[2025-05-13 23:05:11] [INFO] [modules.knowledge_integration] - Loaded 10 topics from knowledge base
[2025-05-13 23:05:11] [INFO] [modules.knowledge_integration] - Loaded knowledge graph with 2 nodes
[2025-05-13 23:05:11] [INFO] [modules.knowledge_integration] - Knowledge Integration initialized
[2025-05-13 23:05:11] [INFO] [root] - Knowledge integration initialized
[2025-05-13 23:05:11] [ERROR] [root] - Error initializing integration modules: PortAudio library not found
[2025-05-13 23:05:11] [ERROR] [root] - Traceback (most recent call last):
  File "/home/runner/workspace/app.py", line 153, in init_services
    speech_integration = get_speech_integration()
                         ^^^^^^^^^^^^^^^^^^^^^^^^
  File "/home/runner/workspace/modules/speech_integration.py", line 177, in get_speech_integration
    _speech_integration = SpeechIntegration()
                          ^^^^^^^^^^^^^^^^^^^
  File "/home/runner/workspace/modules/speech_integration.py", line 45, in __init__
    self._initialize_components()
  File "/home/runner/workspace/modules/speech_integration.py", line 53, in _initialize_components
    from real_speech_recognition import get_speech_recognition_engine
  File "/home/runner/workspace/real_speech_recognition.py", line 13, in <module>
    import sounddevice as sd
  File "/home/runner/workspace/.pythonlibs/lib/python3.11/site-packages/sounddevice.py", line 71, in <module>
    raise OSError('PortAudio library not found')
OSError: PortAudio library not found

[2025-05-13 23:05:44] [INFO] [root] - Default logging configuration applied
[2025-05-13 23:05:44] [INFO] [adaptive_conversation] - Conversation Complexity Engine initialized
[2025-05-13 23:05:44] [INFO] [routes.adaptive_conversation_routes] - Adaptive conversation routes registered
[2025-05-13 23:05:44] [INFO] [routes.learning_routes] - Learning routes registered
[2025-05-13 23:05:44] [INFO] [routes.health_routes] - Health routes registered
[2025-05-13 23:05:44] [INFO] [main] - AlphaVox application initialized
[2025-05-13 23:06:22] [ERROR] [neural_learning_core] - Failed to load spaCy model: [E050] Can't find model 'en_core_web_sm'. It doesn't seem to be a Python package or a valid path to a data directory.
[2025-05-13 23:06:22] [INFO] [neural_learning_core] - Creating a basic spaCy model as fallback
[2025-05-13 23:06:22] [ERROR] [research_module] - Failed to load spaCy model: [E050] Can't find model 'en_core_web_sm'. It doesn't seem to be a Python package or a valid path to a data directory.
[2025-05-13 23:06:22] [INFO] [research_module] - Install spaCy and download model: pip install spacy && python -m spacy download en_core_web_sm
[2025-05-13 23:06:22] [ERROR] [alphavox_input_nlu] - Failed to load spaCy model: [E050] Can't find model 'en_core_web_sm'. It doesn't seem to be a Python package or a valid path to a data directory.
[2025-05-13 23:06:22] [INFO] [alphavox_input_nlu] - Install spaCy and download model: pip install spacy && python -m spacy download en_core_web_sm
[2025-05-13 23:06:22] [INFO] [neural_learning_core] - Loaded 1 interactions from memory
[2025-05-13 23:06:22] [INFO] [neural_learning_core] - Root cause model initialized
[2025-05-13 23:06:22] [INFO] [neural_learning_core] - Neural Learning Core initialized
[2025-05-13 23:06:22] [INFO] [research_module] - AlphaVox Research Module initialized
[2025-05-13 23:06:22] [INFO] [alphavox_input_nlu] - Loaded context window with 1 users
[2025-05-13 23:06:24] [INFO] [research_module] - Saved research cache
[2025-05-13 23:06:24] [INFO] [research_module] - Fetched 0 research articles
[2025-05-13 23:06:24] [WARNING] [research_module] - No articles to analyze
[2025-05-13 23:06:24] [INFO] [neural_learning_core] - Loaded 1 interactions from memory
[2025-05-13 23:06:24] [INFO] [neural_learning_core] - Root cause model initialized
[2025-05-13 23:06:24] [INFO] [neural_learning_core] - Neural Learning Core initialized
[2025-05-13 23:06:24] [INFO] [research_module] - Integrated research insights into Neural Learning Core
[2025-05-13 23:06:24] [INFO] [research_module] - Integrated 0 strategies, 0 intents
[2025-05-13 23:06:24] [INFO] [alphavox_input_nlu] - Updated input processor with research insights
[2025-05-13 23:06:24] [INFO] [alphavox_input_nlu] - Saved context window for 1 users
[2025-05-13 23:06:24] [INFO] [alphavox_input_nlu] - AlphaVoxInputProcessor initialized
[2025-05-13 23:06:24] [ERROR] [alphavox_input_nlu] - Error processing interaction for user 1: sequence index must be integer, not 'slice'
Traceback (most recent call last):
  File "/home/runner/workspace/alphavox_input_nlu.py", line 105, in process_interaction
    interaction['context'] = self._add_context(interaction, user_id)
                             ^^^^^^^^^^^^^^^^^^^^^^^^^^^^^^^^^^^^^^^
  File "/home/runner/workspace/alphavox_input_nlu.py", line 293, in _add_context
    rc['root_cause'] for rc in self.context_window[user_id].get('root_causes', [])[-5:]
                               ~~~~~~~~~~~~~~~~~~~~~~~~~~~~~~~~~~~~~~~~~~~~~~~~~~~^^^^^
TypeError: sequence index must be integer, not 'slice'
[2025-05-13 23:06:24] [INFO] [root] - Processed symbol with AlphaVox NLU: 'sad' → unknown (0.00)
[2025-05-13 23:06:24] [INFO] [root] - Using voice: US Male (us_male)
[2025-05-13 23:06:25] [INFO] [root] - Generated speech with advanced TTS: d1d40ad26009d2139c931614bcb53679.mp3
[2025-05-13 23:06:38] [ERROR] [alphavox_input_nlu] - Error processing interaction for user 1: sequence index must be integer, not 'slice'
Traceback (most recent call last):
  File "/home/runner/workspace/alphavox_input_nlu.py", line 105, in process_interaction
    interaction['context'] = self._add_context(interaction, user_id)
                             ^^^^^^^^^^^^^^^^^^^^^^^^^^^^^^^^^^^^^^^
  File "/home/runner/workspace/alphavox_input_nlu.py", line 293, in _add_context
    rc['root_cause'] for rc in self.context_window[user_id].get('root_causes', [])[-5:]
                               ~~~~~~~~~~~~~~~~~~~~~~~~~~~~~~~~~~~~~~~~~~~~~~~~~~~^^^^^
TypeError: sequence index must be integer, not 'slice'
[2025-05-13 23:06:38] [INFO] [root] - Processed symbol with AlphaVox NLU: 'tired' → unknown (0.00)
[2025-05-13 23:06:38] [INFO] [root] - Using voice: US Male (us_male)
[2025-05-13 23:06:38] [INFO] [root] - Generated speech with advanced TTS: 82b01b3a900b44e2e080939d68e32238.mp3
[2025-05-13 23:07:17] [INFO] [root] - Default logging configuration applied
[2025-05-13 23:07:17] [INFO] [adaptive_conversation] - Conversation Complexity Engine initialized
[2025-05-13 23:07:17] [INFO] [routes.adaptive_conversation_routes] - Adaptive conversation routes registered
[2025-05-13 23:07:17] [INFO] [routes.learning_routes] - Learning routes registered
[2025-05-13 23:07:17] [INFO] [routes.health_routes] - Health routes registered
[2025-05-13 23:07:17] [INFO] [main] - AlphaVox application initialized
[2025-05-13 23:07:17] [INFO] [root] - Using voice: US Male (us_male)
[2025-05-13 23:07:17] [INFO] [root] - Generated speech with advanced TTS: 2e565dc8de98e0705a86dd0c1641289b.mp3
[2025-05-13 23:07:17] [INFO] [root] - Speaking greeting: Good evening! Welcome back, Ev...
[2025-05-13 23:07:18] [INFO] [root] - Using voice: US Male (us_male)
[2025-05-13 23:07:18] [INFO] [root] - Generated speech with advanced TTS: 2e565dc8de98e0705a86dd0c1641289b.mp3
[2025-05-13 23:07:18] [INFO] [root] - Speaking greeting: Good evening! Welcome back, Ev...
[2025-05-13 23:08:19] [ERROR] [neural_learning_core] - Failed to load spaCy model: [E050] Can't find model 'en_core_web_sm'. It doesn't seem to be a Python package or a valid path to a data directory.
[2025-05-13 23:08:19] [INFO] [neural_learning_core] - Creating a basic spaCy model as fallback
[2025-05-13 23:08:20] [ERROR] [research_module] - Failed to load spaCy model: [E050] Can't find model 'en_core_web_sm'. It doesn't seem to be a Python package or a valid path to a data directory.
[2025-05-13 23:08:20] [INFO] [research_module] - Install spaCy and download model: pip install spacy && python -m spacy download en_core_web_sm
[2025-05-13 23:08:20] [ERROR] [alphavox_input_nlu] - Failed to load spaCy model: [E050] Can't find model 'en_core_web_sm'. It doesn't seem to be a Python package or a valid path to a data directory.
[2025-05-13 23:08:20] [INFO] [alphavox_input_nlu] - Install spaCy and download model: pip install spacy && python -m spacy download en_core_web_sm
[2025-05-13 23:08:20] [INFO] [neural_learning_core] - Loaded 1 interactions from memory
[2025-05-13 23:08:20] [INFO] [neural_learning_core] - Root cause model initialized
[2025-05-13 23:08:20] [INFO] [neural_learning_core] - Neural Learning Core initialized
[2025-05-13 23:08:20] [INFO] [research_module] - Loaded valid research cache
[2025-05-13 23:08:20] [INFO] [research_module] - AlphaVox Research Module initialized
[2025-05-13 23:08:20] [INFO] [alphavox_input_nlu] - Loaded context window with 1 users
[2025-05-13 23:08:20] [INFO] [research_module] - Using cached research articles
[2025-05-13 23:08:20] [WARNING] [research_module] - No articles to analyze
[2025-05-13 23:08:20] [INFO] [neural_learning_core] - Loaded 1 interactions from memory
[2025-05-13 23:08:20] [INFO] [neural_learning_core] - Root cause model initialized
[2025-05-13 23:08:20] [INFO] [neural_learning_core] - Neural Learning Core initialized
[2025-05-13 23:08:20] [INFO] [research_module] - Integrated research insights into Neural Learning Core
[2025-05-13 23:08:20] [INFO] [research_module] - Integrated 0 strategies, 0 intents
[2025-05-13 23:08:20] [INFO] [alphavox_input_nlu] - Updated input processor with research insights
[2025-05-13 23:08:20] [INFO] [alphavox_input_nlu] - Saved context window for 1 users
[2025-05-13 23:08:20] [INFO] [alphavox_input_nlu] - AlphaVoxInputProcessor initialized
[2025-05-13 23:08:20] [ERROR] [alphavox_input_nlu] - Error processing interaction for user 1: sequence index must be integer, not 'slice'
Traceback (most recent call last):
  File "/home/runner/workspace/alphavox_input_nlu.py", line 105, in process_interaction
    interaction['context'] = self._add_context(interaction, user_id)
                             ^^^^^^^^^^^^^^^^^^^^^^^^^^^^^^^^^^^^^^^
  File "/home/runner/workspace/alphavox_input_nlu.py", line 293, in _add_context
    rc['root_cause'] for rc in self.context_window[user_id].get('root_causes', [])[-5:]
                               ~~~~~~~~~~~~~~~~~~~~~~~~~~~~~~~~~~~~~~~~~~~~~~~~~~~^^^^^
TypeError: sequence index must be integer, not 'slice'
[2025-05-13 23:08:20] [INFO] [root] - Processed gesture with AlphaVox NLU: 'open_palm' → unknown (0.00)
[2025-05-13 23:08:20] [INFO] [root] - Using voice: US Male (us_male)
[2025-05-13 23:08:20] [INFO] [root] - Generated speech with advanced TTS: f5059857c7890e1425f44994acad2de7.mp3
[2025-05-13 23:08:20] [ERROR] [root] - Error using AlphaVox NLU for gesture: 400 Bad Request: The browser (or proxy) sent a request that this server could not understand.
[2025-05-13 23:08:20] [ERROR] [root] - Traceback (most recent call last):
  File "/home/runner/workspace/.pythonlibs/lib/python3.11/site-packages/werkzeug/wrappers/request.py", line 611, in get_json
    rv = self.json_module.loads(data)
         ^^^^^^^^^^^^^^^^^^^^^^^^^^^^
  File "/home/runner/workspace/.pythonlibs/lib/python3.11/site-packages/flask/json/provider.py", line 187, in loads
    return json.loads(s, **kwargs)
           ^^^^^^^^^^^^^^^^^^^^^^^
  File "/nix/store/clx0mcir7qw8zk36zbr4jra789g3knf6-python3-3.11.10/lib/python3.11/json/__init__.py", line 346, in loads
    return _default_decoder.decode(s)
           ^^^^^^^^^^^^^^^^^^^^^^^^^^
  File "/nix/store/clx0mcir7qw8zk36zbr4jra789g3knf6-python3-3.11.10/lib/python3.11/json/decoder.py", line 337, in decode
    obj, end = self.raw_decode(s, idx=_w(s, 0).end())
               ^^^^^^^^^^^^^^^^^^^^^^^^^^^^^^^^^^^^^^
  File "/nix/store/clx0mcir7qw8zk36zbr4jra789g3knf6-python3-3.11.10/lib/python3.11/json/decoder.py", line 355, in raw_decode
    raise JSONDecodeError("Expecting value", s, err.value) from None
json.decoder.JSONDecodeError: Expecting value: line 1 column 1 (char 0)

During handling of the above exception, another exception occurred:

Traceback (most recent call last):
  File "/home/runner/workspace/.pythonlibs/lib/python3.11/site-packages/flask/wrappers.py", line 214, in on_json_loading_failed
    return super().on_json_loading_failed(e)
           ^^^^^^^^^^^^^^^^^^^^^^^^^^^^^^^^^
  File "/home/runner/workspace/.pythonlibs/lib/python3.11/site-packages/werkzeug/wrappers/request.py", line 645, in on_json_loading_failed
    raise BadRequest(f"Failed to decode JSON object: {e}")
werkzeug.exceptions.BadRequest: 400 Bad Request: Failed to decode JSON object: Expecting value: line 1 column 1 (char 0)

The above exception was the direct cause of the following exception:

Traceback (most recent call last):
  File "/home/runner/workspace/app.py", line 908, in speak
    data = request.json
           ^^^^^^^^^^^^
  File "/home/runner/workspace/.pythonlibs/lib/python3.11/site-packages/werkzeug/wrappers/request.py", line 560, in json
    return self.get_json()
           ^^^^^^^^^^^^^^^
  File "/home/runner/workspace/.pythonlibs/lib/python3.11/site-packages/werkzeug/wrappers/request.py", line 620, in get_json
    rv = self.on_json_loading_failed(e)
         ^^^^^^^^^^^^^^^^^^^^^^^^^^^^^^
  File "/home/runner/workspace/.pythonlibs/lib/python3.11/site-packages/flask/wrappers.py", line 219, in on_json_loading_failed
    raise BadRequest() from ebr
werkzeug.exceptions.BadRequest: 400 Bad Request: The browser (or proxy) sent a request that this server could not understand.

[2025-05-13 23:08:20] [INFO] [root] - Using voice: US Male (us_male)
[2025-05-13 23:08:20] [INFO] [root] - Generated speech with advanced TTS: 92ea85578df65f9c48a073affdea72b1.mp3
[2025-05-13 23:08:25] [ERROR] [alphavox_input_nlu] - Error processing interaction for user 1: sequence index must be integer, not 'slice'
Traceback (most recent call last):
  File "/home/runner/workspace/alphavox_input_nlu.py", line 105, in process_interaction
    interaction['context'] = self._add_context(interaction, user_id)
                             ^^^^^^^^^^^^^^^^^^^^^^^^^^^^^^^^^^^^^^^
  File "/home/runner/workspace/alphavox_input_nlu.py", line 293, in _add_context
    rc['root_cause'] for rc in self.context_window[user_id].get('root_causes', [])[-5:]
                               ~~~~~~~~~~~~~~~~~~~~~~~~~~~~~~~~~~~~~~~~~~~~~~~~~~~^^^^^
TypeError: sequence index must be integer, not 'slice'
[2025-05-13 23:08:25] [INFO] [root] - Processed gesture with AlphaVox NLU: 'open_palm' → unknown (0.00)
[2025-05-13 23:08:25] [INFO] [root] - Using voice: US Male (us_male)
[2025-05-13 23:08:25] [INFO] [root] - Generated speech with advanced TTS: f5059857c7890e1425f44994acad2de7.mp3
[2025-05-13 23:08:25] [ERROR] [root] - Error using AlphaVox NLU for gesture: 400 Bad Request: The browser (or proxy) sent a request that this server could not understand.
[2025-05-13 23:08:25] [ERROR] [root] - Traceback (most recent call last):
  File "/home/runner/workspace/.pythonlibs/lib/python3.11/site-packages/werkzeug/wrappers/request.py", line 611, in get_json
    rv = self.json_module.loads(data)
         ^^^^^^^^^^^^^^^^^^^^^^^^^^^^
  File "/home/runner/workspace/.pythonlibs/lib/python3.11/site-packages/flask/json/provider.py", line 187, in loads
    return json.loads(s, **kwargs)
           ^^^^^^^^^^^^^^^^^^^^^^^
  File "/nix/store/clx0mcir7qw8zk36zbr4jra789g3knf6-python3-3.11.10/lib/python3.11/json/__init__.py", line 346, in loads
    return _default_decoder.decode(s)
           ^^^^^^^^^^^^^^^^^^^^^^^^^^
  File "/nix/store/clx0mcir7qw8zk36zbr4jra789g3knf6-python3-3.11.10/lib/python3.11/json/decoder.py", line 337, in decode
    obj, end = self.raw_decode(s, idx=_w(s, 0).end())
               ^^^^^^^^^^^^^^^^^^^^^^^^^^^^^^^^^^^^^^
  File "/nix/store/clx0mcir7qw8zk36zbr4jra789g3knf6-python3-3.11.10/lib/python3.11/json/decoder.py", line 355, in raw_decode
    raise JSONDecodeError("Expecting value", s, err.value) from None
json.decoder.JSONDecodeError: Expecting value: line 1 column 1 (char 0)

During handling of the above exception, another exception occurred:

Traceback (most recent call last):
  File "/home/runner/workspace/.pythonlibs/lib/python3.11/site-packages/flask/wrappers.py", line 214, in on_json_loading_failed
    return super().on_json_loading_failed(e)
           ^^^^^^^^^^^^^^^^^^^^^^^^^^^^^^^^^
  File "/home/runner/workspace/.pythonlibs/lib/python3.11/site-packages/werkzeug/wrappers/request.py", line 645, in on_json_loading_failed
    raise BadRequest(f"Failed to decode JSON object: {e}")
werkzeug.exceptions.BadRequest: 400 Bad Request: Failed to decode JSON object: Expecting value: line 1 column 1 (char 0)

The above exception was the direct cause of the following exception:

Traceback (most recent call last):
  File "/home/runner/workspace/app.py", line 908, in speak
    data = request.json
           ^^^^^^^^^^^^
  File "/home/runner/workspace/.pythonlibs/lib/python3.11/site-packages/werkzeug/wrappers/request.py", line 560, in json
    return self.get_json()
           ^^^^^^^^^^^^^^^
  File "/home/runner/workspace/.pythonlibs/lib/python3.11/site-packages/werkzeug/wrappers/request.py", line 620, in get_json
    rv = self.on_json_loading_failed(e)
         ^^^^^^^^^^^^^^^^^^^^^^^^^^^^^^
  File "/home/runner/workspace/.pythonlibs/lib/python3.11/site-packages/flask/wrappers.py", line 219, in on_json_loading_failed
    raise BadRequest() from ebr
werkzeug.exceptions.BadRequest: 400 Bad Request: The browser (or proxy) sent a request that this server could not understand.

[2025-05-13 23:08:25] [INFO] [root] - Using voice: US Male (us_male)
[2025-05-13 23:08:25] [INFO] [root] - Generated speech with advanced TTS: 92ea85578df65f9c48a073affdea72b1.mp3
[2025-05-13 23:08:39] [ERROR] [alphavox_input_nlu] - Error processing interaction for user 1: sequence index must be integer, not 'slice'
Traceback (most recent call last):
  File "/home/runner/workspace/alphavox_input_nlu.py", line 105, in process_interaction
    interaction['context'] = self._add_context(interaction, user_id)
                             ^^^^^^^^^^^^^^^^^^^^^^^^^^^^^^^^^^^^^^^
  File "/home/runner/workspace/alphavox_input_nlu.py", line 293, in _add_context
    rc['root_cause'] for rc in self.context_window[user_id].get('root_causes', [])[-5:]
                               ~~~~~~~~~~~~~~~~~~~~~~~~~~~~~~~~~~~~~~~~~~~~~~~~~~~^^^^^
TypeError: sequence index must be integer, not 'slice'
[2025-05-13 23:08:39] [INFO] [root] - Processed gesture with AlphaVox NLU: 'thumbs_up' → unknown (0.00)
[2025-05-13 23:08:39] [INFO] [root] - Using voice: US Male (us_male)
[2025-05-13 23:08:39] [INFO] [root] - Generated speech with advanced TTS: 0397cb22afd890add2438505f2346cc7.mp3
[2025-05-13 23:08:39] [ERROR] [root] - Error using AlphaVox NLU for gesture: 400 Bad Request: The browser (or proxy) sent a request that this server could not understand.
[2025-05-13 23:08:39] [ERROR] [root] - Traceback (most recent call last):
  File "/home/runner/workspace/.pythonlibs/lib/python3.11/site-packages/werkzeug/wrappers/request.py", line 611, in get_json
    rv = self.json_module.loads(data)
         ^^^^^^^^^^^^^^^^^^^^^^^^^^^^
  File "/home/runner/workspace/.pythonlibs/lib/python3.11/site-packages/flask/json/provider.py", line 187, in loads
    return json.loads(s, **kwargs)
           ^^^^^^^^^^^^^^^^^^^^^^^
  File "/nix/store/clx0mcir7qw8zk36zbr4jra789g3knf6-python3-3.11.10/lib/python3.11/json/__init__.py", line 346, in loads
    return _default_decoder.decode(s)
           ^^^^^^^^^^^^^^^^^^^^^^^^^^
  File "/nix/store/clx0mcir7qw8zk36zbr4jra789g3knf6-python3-3.11.10/lib/python3.11/json/decoder.py", line 337, in decode
    obj, end = self.raw_decode(s, idx=_w(s, 0).end())
               ^^^^^^^^^^^^^^^^^^^^^^^^^^^^^^^^^^^^^^
  File "/nix/store/clx0mcir7qw8zk36zbr4jra789g3knf6-python3-3.11.10/lib/python3.11/json/decoder.py", line 355, in raw_decode
    raise JSONDecodeError("Expecting value", s, err.value) from None
json.decoder.JSONDecodeError: Expecting value: line 1 column 1 (char 0)

During handling of the above exception, another exception occurred:

Traceback (most recent call last):
  File "/home/runner/workspace/.pythonlibs/lib/python3.11/site-packages/flask/wrappers.py", line 214, in on_json_loading_failed
    return super().on_json_loading_failed(e)
           ^^^^^^^^^^^^^^^^^^^^^^^^^^^^^^^^^
  File "/home/runner/workspace/.pythonlibs/lib/python3.11/site-packages/werkzeug/wrappers/request.py", line 645, in on_json_loading_failed
    raise BadRequest(f"Failed to decode JSON object: {e}")
werkzeug.exceptions.BadRequest: 400 Bad Request: Failed to decode JSON object: Expecting value: line 1 column 1 (char 0)

The above exception was the direct cause of the following exception:

Traceback (most recent call last):
  File "/home/runner/workspace/app.py", line 908, in speak
    data = request.json
           ^^^^^^^^^^^^
  File "/home/runner/workspace/.pythonlibs/lib/python3.11/site-packages/werkzeug/wrappers/request.py", line 560, in json
    return self.get_json()
           ^^^^^^^^^^^^^^^
  File "/home/runner/workspace/.pythonlibs/lib/python3.11/site-packages/werkzeug/wrappers/request.py", line 620, in get_json
    rv = self.on_json_loading_failed(e)
         ^^^^^^^^^^^^^^^^^^^^^^^^^^^^^^
  File "/home/runner/workspace/.pythonlibs/lib/python3.11/site-packages/flask/wrappers.py", line 219, in on_json_loading_failed
    raise BadRequest() from ebr
werkzeug.exceptions.BadRequest: 400 Bad Request: The browser (or proxy) sent a request that this server could not understand.

[2025-05-13 23:08:39] [INFO] [root] - Using voice: US Male (us_male)
[2025-05-13 23:08:39] [INFO] [root] - Generated speech with advanced TTS: d028fbe058f5cbd7a8708ba923fa3098.mp3
[2025-05-13 23:42:20] [ERROR] [root] - Error using AlphaVox NLU for gesture: 400 Bad Request: The browser (or proxy) sent a request that this server could not understand.
[2025-05-13 23:42:20] [ERROR] [root] - Traceback (most recent call last):
  File "/home/runner/workspace/.pythonlibs/lib/python3.11/site-packages/werkzeug/wrappers/request.py", line 611, in get_json
    rv = self.json_module.loads(data)
         ^^^^^^^^^^^^^^^^^^^^^^^^^^^^
  File "/home/runner/workspace/.pythonlibs/lib/python3.11/site-packages/flask/json/provider.py", line 187, in loads
    return json.loads(s, **kwargs)
           ^^^^^^^^^^^^^^^^^^^^^^^
  File "/nix/store/clx0mcir7qw8zk36zbr4jra789g3knf6-python3-3.11.10/lib/python3.11/json/__init__.py", line 346, in loads
    return _default_decoder.decode(s)
           ^^^^^^^^^^^^^^^^^^^^^^^^^^
  File "/nix/store/clx0mcir7qw8zk36zbr4jra789g3knf6-python3-3.11.10/lib/python3.11/json/decoder.py", line 337, in decode
    obj, end = self.raw_decode(s, idx=_w(s, 0).end())
               ^^^^^^^^^^^^^^^^^^^^^^^^^^^^^^^^^^^^^^
  File "/nix/store/clx0mcir7qw8zk36zbr4jra789g3knf6-python3-3.11.10/lib/python3.11/json/decoder.py", line 355, in raw_decode
    raise JSONDecodeError("Expecting value", s, err.value) from None
json.decoder.JSONDecodeError: Expecting value: line 1 column 1 (char 0)

During handling of the above exception, another exception occurred:

Traceback (most recent call last):
  File "/home/runner/workspace/.pythonlibs/lib/python3.11/site-packages/flask/wrappers.py", line 214, in on_json_loading_failed
    return super().on_json_loading_failed(e)
           ^^^^^^^^^^^^^^^^^^^^^^^^^^^^^^^^^
  File "/home/runner/workspace/.pythonlibs/lib/python3.11/site-packages/werkzeug/wrappers/request.py", line 645, in on_json_loading_failed
    raise BadRequest(f"Failed to decode JSON object: {e}")
werkzeug.exceptions.BadRequest: 400 Bad Request: Failed to decode JSON object: Expecting value: line 1 column 1 (char 0)

The above exception was the direct cause of the following exception:

Traceback (most recent call last):
  File "/home/runner/workspace/app.py", line 908, in speak
    data = request.json
           ^^^^^^^^^^^^
  File "/home/runner/workspace/.pythonlibs/lib/python3.11/site-packages/werkzeug/wrappers/request.py", line 560, in json
    return self.get_json()
           ^^^^^^^^^^^^^^^
  File "/home/runner/workspace/.pythonlibs/lib/python3.11/site-packages/werkzeug/wrappers/request.py", line 620, in get_json
    rv = self.on_json_loading_failed(e)
         ^^^^^^^^^^^^^^^^^^^^^^^^^^^^^^
  File "/home/runner/workspace/.pythonlibs/lib/python3.11/site-packages/flask/wrappers.py", line 219, in on_json_loading_failed
    raise BadRequest() from ebr
werkzeug.exceptions.BadRequest: 400 Bad Request: The browser (or proxy) sent a request that this server could not understand.

[2025-05-13 23:42:20] [INFO] [root] - Using voice: US Male (us_male)
[2025-05-13 23:42:20] [INFO] [root] - Generated speech with advanced TTS: 94ad3b543c95daee980e2dc1427206a6.mp3
[2025-05-13 23:42:20] [ERROR] [alphavox_input_nlu] - Error processing interaction for user 1: sequence index must be integer, not 'slice'
Traceback (most recent call last):
  File "/home/runner/workspace/alphavox_input_nlu.py", line 105, in process_interaction
    interaction['context'] = self._add_context(interaction, user_id)
                             ^^^^^^^^^^^^^^^^^^^^^^^^^^^^^^^^^^^^^^^
  File "/home/runner/workspace/alphavox_input_nlu.py", line 293, in _add_context
    rc['root_cause'] for rc in self.context_window[user_id].get('root_causes', [])[-5:]
                               ~~~~~~~~~~~~~~~~~~~~~~~~~~~~~~~~~~~~~~~~~~~~~~~~~~~^^^^^
TypeError: sequence index must be integer, not 'slice'
[2025-05-13 23:42:20] [INFO] [root] - Processed gesture with AlphaVox NLU: 'nod' → unknown (0.00)
[2025-05-13 23:42:20] [INFO] [root] - Using voice: US Male (us_male)
[2025-05-13 23:42:20] [INFO] [root] - Generated speech with advanced TTS: aaaf28040d070cff5aae5a0baa9ca965.mp3
[2025-05-13 23:42:25] [ERROR] [alphavox_input_nlu] - Error processing interaction for user 1: sequence index must be integer, not 'slice'
Traceback (most recent call last):
  File "/home/runner/workspace/alphavox_input_nlu.py", line 105, in process_interaction
    interaction['context'] = self._add_context(interaction, user_id)
                             ^^^^^^^^^^^^^^^^^^^^^^^^^^^^^^^^^^^^^^^
  File "/home/runner/workspace/alphavox_input_nlu.py", line 293, in _add_context
    rc['root_cause'] for rc in self.context_window[user_id].get('root_causes', [])[-5:]
                               ~~~~~~~~~~~~~~~~~~~~~~~~~~~~~~~~~~~~~~~~~~~~~~~~~~~^^^^^
TypeError: sequence index must be integer, not 'slice'
[2025-05-13 23:42:25] [INFO] [root] - Processed gesture with AlphaVox NLU: 'nod' → unknown (0.00)
[2025-05-13 23:42:25] [INFO] [root] - Using voice: US Male (us_male)
[2025-05-13 23:42:25] [INFO] [root] - Generated speech with advanced TTS: aaaf28040d070cff5aae5a0baa9ca965.mp3
[2025-05-13 23:42:25] [ERROR] [root] - Error using AlphaVox NLU for gesture: 400 Bad Request: The browser (or proxy) sent a request that this server could not understand.
[2025-05-13 23:42:25] [ERROR] [root] - Traceback (most recent call last):
  File "/home/runner/workspace/.pythonlibs/lib/python3.11/site-packages/werkzeug/wrappers/request.py", line 611, in get_json
    rv = self.json_module.loads(data)
         ^^^^^^^^^^^^^^^^^^^^^^^^^^^^
  File "/home/runner/workspace/.pythonlibs/lib/python3.11/site-packages/flask/json/provider.py", line 187, in loads
    return json.loads(s, **kwargs)
           ^^^^^^^^^^^^^^^^^^^^^^^
  File "/nix/store/clx0mcir7qw8zk36zbr4jra789g3knf6-python3-3.11.10/lib/python3.11/json/__init__.py", line 346, in loads
    return _default_decoder.decode(s)
           ^^^^^^^^^^^^^^^^^^^^^^^^^^
  File "/nix/store/clx0mcir7qw8zk36zbr4jra789g3knf6-python3-3.11.10/lib/python3.11/json/decoder.py", line 337, in decode
    obj, end = self.raw_decode(s, idx=_w(s, 0).end())
               ^^^^^^^^^^^^^^^^^^^^^^^^^^^^^^^^^^^^^^
  File "/nix/store/clx0mcir7qw8zk36zbr4jra789g3knf6-python3-3.11.10/lib/python3.11/json/decoder.py", line 355, in raw_decode
    raise JSONDecodeError("Expecting value", s, err.value) from None
json.decoder.JSONDecodeError: Expecting value: line 1 column 1 (char 0)

During handling of the above exception, another exception occurred:

Traceback (most recent call last):
  File "/home/runner/workspace/.pythonlibs/lib/python3.11/site-packages/flask/wrappers.py", line 214, in on_json_loading_failed
    return super().on_json_loading_failed(e)
           ^^^^^^^^^^^^^^^^^^^^^^^^^^^^^^^^^
  File "/home/runner/workspace/.pythonlibs/lib/python3.11/site-packages/werkzeug/wrappers/request.py", line 645, in on_json_loading_failed
    raise BadRequest(f"Failed to decode JSON object: {e}")
werkzeug.exceptions.BadRequest: 400 Bad Request: Failed to decode JSON object: Expecting value: line 1 column 1 (char 0)

The above exception was the direct cause of the following exception:

Traceback (most recent call last):
  File "/home/runner/workspace/app.py", line 908, in speak
    data = request.json
           ^^^^^^^^^^^^
  File "/home/runner/workspace/.pythonlibs/lib/python3.11/site-packages/werkzeug/wrappers/request.py", line 560, in json
    return self.get_json()
           ^^^^^^^^^^^^^^^
  File "/home/runner/workspace/.pythonlibs/lib/python3.11/site-packages/werkzeug/wrappers/request.py", line 620, in get_json
    rv = self.on_json_loading_failed(e)
         ^^^^^^^^^^^^^^^^^^^^^^^^^^^^^^
  File "/home/runner/workspace/.pythonlibs/lib/python3.11/site-packages/flask/wrappers.py", line 219, in on_json_loading_failed
    raise BadRequest() from ebr
werkzeug.exceptions.BadRequest: 400 Bad Request: The browser (or proxy) sent a request that this server could not understand.

[2025-05-13 23:42:25] [INFO] [root] - Using voice: US Male (us_male)
[2025-05-13 23:42:25] [INFO] [root] - Generated speech with advanced TTS: 94ad3b543c95daee980e2dc1427206a6.mp3
[2025-05-13 23:43:04] [ERROR] [alphavox_input_nlu] - Error processing interaction for user 1: sequence index must be integer, not 'slice'
Traceback (most recent call last):
  File "/home/runner/workspace/alphavox_input_nlu.py", line 105, in process_interaction
    interaction['context'] = self._add_context(interaction, user_id)
                             ^^^^^^^^^^^^^^^^^^^^^^^^^^^^^^^^^^^^^^^
  File "/home/runner/workspace/alphavox_input_nlu.py", line 293, in _add_context
    rc['root_cause'] for rc in self.context_window[user_id].get('root_causes', [])[-5:]
                               ~~~~~~~~~~~~~~~~~~~~~~~~~~~~~~~~~~~~~~~~~~~~~~~~~~~^^^^^
TypeError: sequence index must be integer, not 'slice'
[2025-05-13 23:43:04] [INFO] [root] - Processed gesture with AlphaVox NLU: 'nod' → unknown (0.00)
[2025-05-13 23:43:04] [INFO] [root] - Using voice: US Male (us_male)
[2025-05-13 23:43:04] [INFO] [root] - Generated speech with advanced TTS: aaaf28040d070cff5aae5a0baa9ca965.mp3
[2025-05-13 23:43:04] [ERROR] [root] - Error using AlphaVox NLU for gesture: 400 Bad Request: The browser (or proxy) sent a request that this server could not understand.
[2025-05-13 23:43:04] [ERROR] [root] - Traceback (most recent call last):
  File "/home/runner/workspace/.pythonlibs/lib/python3.11/site-packages/werkzeug/wrappers/request.py", line 611, in get_json
    rv = self.json_module.loads(data)
         ^^^^^^^^^^^^^^^^^^^^^^^^^^^^
  File "/home/runner/workspace/.pythonlibs/lib/python3.11/site-packages/flask/json/provider.py", line 187, in loads
    return json.loads(s, **kwargs)
           ^^^^^^^^^^^^^^^^^^^^^^^
  File "/nix/store/clx0mcir7qw8zk36zbr4jra789g3knf6-python3-3.11.10/lib/python3.11/json/__init__.py", line 346, in loads
    return _default_decoder.decode(s)
           ^^^^^^^^^^^^^^^^^^^^^^^^^^
  File "/nix/store/clx0mcir7qw8zk36zbr4jra789g3knf6-python3-3.11.10/lib/python3.11/json/decoder.py", line 337, in decode
    obj, end = self.raw_decode(s, idx=_w(s, 0).end())
               ^^^^^^^^^^^^^^^^^^^^^^^^^^^^^^^^^^^^^^
  File "/nix/store/clx0mcir7qw8zk36zbr4jra789g3knf6-python3-3.11.10/lib/python3.11/json/decoder.py", line 355, in raw_decode
    raise JSONDecodeError("Expecting value", s, err.value) from None
json.decoder.JSONDecodeError: Expecting value: line 1 column 1 (char 0)

During handling of the above exception, another exception occurred:

Traceback (most recent call last):
  File "/home/runner/workspace/.pythonlibs/lib/python3.11/site-packages/flask/wrappers.py", line 214, in on_json_loading_failed
    return super().on_json_loading_failed(e)
           ^^^^^^^^^^^^^^^^^^^^^^^^^^^^^^^^^
  File "/home/runner/workspace/.pythonlibs/lib/python3.11/site-packages/werkzeug/wrappers/request.py", line 645, in on_json_loading_failed
    raise BadRequest(f"Failed to decode JSON object: {e}")
werkzeug.exceptions.BadRequest: 400 Bad Request: Failed to decode JSON object: Expecting value: line 1 column 1 (char 0)

The above exception was the direct cause of the following exception:

Traceback (most recent call last):
  File "/home/runner/workspace/app.py", line 908, in speak
    data = request.json
           ^^^^^^^^^^^^
  File "/home/runner/workspace/.pythonlibs/lib/python3.11/site-packages/werkzeug/wrappers/request.py", line 560, in json
    return self.get_json()
           ^^^^^^^^^^^^^^^
  File "/home/runner/workspace/.pythonlibs/lib/python3.11/site-packages/werkzeug/wrappers/request.py", line 620, in get_json
    rv = self.on_json_loading_failed(e)
         ^^^^^^^^^^^^^^^^^^^^^^^^^^^^^^
  File "/home/runner/workspace/.pythonlibs/lib/python3.11/site-packages/flask/wrappers.py", line 219, in on_json_loading_failed
    raise BadRequest() from ebr
werkzeug.exceptions.BadRequest: 400 Bad Request: The browser (or proxy) sent a request that this server could not understand.

[2025-05-13 23:43:04] [INFO] [root] - Using voice: US Male (us_male)
[2025-05-13 23:43:04] [INFO] [root] - Generated speech with advanced TTS: 94ad3b543c95daee980e2dc1427206a6.mp3
[2025-05-13 23:44:34] [ERROR] [root] - Error using AlphaVox NLU for gesture: 400 Bad Request: The browser (or proxy) sent a request that this server could not understand.
[2025-05-13 23:44:34] [ERROR] [root] - Traceback (most recent call last):
  File "/home/runner/workspace/.pythonlibs/lib/python3.11/site-packages/werkzeug/wrappers/request.py", line 611, in get_json
    rv = self.json_module.loads(data)
         ^^^^^^^^^^^^^^^^^^^^^^^^^^^^
  File "/home/runner/workspace/.pythonlibs/lib/python3.11/site-packages/flask/json/provider.py", line 187, in loads
    return json.loads(s, **kwargs)
           ^^^^^^^^^^^^^^^^^^^^^^^
  File "/nix/store/clx0mcir7qw8zk36zbr4jra789g3knf6-python3-3.11.10/lib/python3.11/json/__init__.py", line 346, in loads
    return _default_decoder.decode(s)
           ^^^^^^^^^^^^^^^^^^^^^^^^^^
  File "/nix/store/clx0mcir7qw8zk36zbr4jra789g3knf6-python3-3.11.10/lib/python3.11/json/decoder.py", line 337, in decode
    obj, end = self.raw_decode(s, idx=_w(s, 0).end())
               ^^^^^^^^^^^^^^^^^^^^^^^^^^^^^^^^^^^^^^
  File "/nix/store/clx0mcir7qw8zk36zbr4jra789g3knf6-python3-3.11.10/lib/python3.11/json/decoder.py", line 355, in raw_decode
    raise JSONDecodeError("Expecting value", s, err.value) from None
json.decoder.JSONDecodeError: Expecting value: line 1 column 1 (char 0)

During handling of the above exception, another exception occurred:

Traceback (most recent call last):
  File "/home/runner/workspace/.pythonlibs/lib/python3.11/site-packages/flask/wrappers.py", line 214, in on_json_loading_failed
    return super().on_json_loading_failed(e)
           ^^^^^^^^^^^^^^^^^^^^^^^^^^^^^^^^^
  File "/home/runner/workspace/.pythonlibs/lib/python3.11/site-packages/werkzeug/wrappers/request.py", line 645, in on_json_loading_failed
    raise BadRequest(f"Failed to decode JSON object: {e}")
werkzeug.exceptions.BadRequest: 400 Bad Request: Failed to decode JSON object: Expecting value: line 1 column 1 (char 0)

The above exception was the direct cause of the following exception:

Traceback (most recent call last):
  File "/home/runner/workspace/app.py", line 908, in speak
    data = request.json
           ^^^^^^^^^^^^
  File "/home/runner/workspace/.pythonlibs/lib/python3.11/site-packages/werkzeug/wrappers/request.py", line 560, in json
    return self.get_json()
           ^^^^^^^^^^^^^^^
  File "/home/runner/workspace/.pythonlibs/lib/python3.11/site-packages/werkzeug/wrappers/request.py", line 620, in get_json
    rv = self.on_json_loading_failed(e)
         ^^^^^^^^^^^^^^^^^^^^^^^^^^^^^^
  File "/home/runner/workspace/.pythonlibs/lib/python3.11/site-packages/flask/wrappers.py", line 219, in on_json_loading_failed
    raise BadRequest() from ebr
werkzeug.exceptions.BadRequest: 400 Bad Request: The browser (or proxy) sent a request that this server could not understand.

[2025-05-13 23:44:34] [INFO] [root] - Using voice: US Male (us_male)
[2025-05-13 23:44:34] [INFO] [root] - Generated speech with advanced TTS: 95442782f93e1edd95d9cf04005a67ea.mp3
[2025-05-13 23:44:34] [ERROR] [alphavox_input_nlu] - Error processing interaction for user 1: sequence index must be integer, not 'slice'
Traceback (most recent call last):
  File "/home/runner/workspace/alphavox_input_nlu.py", line 105, in process_interaction
    interaction['context'] = self._add_context(interaction, user_id)
                             ^^^^^^^^^^^^^^^^^^^^^^^^^^^^^^^^^^^^^^^
  File "/home/runner/workspace/alphavox_input_nlu.py", line 293, in _add_context
    rc['root_cause'] for rc in self.context_window[user_id].get('root_causes', [])[-5:]
                               ~~~~~~~~~~~~~~~~~~~~~~~~~~~~~~~~~~~~~~~~~~~~~~~~~~~^^^^^
TypeError: sequence index must be integer, not 'slice'
[2025-05-13 23:44:34] [INFO] [root] - Processed gesture with AlphaVox NLU: 'shake' → unknown (0.00)
[2025-05-13 23:44:34] [INFO] [root] - Using voice: US Male (us_male)
[2025-05-13 23:44:34] [INFO] [root] - Generated speech with advanced TTS: 61eb73c1051b39fc1f1a5946c126ff08.mp3
[2025-05-13 23:46:24] [INFO] [root] - Default logging configuration applied
[2025-05-13 23:46:24] [INFO] [adaptive_conversation] - Conversation Complexity Engine initialized
[2025-05-13 23:46:24] [INFO] [routes.adaptive_conversation_routes] - Adaptive conversation routes registered
[2025-05-13 23:46:24] [INFO] [routes.learning_routes] - Learning routes registered
[2025-05-13 23:46:24] [INFO] [routes.health_routes] - Health routes registered
[2025-05-13 23:46:24] [INFO] [main] - AlphaVox application initialized
[2025-05-13 23:46:25] [INFO] [root] - Using voice: US Male (us_male)
[2025-05-13 23:46:25] [INFO] [root] - Generated speech with advanced TTS: 2e565dc8de98e0705a86dd0c1641289b.mp3
[2025-05-13 23:46:25] [INFO] [root] - Speaking greeting: Good evening! Welcome back, Ev...
[2025-05-13 23:46:26] [INFO] [root] - Using voice: US Male (us_male)
[2025-05-13 23:46:26] [INFO] [root] - Generated speech with advanced TTS: 2e565dc8de98e0705a86dd0c1641289b.mp3
[2025-05-13 23:46:26] [INFO] [root] - Speaking greeting: Good evening! Welcome back, Ev...
[2025-05-13 23:46:33] [ERROR] [neural_learning_core] - Failed to load spaCy model: [E050] Can't find model 'en_core_web_sm'. It doesn't seem to be a Python package or a valid path to a data directory.
[2025-05-13 23:46:33] [INFO] [neural_learning_core] - Creating a basic spaCy model as fallback
[2025-05-13 23:46:33] [ERROR] [research_module] - Failed to load spaCy model: [E050] Can't find model 'en_core_web_sm'. It doesn't seem to be a Python package or a valid path to a data directory.
[2025-05-13 23:46:33] [INFO] [research_module] - Install spaCy and download model: pip install spacy && python -m spacy download en_core_web_sm
[2025-05-13 23:46:33] [ERROR] [alphavox_input_nlu] - Failed to load spaCy model: [E050] Can't find model 'en_core_web_sm'. It doesn't seem to be a Python package or a valid path to a data directory.
[2025-05-13 23:46:33] [INFO] [alphavox_input_nlu] - Install spaCy and download model: pip install spacy && python -m spacy download en_core_web_sm
[2025-05-13 23:46:33] [INFO] [neural_learning_core] - Loaded 1 interactions from memory
[2025-05-13 23:46:33] [INFO] [neural_learning_core] - Root cause model initialized
[2025-05-13 23:46:33] [INFO] [neural_learning_core] - Neural Learning Core initialized
[2025-05-13 23:46:33] [INFO] [research_module] - Loaded valid research cache
[2025-05-13 23:46:33] [INFO] [research_module] - AlphaVox Research Module initialized
[2025-05-13 23:46:33] [INFO] [alphavox_input_nlu] - Loaded context window with 1 users
[2025-05-13 23:46:33] [INFO] [research_module] - Using cached research articles
[2025-05-13 23:46:33] [WARNING] [research_module] - No articles to analyze
[2025-05-13 23:46:33] [INFO] [neural_learning_core] - Loaded 1 interactions from memory
[2025-05-13 23:46:33] [INFO] [neural_learning_core] - Root cause model initialized
[2025-05-13 23:46:33] [INFO] [neural_learning_core] - Neural Learning Core initialized
[2025-05-13 23:46:33] [INFO] [research_module] - Integrated research insights into Neural Learning Core
[2025-05-13 23:46:33] [INFO] [research_module] - Integrated 0 strategies, 0 intents
[2025-05-13 23:46:33] [INFO] [alphavox_input_nlu] - Updated input processor with research insights
[2025-05-13 23:46:33] [INFO] [alphavox_input_nlu] - Saved context window for 1 users
[2025-05-13 23:46:33] [INFO] [alphavox_input_nlu] - AlphaVoxInputProcessor initialized
[2025-05-13 23:46:33] [ERROR] [alphavox_input_nlu] - Error processing interaction for user 1: sequence index must be integer, not 'slice'
Traceback (most recent call last):
  File "/home/runner/workspace/alphavox_input_nlu.py", line 105, in process_interaction
    interaction['context'] = self._add_context(interaction, user_id)
                             ^^^^^^^^^^^^^^^^^^^^^^^^^^^^^^^^^^^^^^^
  File "/home/runner/workspace/alphavox_input_nlu.py", line 293, in _add_context
    rc['root_cause'] for rc in self.context_window[user_id].get('root_causes', [])[-5:]
                               ~~~~~~~~~~~~~~~~~~~~~~~~~~~~~~~~~~~~~~~~~~~~~~~~~~~^^^^^
TypeError: sequence index must be integer, not 'slice'
[2025-05-13 23:46:33] [INFO] [root] - Processed gesture with AlphaVox NLU: 'nod' → unknown (0.00)
[2025-05-13 23:46:33] [INFO] [root] - Using voice: US Male (us_male)
[2025-05-13 23:46:33] [INFO] [root] - Generated speech with advanced TTS: aaaf28040d070cff5aae5a0baa9ca965.mp3
[2025-05-13 23:46:33] [ERROR] [root] - Error using AlphaVox NLU for gesture: 400 Bad Request: The browser (or proxy) sent a request that this server could not understand.
[2025-05-13 23:46:33] [ERROR] [root] - Traceback (most recent call last):
  File "/home/runner/workspace/.pythonlibs/lib/python3.11/site-packages/werkzeug/wrappers/request.py", line 611, in get_json
    rv = self.json_module.loads(data)
         ^^^^^^^^^^^^^^^^^^^^^^^^^^^^
  File "/home/runner/workspace/.pythonlibs/lib/python3.11/site-packages/flask/json/provider.py", line 187, in loads
    return json.loads(s, **kwargs)
           ^^^^^^^^^^^^^^^^^^^^^^^
  File "/nix/store/clx0mcir7qw8zk36zbr4jra789g3knf6-python3-3.11.10/lib/python3.11/json/__init__.py", line 346, in loads
    return _default_decoder.decode(s)
           ^^^^^^^^^^^^^^^^^^^^^^^^^^
  File "/nix/store/clx0mcir7qw8zk36zbr4jra789g3knf6-python3-3.11.10/lib/python3.11/json/decoder.py", line 337, in decode
    obj, end = self.raw_decode(s, idx=_w(s, 0).end())
               ^^^^^^^^^^^^^^^^^^^^^^^^^^^^^^^^^^^^^^
  File "/nix/store/clx0mcir7qw8zk36zbr4jra789g3knf6-python3-3.11.10/lib/python3.11/json/decoder.py", line 355, in raw_decode
    raise JSONDecodeError("Expecting value", s, err.value) from None
json.decoder.JSONDecodeError: Expecting value: line 1 column 1 (char 0)

During handling of the above exception, another exception occurred:

Traceback (most recent call last):
  File "/home/runner/workspace/.pythonlibs/lib/python3.11/site-packages/flask/wrappers.py", line 214, in on_json_loading_failed
    return super().on_json_loading_failed(e)
           ^^^^^^^^^^^^^^^^^^^^^^^^^^^^^^^^^
  File "/home/runner/workspace/.pythonlibs/lib/python3.11/site-packages/werkzeug/wrappers/request.py", line 645, in on_json_loading_failed
    raise BadRequest(f"Failed to decode JSON object: {e}")
werkzeug.exceptions.BadRequest: 400 Bad Request: Failed to decode JSON object: Expecting value: line 1 column 1 (char 0)

The above exception was the direct cause of the following exception:

Traceback (most recent call last):
  File "/home/runner/workspace/app.py", line 908, in speak
    data = request.json
           ^^^^^^^^^^^^
  File "/home/runner/workspace/.pythonlibs/lib/python3.11/site-packages/werkzeug/wrappers/request.py", line 560, in json
    return self.get_json()
           ^^^^^^^^^^^^^^^
  File "/home/runner/workspace/.pythonlibs/lib/python3.11/site-packages/werkzeug/wrappers/request.py", line 620, in get_json
    rv = self.on_json_loading_failed(e)
         ^^^^^^^^^^^^^^^^^^^^^^^^^^^^^^
  File "/home/runner/workspace/.pythonlibs/lib/python3.11/site-packages/flask/wrappers.py", line 219, in on_json_loading_failed
    raise BadRequest() from ebr
werkzeug.exceptions.BadRequest: 400 Bad Request: The browser (or proxy) sent a request that this server could not understand.

[2025-05-13 23:46:33] [INFO] [root] - Using voice: US Male (us_male)
[2025-05-13 23:46:33] [INFO] [root] - Generated speech with advanced TTS: 94ad3b543c95daee980e2dc1427206a6.mp3
[2025-05-13 23:46:57] [ERROR] [alphavox_input_nlu] - Error processing interaction for user 1: sequence index must be integer, not 'slice'
Traceback (most recent call last):
  File "/home/runner/workspace/alphavox_input_nlu.py", line 105, in process_interaction
    interaction['context'] = self._add_context(interaction, user_id)
                             ^^^^^^^^^^^^^^^^^^^^^^^^^^^^^^^^^^^^^^^
  File "/home/runner/workspace/alphavox_input_nlu.py", line 293, in _add_context
    rc['root_cause'] for rc in self.context_window[user_id].get('root_causes', [])[-5:]
                               ~~~~~~~~~~~~~~~~~~~~~~~~~~~~~~~~~~~~~~~~~~~~~~~~~~~^^^^^
TypeError: sequence index must be integer, not 'slice'
[2025-05-13 23:46:57] [INFO] [root] - Processed gesture with AlphaVox NLU: 'nod' → unknown (0.00)
[2025-05-13 23:46:57] [INFO] [root] - Using voice: US Male (us_male)
[2025-05-13 23:46:57] [INFO] [root] - Generated speech with advanced TTS: aaaf28040d070cff5aae5a0baa9ca965.mp3
[2025-05-13 23:46:57] [ERROR] [root] - Error using AlphaVox NLU for gesture: 400 Bad Request: The browser (or proxy) sent a request that this server could not understand.
[2025-05-13 23:46:57] [ERROR] [root] - Traceback (most recent call last):
  File "/home/runner/workspace/.pythonlibs/lib/python3.11/site-packages/werkzeug/wrappers/request.py", line 611, in get_json
    rv = self.json_module.loads(data)
         ^^^^^^^^^^^^^^^^^^^^^^^^^^^^
  File "/home/runner/workspace/.pythonlibs/lib/python3.11/site-packages/flask/json/provider.py", line 187, in loads
    return json.loads(s, **kwargs)
           ^^^^^^^^^^^^^^^^^^^^^^^
  File "/nix/store/clx0mcir7qw8zk36zbr4jra789g3knf6-python3-3.11.10/lib/python3.11/json/__init__.py", line 346, in loads
    return _default_decoder.decode(s)
           ^^^^^^^^^^^^^^^^^^^^^^^^^^
  File "/nix/store/clx0mcir7qw8zk36zbr4jra789g3knf6-python3-3.11.10/lib/python3.11/json/decoder.py", line 337, in decode
    obj, end = self.raw_decode(s, idx=_w(s, 0).end())
               ^^^^^^^^^^^^^^^^^^^^^^^^^^^^^^^^^^^^^^
  File "/nix/store/clx0mcir7qw8zk36zbr4jra789g3knf6-python3-3.11.10/lib/python3.11/json/decoder.py", line 355, in raw_decode
    raise JSONDecodeError("Expecting value", s, err.value) from None
json.decoder.JSONDecodeError: Expecting value: line 1 column 1 (char 0)

During handling of the above exception, another exception occurred:

Traceback (most recent call last):
  File "/home/runner/workspace/.pythonlibs/lib/python3.11/site-packages/flask/wrappers.py", line 214, in on_json_loading_failed
    return super().on_json_loading_failed(e)
           ^^^^^^^^^^^^^^^^^^^^^^^^^^^^^^^^^
  File "/home/runner/workspace/.pythonlibs/lib/python3.11/site-packages/werkzeug/wrappers/request.py", line 645, in on_json_loading_failed
    raise BadRequest(f"Failed to decode JSON object: {e}")
werkzeug.exceptions.BadRequest: 400 Bad Request: Failed to decode JSON object: Expecting value: line 1 column 1 (char 0)

The above exception was the direct cause of the following exception:

Traceback (most recent call last):
  File "/home/runner/workspace/app.py", line 908, in speak
    data = request.json
           ^^^^^^^^^^^^
  File "/home/runner/workspace/.pythonlibs/lib/python3.11/site-packages/werkzeug/wrappers/request.py", line 560, in json
    return self.get_json()
           ^^^^^^^^^^^^^^^
  File "/home/runner/workspace/.pythonlibs/lib/python3.11/site-packages/werkzeug/wrappers/request.py", line 620, in get_json
    rv = self.on_json_loading_failed(e)
         ^^^^^^^^^^^^^^^^^^^^^^^^^^^^^^
  File "/home/runner/workspace/.pythonlibs/lib/python3.11/site-packages/flask/wrappers.py", line 219, in on_json_loading_failed
    raise BadRequest() from ebr
werkzeug.exceptions.BadRequest: 400 Bad Request: The browser (or proxy) sent a request that this server could not understand.

[2025-05-13 23:46:57] [INFO] [root] - Using voice: US Male (us_male)
[2025-05-13 23:46:57] [INFO] [root] - Generated speech with advanced TTS: 94ad3b543c95daee980e2dc1427206a6.mp3
[2025-05-13 23:47:04] [ERROR] [alphavox_input_nlu] - Error processing interaction for user 1: sequence index must be integer, not 'slice'
Traceback (most recent call last):
  File "/home/runner/workspace/alphavox_input_nlu.py", line 105, in process_interaction
    interaction['context'] = self._add_context(interaction, user_id)
                             ^^^^^^^^^^^^^^^^^^^^^^^^^^^^^^^^^^^^^^^
  File "/home/runner/workspace/alphavox_input_nlu.py", line 293, in _add_context
    rc['root_cause'] for rc in self.context_window[user_id].get('root_causes', [])[-5:]
                               ~~~~~~~~~~~~~~~~~~~~~~~~~~~~~~~~~~~~~~~~~~~~~~~~~~~^^^^^
TypeError: sequence index must be integer, not 'slice'
[2025-05-13 23:47:04] [INFO] [root] - Processed gesture with AlphaVox NLU: 'thumbs_up' → unknown (0.00)
[2025-05-13 23:47:05] [INFO] [root] - Using voice: US Male (us_male)
[2025-05-13 23:47:05] [INFO] [root] - Generated speech with advanced TTS: 0397cb22afd890add2438505f2346cc7.mp3
[2025-05-13 23:47:05] [ERROR] [root] - Error using AlphaVox NLU for gesture: 400 Bad Request: The browser (or proxy) sent a request that this server could not understand.
[2025-05-13 23:47:05] [ERROR] [root] - Traceback (most recent call last):
  File "/home/runner/workspace/.pythonlibs/lib/python3.11/site-packages/werkzeug/wrappers/request.py", line 611, in get_json
    rv = self.json_module.loads(data)
         ^^^^^^^^^^^^^^^^^^^^^^^^^^^^
  File "/home/runner/workspace/.pythonlibs/lib/python3.11/site-packages/flask/json/provider.py", line 187, in loads
    return json.loads(s, **kwargs)
           ^^^^^^^^^^^^^^^^^^^^^^^
  File "/nix/store/clx0mcir7qw8zk36zbr4jra789g3knf6-python3-3.11.10/lib/python3.11/json/__init__.py", line 346, in loads
    return _default_decoder.decode(s)
           ^^^^^^^^^^^^^^^^^^^^^^^^^^
  File "/nix/store/clx0mcir7qw8zk36zbr4jra789g3knf6-python3-3.11.10/lib/python3.11/json/decoder.py", line 337, in decode
    obj, end = self.raw_decode(s, idx=_w(s, 0).end())
               ^^^^^^^^^^^^^^^^^^^^^^^^^^^^^^^^^^^^^^
  File "/nix/store/clx0mcir7qw8zk36zbr4jra789g3knf6-python3-3.11.10/lib/python3.11/json/decoder.py", line 355, in raw_decode
    raise JSONDecodeError("Expecting value", s, err.value) from None
json.decoder.JSONDecodeError: Expecting value: line 1 column 1 (char 0)

During handling of the above exception, another exception occurred:

Traceback (most recent call last):
  File "/home/runner/workspace/.pythonlibs/lib/python3.11/site-packages/flask/wrappers.py", line 214, in on_json_loading_failed
    return super().on_json_loading_failed(e)
           ^^^^^^^^^^^^^^^^^^^^^^^^^^^^^^^^^
  File "/home/runner/workspace/.pythonlibs/lib/python3.11/site-packages/werkzeug/wrappers/request.py", line 645, in on_json_loading_failed
    raise BadRequest(f"Failed to decode JSON object: {e}")
werkzeug.exceptions.BadRequest: 400 Bad Request: Failed to decode JSON object: Expecting value: line 1 column 1 (char 0)

The above exception was the direct cause of the following exception:

Traceback (most recent call last):
  File "/home/runner/workspace/app.py", line 908, in speak
    data = request.json
           ^^^^^^^^^^^^
  File "/home/runner/workspace/.pythonlibs/lib/python3.11/site-packages/werkzeug/wrappers/request.py", line 560, in json
    return self.get_json()
           ^^^^^^^^^^^^^^^
  File "/home/runner/workspace/.pythonlibs/lib/python3.11/site-packages/werkzeug/wrappers/request.py", line 620, in get_json
    rv = self.on_json_loading_failed(e)
         ^^^^^^^^^^^^^^^^^^^^^^^^^^^^^^
  File "/home/runner/workspace/.pythonlibs/lib/python3.11/site-packages/flask/wrappers.py", line 219, in on_json_loading_failed
    raise BadRequest() from ebr
werkzeug.exceptions.BadRequest: 400 Bad Request: The browser (or proxy) sent a request that this server could not understand.

[2025-05-13 23:47:05] [INFO] [root] - Using voice: US Male (us_male)
[2025-05-13 23:47:05] [INFO] [root] - Generated speech with advanced TTS: d028fbe058f5cbd7a8708ba923fa3098.mp3
[2025-05-13 23:47:41] [ERROR] [alphavox_input_nlu] - Error processing interaction for user 1: sequence index must be integer, not 'slice'
Traceback (most recent call last):
  File "/home/runner/workspace/alphavox_input_nlu.py", line 105, in process_interaction
    interaction['context'] = self._add_context(interaction, user_id)
                             ^^^^^^^^^^^^^^^^^^^^^^^^^^^^^^^^^^^^^^^
  File "/home/runner/workspace/alphavox_input_nlu.py", line 293, in _add_context
    rc['root_cause'] for rc in self.context_window[user_id].get('root_causes', [])[-5:]
                               ~~~~~~~~~~~~~~~~~~~~~~~~~~~~~~~~~~~~~~~~~~~~~~~~~~~^^^^^
TypeError: sequence index must be integer, not 'slice'
[2025-05-13 23:47:41] [INFO] [root] - Processed gesture with AlphaVox NLU: 'thumbs_up' → unknown (0.00)
[2025-05-13 23:47:41] [INFO] [root] - Using voice: US Male (us_male)
[2025-05-13 23:47:41] [INFO] [root] - Generated speech with advanced TTS: 0397cb22afd890add2438505f2346cc7.mp3
[2025-05-13 23:47:41] [ERROR] [root] - Error using AlphaVox NLU for gesture: 400 Bad Request: The browser (or proxy) sent a request that this server could not understand.
[2025-05-13 23:47:41] [ERROR] [root] - Traceback (most recent call last):
  File "/home/runner/workspace/.pythonlibs/lib/python3.11/site-packages/werkzeug/wrappers/request.py", line 611, in get_json
    rv = self.json_module.loads(data)
         ^^^^^^^^^^^^^^^^^^^^^^^^^^^^
  File "/home/runner/workspace/.pythonlibs/lib/python3.11/site-packages/flask/json/provider.py", line 187, in loads
    return json.loads(s, **kwargs)
           ^^^^^^^^^^^^^^^^^^^^^^^
  File "/nix/store/clx0mcir7qw8zk36zbr4jra789g3knf6-python3-3.11.10/lib/python3.11/json/__init__.py", line 346, in loads
    return _default_decoder.decode(s)
           ^^^^^^^^^^^^^^^^^^^^^^^^^^
  File "/nix/store/clx0mcir7qw8zk36zbr4jra789g3knf6-python3-3.11.10/lib/python3.11/json/decoder.py", line 337, in decode
    obj, end = self.raw_decode(s, idx=_w(s, 0).end())
               ^^^^^^^^^^^^^^^^^^^^^^^^^^^^^^^^^^^^^^
  File "/nix/store/clx0mcir7qw8zk36zbr4jra789g3knf6-python3-3.11.10/lib/python3.11/json/decoder.py", line 355, in raw_decode
    raise JSONDecodeError("Expecting value", s, err.value) from None
json.decoder.JSONDecodeError: Expecting value: line 1 column 1 (char 0)

During handling of the above exception, another exception occurred:

Traceback (most recent call last):
  File "/home/runner/workspace/.pythonlibs/lib/python3.11/site-packages/flask/wrappers.py", line 214, in on_json_loading_failed
    return super().on_json_loading_failed(e)
           ^^^^^^^^^^^^^^^^^^^^^^^^^^^^^^^^^
  File "/home/runner/workspace/.pythonlibs/lib/python3.11/site-packages/werkzeug/wrappers/request.py", line 645, in on_json_loading_failed
    raise BadRequest(f"Failed to decode JSON object: {e}")
werkzeug.exceptions.BadRequest: 400 Bad Request: Failed to decode JSON object: Expecting value: line 1 column 1 (char 0)

The above exception was the direct cause of the following exception:

Traceback (most recent call last):
  File "/home/runner/workspace/app.py", line 908, in speak
    data = request.json
           ^^^^^^^^^^^^
  File "/home/runner/workspace/.pythonlibs/lib/python3.11/site-packages/werkzeug/wrappers/request.py", line 560, in json
    return self.get_json()
           ^^^^^^^^^^^^^^^
  File "/home/runner/workspace/.pythonlibs/lib/python3.11/site-packages/werkzeug/wrappers/request.py", line 620, in get_json
    rv = self.on_json_loading_failed(e)
         ^^^^^^^^^^^^^^^^^^^^^^^^^^^^^^
  File "/home/runner/workspace/.pythonlibs/lib/python3.11/site-packages/flask/wrappers.py", line 219, in on_json_loading_failed
    raise BadRequest() from ebr
werkzeug.exceptions.BadRequest: 400 Bad Request: The browser (or proxy) sent a request that this server could not understand.

[2025-05-13 23:47:41] [INFO] [root] - Using voice: US Male (us_male)
[2025-05-13 23:47:41] [INFO] [root] - Generated speech with advanced TTS: d028fbe058f5cbd7a8708ba923fa3098.mp3
[2025-05-13 23:48:41] [ERROR] [alphavox_input_nlu] - Error processing interaction for user 1: sequence index must be integer, not 'slice'
Traceback (most recent call last):
  File "/home/runner/workspace/alphavox_input_nlu.py", line 105, in process_interaction
    interaction['context'] = self._add_context(interaction, user_id)
                             ^^^^^^^^^^^^^^^^^^^^^^^^^^^^^^^^^^^^^^^
  File "/home/runner/workspace/alphavox_input_nlu.py", line 293, in _add_context
    rc['root_cause'] for rc in self.context_window[user_id].get('root_causes', [])[-5:]
                               ~~~~~~~~~~~~~~~~~~~~~~~~~~~~~~~~~~~~~~~~~~~~~~~~~~~^^^^^
TypeError: sequence index must be integer, not 'slice'
[2025-05-13 23:48:41] [INFO] [root] - Processed gesture with AlphaVox NLU: 'thumbs_up' → unknown (0.00)
[2025-05-13 23:48:41] [INFO] [root] - Using voice: US Male (us_male)
[2025-05-13 23:48:41] [INFO] [root] - Generated speech with advanced TTS: 0397cb22afd890add2438505f2346cc7.mp3
[2025-05-13 23:48:41] [ERROR] [root] - Error using AlphaVox NLU for gesture: 400 Bad Request: The browser (or proxy) sent a request that this server could not understand.
[2025-05-13 23:48:41] [ERROR] [root] - Traceback (most recent call last):
  File "/home/runner/workspace/.pythonlibs/lib/python3.11/site-packages/werkzeug/wrappers/request.py", line 611, in get_json
    rv = self.json_module.loads(data)
         ^^^^^^^^^^^^^^^^^^^^^^^^^^^^
  File "/home/runner/workspace/.pythonlibs/lib/python3.11/site-packages/flask/json/provider.py", line 187, in loads
    return json.loads(s, **kwargs)
           ^^^^^^^^^^^^^^^^^^^^^^^
  File "/nix/store/clx0mcir7qw8zk36zbr4jra789g3knf6-python3-3.11.10/lib/python3.11/json/__init__.py", line 346, in loads
    return _default_decoder.decode(s)
           ^^^^^^^^^^^^^^^^^^^^^^^^^^
  File "/nix/store/clx0mcir7qw8zk36zbr4jra789g3knf6-python3-3.11.10/lib/python3.11/json/decoder.py", line 337, in decode
    obj, end = self.raw_decode(s, idx=_w(s, 0).end())
               ^^^^^^^^^^^^^^^^^^^^^^^^^^^^^^^^^^^^^^
  File "/nix/store/clx0mcir7qw8zk36zbr4jra789g3knf6-python3-3.11.10/lib/python3.11/json/decoder.py", line 355, in raw_decode
    raise JSONDecodeError("Expecting value", s, err.value) from None
json.decoder.JSONDecodeError: Expecting value: line 1 column 1 (char 0)

During handling of the above exception, another exception occurred:

Traceback (most recent call last):
  File "/home/runner/workspace/.pythonlibs/lib/python3.11/site-packages/flask/wrappers.py", line 214, in on_json_loading_failed
    return super().on_json_loading_failed(e)
           ^^^^^^^^^^^^^^^^^^^^^^^^^^^^^^^^^
  File "/home/runner/workspace/.pythonlibs/lib/python3.11/site-packages/werkzeug/wrappers/request.py", line 645, in on_json_loading_failed
    raise BadRequest(f"Failed to decode JSON object: {e}")
werkzeug.exceptions.BadRequest: 400 Bad Request: Failed to decode JSON object: Expecting value: line 1 column 1 (char 0)

The above exception was the direct cause of the following exception:

Traceback (most recent call last):
  File "/home/runner/workspace/app.py", line 908, in speak
    data = request.json
           ^^^^^^^^^^^^
  File "/home/runner/workspace/.pythonlibs/lib/python3.11/site-packages/werkzeug/wrappers/request.py", line 560, in json
    return self.get_json()
           ^^^^^^^^^^^^^^^
  File "/home/runner/workspace/.pythonlibs/lib/python3.11/site-packages/werkzeug/wrappers/request.py", line 620, in get_json
    rv = self.on_json_loading_failed(e)
         ^^^^^^^^^^^^^^^^^^^^^^^^^^^^^^
  File "/home/runner/workspace/.pythonlibs/lib/python3.11/site-packages/flask/wrappers.py", line 219, in on_json_loading_failed
    raise BadRequest() from ebr
werkzeug.exceptions.BadRequest: 400 Bad Request: The browser (or proxy) sent a request that this server could not understand.

[2025-05-13 23:48:41] [INFO] [root] - Using voice: US Male (us_male)
[2025-05-13 23:48:41] [INFO] [root] - Generated speech with advanced TTS: d028fbe058f5cbd7a8708ba923fa3098.mp3
[2025-05-13 23:48:46] [ERROR] [alphavox_input_nlu] - Error processing interaction for user 1: sequence index must be integer, not 'slice'
Traceback (most recent call last):
  File "/home/runner/workspace/alphavox_input_nlu.py", line 105, in process_interaction
    interaction['context'] = self._add_context(interaction, user_id)
                             ^^^^^^^^^^^^^^^^^^^^^^^^^^^^^^^^^^^^^^^
  File "/home/runner/workspace/alphavox_input_nlu.py", line 293, in _add_context
    rc['root_cause'] for rc in self.context_window[user_id].get('root_causes', [])[-5:]
                               ~~~~~~~~~~~~~~~~~~~~~~~~~~~~~~~~~~~~~~~~~~~~~~~~~~~^^^^^
TypeError: sequence index must be integer, not 'slice'
[2025-05-13 23:48:46] [INFO] [root] - Processed gesture with AlphaVox NLU: 'point_up' → unknown (0.00)
[2025-05-13 23:48:46] [INFO] [root] - Using voice: US Male (us_male)
[2025-05-13 23:48:46] [INFO] [root] - Generated speech with advanced TTS: 080e277b12f4d2500a29df92598fa913.mp3
[2025-05-13 23:48:46] [ERROR] [root] - Error using AlphaVox NLU for gesture: 400 Bad Request: The browser (or proxy) sent a request that this server could not understand.
[2025-05-13 23:48:46] [ERROR] [root] - Traceback (most recent call last):
  File "/home/runner/workspace/.pythonlibs/lib/python3.11/site-packages/werkzeug/wrappers/request.py", line 611, in get_json
    rv = self.json_module.loads(data)
         ^^^^^^^^^^^^^^^^^^^^^^^^^^^^
  File "/home/runner/workspace/.pythonlibs/lib/python3.11/site-packages/flask/json/provider.py", line 187, in loads
    return json.loads(s, **kwargs)
           ^^^^^^^^^^^^^^^^^^^^^^^
  File "/nix/store/clx0mcir7qw8zk36zbr4jra789g3knf6-python3-3.11.10/lib/python3.11/json/__init__.py", line 346, in loads
    return _default_decoder.decode(s)
           ^^^^^^^^^^^^^^^^^^^^^^^^^^
  File "/nix/store/clx0mcir7qw8zk36zbr4jra789g3knf6-python3-3.11.10/lib/python3.11/json/decoder.py", line 337, in decode
    obj, end = self.raw_decode(s, idx=_w(s, 0).end())
               ^^^^^^^^^^^^^^^^^^^^^^^^^^^^^^^^^^^^^^
  File "/nix/store/clx0mcir7qw8zk36zbr4jra789g3knf6-python3-3.11.10/lib/python3.11/json/decoder.py", line 355, in raw_decode
    raise JSONDecodeError("Expecting value", s, err.value) from None
json.decoder.JSONDecodeError: Expecting value: line 1 column 1 (char 0)

During handling of the above exception, another exception occurred:

Traceback (most recent call last):
  File "/home/runner/workspace/.pythonlibs/lib/python3.11/site-packages/flask/wrappers.py", line 214, in on_json_loading_failed
    return super().on_json_loading_failed(e)
           ^^^^^^^^^^^^^^^^^^^^^^^^^^^^^^^^^
  File "/home/runner/workspace/.pythonlibs/lib/python3.11/site-packages/werkzeug/wrappers/request.py", line 645, in on_json_loading_failed
    raise BadRequest(f"Failed to decode JSON object: {e}")
werkzeug.exceptions.BadRequest: 400 Bad Request: Failed to decode JSON object: Expecting value: line 1 column 1 (char 0)

The above exception was the direct cause of the following exception:

Traceback (most recent call last):
  File "/home/runner/workspace/app.py", line 908, in speak
    data = request.json
           ^^^^^^^^^^^^
  File "/home/runner/workspace/.pythonlibs/lib/python3.11/site-packages/werkzeug/wrappers/request.py", line 560, in json
    return self.get_json()
           ^^^^^^^^^^^^^^^
  File "/home/runner/workspace/.pythonlibs/lib/python3.11/site-packages/werkzeug/wrappers/request.py", line 620, in get_json
    rv = self.on_json_loading_failed(e)
         ^^^^^^^^^^^^^^^^^^^^^^^^^^^^^^
  File "/home/runner/workspace/.pythonlibs/lib/python3.11/site-packages/flask/wrappers.py", line 219, in on_json_loading_failed
    raise BadRequest() from ebr
werkzeug.exceptions.BadRequest: 400 Bad Request: The browser (or proxy) sent a request that this server could not understand.

[2025-05-13 23:48:46] [INFO] [root] - Using voice: US Male (us_male)
[2025-05-13 23:48:46] [INFO] [root] - Generated speech with advanced TTS: 1f764bbdb9e8adc611a04c28fabe30d3.mp3
[2025-05-13 23:49:25] [INFO] [root] - Default logging configuration applied
[2025-05-13 23:49:25] [INFO] [adaptive_conversation] - Conversation Complexity Engine initialized
[2025-05-13 23:49:25] [INFO] [routes.adaptive_conversation_routes] - Adaptive conversation routes registered
[2025-05-13 23:49:25] [INFO] [routes.learning_routes] - Learning routes registered
[2025-05-13 23:49:25] [INFO] [routes.health_routes] - Health routes registered
[2025-05-13 23:49:25] [INFO] [main] - AlphaVox application initialized
[2025-05-13 23:49:28] [INFO] [root] - Default logging configuration applied
[2025-05-13 23:49:28] [INFO] [adaptive_conversation] - Conversation Complexity Engine initialized
[2025-05-13 23:49:28] [INFO] [routes.adaptive_conversation_routes] - Adaptive conversation routes registered
[2025-05-13 23:49:28] [INFO] [routes.learning_routes] - Learning routes registered
[2025-05-13 23:49:28] [INFO] [routes.health_routes] - Health routes registered
[2025-05-13 23:49:28] [INFO] [main] - AlphaVox application initialized
[2025-05-13 23:50:27] [INFO] [root] - Default logging configuration applied
[2025-05-13 23:50:27] [INFO] [adaptive_conversation] - Conversation Complexity Engine initialized
[2025-05-13 23:50:27] [INFO] [routes.adaptive_conversation_routes] - Adaptive conversation routes registered
[2025-05-13 23:50:27] [INFO] [routes.learning_routes] - Learning routes registered
[2025-05-13 23:50:27] [INFO] [routes.health_routes] - Health routes registered
[2025-05-13 23:50:27] [INFO] [main] - AlphaVox application initialized
[2025-05-13 23:51:36] [INFO] [root] - Default logging configuration applied
[2025-05-13 23:51:37] [INFO] [adaptive_conversation] - Conversation Complexity Engine initialized
[2025-05-13 23:51:37] [INFO] [routes.adaptive_conversation_routes] - Adaptive conversation routes registered
[2025-05-13 23:51:37] [INFO] [routes.learning_routes] - Learning routes registered
[2025-05-13 23:51:37] [INFO] [routes.health_routes] - Health routes registered
[2025-05-13 23:51:37] [INFO] [main] - AlphaVox application initialized
[2025-05-13 23:52:12] [INFO] [nonverbal_engine] - Initializing NonverbalEngine with self-learning capabilities
[2025-05-13 23:52:12] [INFO] [nonverbal_engine] - NonverbalEngine initialized with self-modification capabilities
[2025-05-13 23:52:12] [INFO] [real_eye_tracking] - Real eye tracking service initialized
[2025-05-13 23:52:12] [INFO] [root] - Using real eye tracking service
[2025-05-13 23:52:12] [WARNING] [root] - Real speech recognition not available: PortAudio library not found, using simulated service
[2025-05-13 23:52:12] [INFO] [sound_recognition_service] - Initializing SoundRecognitionService
[2025-05-13 23:52:12] [INFO] [attached_assets.speech_recognition_engine] - Speech Recognition Engine initialized with language: en-US
[2025-05-13 23:52:12] [INFO] [sound_recognition_service] - Using simulated speech recognition engine
[2025-05-13 23:52:12] [INFO] [sound_recognition_service] - Using real speech recognition engine
[2025-05-13 23:52:12] [INFO] [sound_recognition_service] - SoundRecognitionService initialized
[2025-05-13 23:52:12] [INFO] [behavior_capture] - Initialized behavior capture processors
[2025-05-13 23:52:12] [INFO] [root] - Behavior capture system initialized
[2025-05-13 23:52:12] [INFO] [root] - Initialized AI self-learning and self-modification capabilities
[2025-05-13 23:52:12] [INFO] [nonverbal_engine] - Initializing NonverbalEngine with self-learning capabilities
[2025-05-13 23:52:12] [INFO] [nonverbal_engine] - NonverbalEngine initialized with self-modification capabilities
[2025-05-13 23:52:12] [INFO] [conversation_engine] - Conversation engine initialized
[2025-05-13 23:52:12] [INFO] [input_analyzer] - Input analyzer initialized
[2025-05-13 23:52:12] [INFO] [behavioral_interpreter] - Behavioral interpreter initialized
[2025-05-13 23:52:12] [INFO] [interpreter] - Interpreter initialized
[2025-05-13 23:52:12] [INFO] [root] - Advanced AI interpreter initialized
[2025-05-13 23:52:12] [INFO] [root] - All advanced AI components initialized
[2025-05-13 23:52:12] [INFO] [modules.knowledge_integration] - Knowledge engine loaded
[2025-05-13 23:52:12] [INFO] [modules.knowledge_integration] - Loaded 15 facts from knowledge base
[2025-05-13 23:52:12] [INFO] [modules.knowledge_integration] - Loaded 10 topics from knowledge base
[2025-05-13 23:52:12] [INFO] [modules.knowledge_integration] - Loaded knowledge graph with 2 nodes
[2025-05-13 23:52:12] [INFO] [modules.knowledge_integration] - Knowledge Integration initialized
[2025-05-13 23:52:12] [INFO] [root] - Knowledge integration initialized
[2025-05-13 23:52:12] [ERROR] [root] - Error initializing integration modules: PortAudio library not found
[2025-05-13 23:52:12] [ERROR] [root] - Traceback (most recent call last):
  File "/home/runner/workspace/app.py", line 153, in init_services
    speech_integration = get_speech_integration()
                         ^^^^^^^^^^^^^^^^^^^^^^^^
  File "/home/runner/workspace/modules/speech_integration.py", line 177, in get_speech_integration
    _speech_integration = SpeechIntegration()
                          ^^^^^^^^^^^^^^^^^^^
  File "/home/runner/workspace/modules/speech_integration.py", line 45, in __init__
    self._initialize_components()
  File "/home/runner/workspace/modules/speech_integration.py", line 53, in _initialize_components
    from real_speech_recognition import get_speech_recognition_engine
  File "/home/runner/workspace/real_speech_recognition.py", line 13, in <module>
    import sounddevice as sd
  File "/home/runner/workspace/.pythonlibs/lib/python3.11/site-packages/sounddevice.py", line 71, in <module>
    raise OSError('PortAudio library not found')
OSError: PortAudio library not found

[2025-05-13 23:52:46] [INFO] [root] - Default logging configuration applied
[2025-05-13 23:52:46] [INFO] [adaptive_conversation] - Conversation Complexity Engine initialized
[2025-05-13 23:52:46] [INFO] [routes.adaptive_conversation_routes] - Adaptive conversation routes registered
[2025-05-13 23:52:46] [INFO] [routes.learning_routes] - Learning routes registered
[2025-05-13 23:52:46] [INFO] [routes.health_routes] - Health routes registered
[2025-05-13 23:52:46] [INFO] [main] - AlphaVox application initialized
[2025-05-13 23:52:46] [INFO] [root] - Using voice: US Male (us_male)
[2025-05-13 23:52:46] [INFO] [root] - Generated speech with advanced TTS: 2e565dc8de98e0705a86dd0c1641289b.mp3
[2025-05-13 23:52:46] [INFO] [root] - Speaking greeting: Good evening! Welcome back, Ev...
[2025-05-13 23:52:47] [INFO] [root] - Using voice: US Male (us_male)
[2025-05-13 23:52:47] [INFO] [root] - Generated speech with advanced TTS: 2e565dc8de98e0705a86dd0c1641289b.mp3
[2025-05-13 23:52:47] [INFO] [root] - Speaking greeting: Good evening! Welcome back, Ev...
[2025-05-13 23:53:21] [ERROR] [neural_learning_core] - Failed to load spaCy model: [E050] Can't find model 'en_core_web_sm'. It doesn't seem to be a Python package or a valid path to a data directory.
[2025-05-13 23:53:21] [INFO] [neural_learning_core] - Creating a basic spaCy model as fallback
[2025-05-13 23:53:21] [ERROR] [research_module] - Failed to load spaCy model: [E050] Can't find model 'en_core_web_sm'. It doesn't seem to be a Python package or a valid path to a data directory.
[2025-05-13 23:53:21] [INFO] [research_module] - Install spaCy and download model: pip install spacy && python -m spacy download en_core_web_sm
[2025-05-13 23:53:21] [ERROR] [alphavox_input_nlu] - Failed to load spaCy model: [E050] Can't find model 'en_core_web_sm'. It doesn't seem to be a Python package or a valid path to a data directory.
[2025-05-13 23:53:21] [INFO] [alphavox_input_nlu] - Install spaCy and download model: pip install spacy && python -m spacy download en_core_web_sm
[2025-05-13 23:53:21] [INFO] [neural_learning_core] - Loaded 1 interactions from memory
[2025-05-13 23:53:21] [INFO] [neural_learning_core] - Root cause model initialized
[2025-05-13 23:53:21] [INFO] [neural_learning_core] - Neural Learning Core initialized
[2025-05-13 23:53:21] [INFO] [research_module] - Loaded valid research cache
[2025-05-13 23:53:21] [INFO] [research_module] - AlphaVox Research Module initialized
[2025-05-13 23:53:21] [INFO] [alphavox_input_nlu] - Loaded context window with 1 users
[2025-05-13 23:53:21] [INFO] [research_module] - Using cached research articles
[2025-05-13 23:53:21] [WARNING] [research_module] - No articles to analyze
[2025-05-13 23:53:21] [INFO] [neural_learning_core] - Loaded 1 interactions from memory
[2025-05-13 23:53:21] [INFO] [neural_learning_core] - Root cause model initialized
[2025-05-13 23:53:21] [INFO] [neural_learning_core] - Neural Learning Core initialized
[2025-05-13 23:53:21] [INFO] [research_module] - Integrated research insights into Neural Learning Core
[2025-05-13 23:53:21] [INFO] [research_module] - Integrated 0 strategies, 0 intents
[2025-05-13 23:53:21] [INFO] [alphavox_input_nlu] - Updated input processor with research insights
[2025-05-13 23:53:21] [INFO] [alphavox_input_nlu] - Saved context window for 1 users
[2025-05-13 23:53:21] [INFO] [alphavox_input_nlu] - AlphaVoxInputProcessor initialized
[2025-05-13 23:53:21] [ERROR] [alphavox_input_nlu] - Error processing interaction for user 1: sequence index must be integer, not 'slice'
Traceback (most recent call last):
  File "/home/runner/workspace/alphavox_input_nlu.py", line 105, in process_interaction
    interaction['context'] = self._add_context(interaction, user_id)
                             ^^^^^^^^^^^^^^^^^^^^^^^^^^^^^^^^^^^^^^^
  File "/home/runner/workspace/alphavox_input_nlu.py", line 293, in _add_context
    rc['root_cause'] for rc in self.context_window[user_id].get('root_causes', [])[-5:]
                               ~~~~~~~~~~~~~~~~~~~~~~~~~~~~~~~~~~~~~~~~~~~~~~~~~~~^^^^^
TypeError: sequence index must be integer, not 'slice'
[2025-05-13 23:53:21] [INFO] [root] - Processed gesture with AlphaVox NLU: 'nod' → unknown (0.00)
[2025-05-13 23:53:21] [INFO] [root] - Using voice: US Male (us_male)
[2025-05-13 23:53:21] [INFO] [root] - Generated speech with advanced TTS: aaaf28040d070cff5aae5a0baa9ca965.mp3
[2025-05-13 23:53:21] [ERROR] [root] - Error using AlphaVox NLU for gesture: 400 Bad Request: The browser (or proxy) sent a request that this server could not understand.
[2025-05-13 23:53:21] [ERROR] [root] - Traceback (most recent call last):
  File "/home/runner/workspace/.pythonlibs/lib/python3.11/site-packages/werkzeug/wrappers/request.py", line 611, in get_json
    rv = self.json_module.loads(data)
         ^^^^^^^^^^^^^^^^^^^^^^^^^^^^
  File "/home/runner/workspace/.pythonlibs/lib/python3.11/site-packages/flask/json/provider.py", line 187, in loads
    return json.loads(s, **kwargs)
           ^^^^^^^^^^^^^^^^^^^^^^^
  File "/nix/store/clx0mcir7qw8zk36zbr4jra789g3knf6-python3-3.11.10/lib/python3.11/json/__init__.py", line 346, in loads
    return _default_decoder.decode(s)
           ^^^^^^^^^^^^^^^^^^^^^^^^^^
  File "/nix/store/clx0mcir7qw8zk36zbr4jra789g3knf6-python3-3.11.10/lib/python3.11/json/decoder.py", line 337, in decode
    obj, end = self.raw_decode(s, idx=_w(s, 0).end())
               ^^^^^^^^^^^^^^^^^^^^^^^^^^^^^^^^^^^^^^
  File "/nix/store/clx0mcir7qw8zk36zbr4jra789g3knf6-python3-3.11.10/lib/python3.11/json/decoder.py", line 355, in raw_decode
    raise JSONDecodeError("Expecting value", s, err.value) from None
json.decoder.JSONDecodeError: Expecting value: line 1 column 1 (char 0)

During handling of the above exception, another exception occurred:

Traceback (most recent call last):
  File "/home/runner/workspace/.pythonlibs/lib/python3.11/site-packages/flask/wrappers.py", line 214, in on_json_loading_failed
    return super().on_json_loading_failed(e)
           ^^^^^^^^^^^^^^^^^^^^^^^^^^^^^^^^^
  File "/home/runner/workspace/.pythonlibs/lib/python3.11/site-packages/werkzeug/wrappers/request.py", line 645, in on_json_loading_failed
    raise BadRequest(f"Failed to decode JSON object: {e}")
werkzeug.exceptions.BadRequest: 400 Bad Request: Failed to decode JSON object: Expecting value: line 1 column 1 (char 0)

The above exception was the direct cause of the following exception:

Traceback (most recent call last):
  File "/home/runner/workspace/app.py", line 908, in speak
    data = request.json
           ^^^^^^^^^^^^
  File "/home/runner/workspace/.pythonlibs/lib/python3.11/site-packages/werkzeug/wrappers/request.py", line 560, in json
    return self.get_json()
           ^^^^^^^^^^^^^^^
  File "/home/runner/workspace/.pythonlibs/lib/python3.11/site-packages/werkzeug/wrappers/request.py", line 620, in get_json
    rv = self.on_json_loading_failed(e)
         ^^^^^^^^^^^^^^^^^^^^^^^^^^^^^^
  File "/home/runner/workspace/.pythonlibs/lib/python3.11/site-packages/flask/wrappers.py", line 219, in on_json_loading_failed
    raise BadRequest() from ebr
werkzeug.exceptions.BadRequest: 400 Bad Request: The browser (or proxy) sent a request that this server could not understand.

[2025-05-13 23:53:21] [INFO] [root] - Using voice: US Male (us_male)
[2025-05-13 23:53:21] [INFO] [root] - Generated speech with advanced TTS: 94ad3b543c95daee980e2dc1427206a6.mp3
[2025-05-13 23:55:24] [ERROR] [alphavox_input_nlu] - Error processing interaction for user 1: sequence index must be integer, not 'slice'
Traceback (most recent call last):
  File "/home/runner/workspace/alphavox_input_nlu.py", line 105, in process_interaction
    interaction['context'] = self._add_context(interaction, user_id)
                             ^^^^^^^^^^^^^^^^^^^^^^^^^^^^^^^^^^^^^^^
  File "/home/runner/workspace/alphavox_input_nlu.py", line 293, in _add_context
    rc['root_cause'] for rc in self.context_window[user_id].get('root_causes', [])[-5:]
                               ~~~~~~~~~~~~~~~~~~~~~~~~~~~~~~~~~~~~~~~~~~~~~~~~~~~^^^^^
TypeError: sequence index must be integer, not 'slice'
[2025-05-13 23:55:24] [INFO] [root] - Processed gesture with AlphaVox NLU: 'nod' → unknown (0.00)
[2025-05-13 23:55:24] [INFO] [root] - Using voice: US Male (us_male)
[2025-05-13 23:55:24] [INFO] [root] - Generated speech with advanced TTS: aaaf28040d070cff5aae5a0baa9ca965.mp3
[2025-05-13 23:55:24] [ERROR] [root] - Error using AlphaVox NLU for gesture: 400 Bad Request: The browser (or proxy) sent a request that this server could not understand.
[2025-05-13 23:55:24] [ERROR] [root] - Traceback (most recent call last):
  File "/home/runner/workspace/.pythonlibs/lib/python3.11/site-packages/werkzeug/wrappers/request.py", line 611, in get_json
    rv = self.json_module.loads(data)
         ^^^^^^^^^^^^^^^^^^^^^^^^^^^^
  File "/home/runner/workspace/.pythonlibs/lib/python3.11/site-packages/flask/json/provider.py", line 187, in loads
    return json.loads(s, **kwargs)
           ^^^^^^^^^^^^^^^^^^^^^^^
  File "/nix/store/clx0mcir7qw8zk36zbr4jra789g3knf6-python3-3.11.10/lib/python3.11/json/__init__.py", line 346, in loads
    return _default_decoder.decode(s)
           ^^^^^^^^^^^^^^^^^^^^^^^^^^
  File "/nix/store/clx0mcir7qw8zk36zbr4jra789g3knf6-python3-3.11.10/lib/python3.11/json/decoder.py", line 337, in decode
    obj, end = self.raw_decode(s, idx=_w(s, 0).end())
               ^^^^^^^^^^^^^^^^^^^^^^^^^^^^^^^^^^^^^^
  File "/nix/store/clx0mcir7qw8zk36zbr4jra789g3knf6-python3-3.11.10/lib/python3.11/json/decoder.py", line 355, in raw_decode
    raise JSONDecodeError("Expecting value", s, err.value) from None
json.decoder.JSONDecodeError: Expecting value: line 1 column 1 (char 0)

During handling of the above exception, another exception occurred:

Traceback (most recent call last):
  File "/home/runner/workspace/.pythonlibs/lib/python3.11/site-packages/flask/wrappers.py", line 214, in on_json_loading_failed
    return super().on_json_loading_failed(e)
           ^^^^^^^^^^^^^^^^^^^^^^^^^^^^^^^^^
  File "/home/runner/workspace/.pythonlibs/lib/python3.11/site-packages/werkzeug/wrappers/request.py", line 645, in on_json_loading_failed
    raise BadRequest(f"Failed to decode JSON object: {e}")
werkzeug.exceptions.BadRequest: 400 Bad Request: Failed to decode JSON object: Expecting value: line 1 column 1 (char 0)

The above exception was the direct cause of the following exception:

Traceback (most recent call last):
  File "/home/runner/workspace/app.py", line 908, in speak
    data = request.json
           ^^^^^^^^^^^^
  File "/home/runner/workspace/.pythonlibs/lib/python3.11/site-packages/werkzeug/wrappers/request.py", line 560, in json
    return self.get_json()
           ^^^^^^^^^^^^^^^
  File "/home/runner/workspace/.pythonlibs/lib/python3.11/site-packages/werkzeug/wrappers/request.py", line 620, in get_json
    rv = self.on_json_loading_failed(e)
         ^^^^^^^^^^^^^^^^^^^^^^^^^^^^^^
  File "/home/runner/workspace/.pythonlibs/lib/python3.11/site-packages/flask/wrappers.py", line 219, in on_json_loading_failed
    raise BadRequest() from ebr
werkzeug.exceptions.BadRequest: 400 Bad Request: The browser (or proxy) sent a request that this server could not understand.

[2025-05-13 23:55:24] [INFO] [root] - Using voice: US Male (us_male)
[2025-05-13 23:55:24] [INFO] [root] - Generated speech with advanced TTS: 94ad3b543c95daee980e2dc1427206a6.mp3
[2025-05-14 00:05:26] [ERROR] [root] - Error using AlphaVox NLU for gesture: 400 Bad Request: The browser (or proxy) sent a request that this server could not understand.
[2025-05-14 00:05:26] [ERROR] [root] - Traceback (most recent call last):
  File "/home/runner/workspace/.pythonlibs/lib/python3.11/site-packages/werkzeug/wrappers/request.py", line 611, in get_json
    rv = self.json_module.loads(data)
         ^^^^^^^^^^^^^^^^^^^^^^^^^^^^
  File "/home/runner/workspace/.pythonlibs/lib/python3.11/site-packages/flask/json/provider.py", line 187, in loads
    return json.loads(s, **kwargs)
           ^^^^^^^^^^^^^^^^^^^^^^^
  File "/nix/store/clx0mcir7qw8zk36zbr4jra789g3knf6-python3-3.11.10/lib/python3.11/json/__init__.py", line 346, in loads
    return _default_decoder.decode(s)
           ^^^^^^^^^^^^^^^^^^^^^^^^^^
  File "/nix/store/clx0mcir7qw8zk36zbr4jra789g3knf6-python3-3.11.10/lib/python3.11/json/decoder.py", line 337, in decode
    obj, end = self.raw_decode(s, idx=_w(s, 0).end())
               ^^^^^^^^^^^^^^^^^^^^^^^^^^^^^^^^^^^^^^
  File "/nix/store/clx0mcir7qw8zk36zbr4jra789g3knf6-python3-3.11.10/lib/python3.11/json/decoder.py", line 355, in raw_decode
    raise JSONDecodeError("Expecting value", s, err.value) from None
json.decoder.JSONDecodeError: Expecting value: line 1 column 1 (char 0)

During handling of the above exception, another exception occurred:

Traceback (most recent call last):
  File "/home/runner/workspace/.pythonlibs/lib/python3.11/site-packages/flask/wrappers.py", line 214, in on_json_loading_failed
    return super().on_json_loading_failed(e)
           ^^^^^^^^^^^^^^^^^^^^^^^^^^^^^^^^^
  File "/home/runner/workspace/.pythonlibs/lib/python3.11/site-packages/werkzeug/wrappers/request.py", line 645, in on_json_loading_failed
    raise BadRequest(f"Failed to decode JSON object: {e}")
werkzeug.exceptions.BadRequest: 400 Bad Request: Failed to decode JSON object: Expecting value: line 1 column 1 (char 0)

The above exception was the direct cause of the following exception:

Traceback (most recent call last):
  File "/home/runner/workspace/app.py", line 908, in speak
    data = request.json
           ^^^^^^^^^^^^
  File "/home/runner/workspace/.pythonlibs/lib/python3.11/site-packages/werkzeug/wrappers/request.py", line 560, in json
    return self.get_json()
           ^^^^^^^^^^^^^^^
  File "/home/runner/workspace/.pythonlibs/lib/python3.11/site-packages/werkzeug/wrappers/request.py", line 620, in get_json
    rv = self.on_json_loading_failed(e)
         ^^^^^^^^^^^^^^^^^^^^^^^^^^^^^^
  File "/home/runner/workspace/.pythonlibs/lib/python3.11/site-packages/flask/wrappers.py", line 219, in on_json_loading_failed
    raise BadRequest() from ebr
werkzeug.exceptions.BadRequest: 400 Bad Request: The browser (or proxy) sent a request that this server could not understand.

[2025-05-14 00:05:27] [INFO] [root] - Using voice: US Male (us_male)
[2025-05-14 00:05:27] [INFO] [root] - Generated speech with advanced TTS: 94ad3b543c95daee980e2dc1427206a6.mp3
[2025-05-14 00:05:27] [ERROR] [alphavox_input_nlu] - Error processing interaction for user 1: sequence index must be integer, not 'slice'
Traceback (most recent call last):
  File "/home/runner/workspace/alphavox_input_nlu.py", line 105, in process_interaction
    interaction['context'] = self._add_context(interaction, user_id)
                             ^^^^^^^^^^^^^^^^^^^^^^^^^^^^^^^^^^^^^^^
  File "/home/runner/workspace/alphavox_input_nlu.py", line 293, in _add_context
    rc['root_cause'] for rc in self.context_window[user_id].get('root_causes', [])[-5:]
                               ~~~~~~~~~~~~~~~~~~~~~~~~~~~~~~~~~~~~~~~~~~~~~~~~~~~^^^^^
TypeError: sequence index must be integer, not 'slice'
[2025-05-14 00:05:27] [INFO] [root] - Processed gesture with AlphaVox NLU: 'nod' → unknown (0.00)
[2025-05-14 00:05:27] [INFO] [root] - Using voice: US Male (us_male)
[2025-05-14 00:05:27] [INFO] [root] - Generated speech with advanced TTS: aaaf28040d070cff5aae5a0baa9ca965.mp3
[2025-05-20 18:13:50] [INFO] [root] - Default logging configuration applied
[2025-05-20 18:13:50] [INFO] [adaptive_conversation] - Conversation Complexity Engine initialized
[2025-05-20 18:15:29] [INFO] [root] - Default logging configuration applied
[2025-05-20 18:15:29] [INFO] [adaptive_conversation] - Conversation Complexity Engine initialized
[2025-05-20 18:15:29] [INFO] [routes.adaptive_conversation_routes] - Adaptive conversation routes registered
[2025-05-20 18:15:29] [INFO] [routes.learning_routes] - Learning routes registered
[2025-05-20 18:15:29] [INFO] [routes.health_routes] - Health routes registered
[2025-05-20 18:15:29] [INFO] [main] - AlphaVox application initialized
[2025-05-20 18:16:06] [INFO] [learning_analytics] - Initializing LearningAnalytics for user None
[2025-05-20 18:16:06] [INFO] [nonverbal_engine] - Initializing NonverbalEngine with self-learning capabilities
[2025-05-20 18:16:06] [INFO] [nonverbal_engine] - Loaded usage stats with 2 entries
[2025-05-20 18:16:06] [INFO] [nonverbal_engine] - NonverbalEngine initialized with self-modification capabilities
[2025-05-20 18:16:06] [INFO] [real_eye_tracking] - Real eye tracking service initialized
[2025-05-20 18:16:06] [INFO] [root] - Using real eye tracking service
[2025-05-20 18:16:07] [WARNING] [root] - Real speech recognition not available: PortAudio library not found, using simulated service
[2025-05-20 18:16:07] [INFO] [sound_recognition_service] - Initializing SoundRecognitionService
[2025-05-20 18:16:07] [INFO] [attached_assets.speech_recognition_engine] - Speech Recognition Engine initialized with language: en-US
[2025-05-20 18:16:07] [INFO] [sound_recognition_service] - Using simulated speech recognition engine
[2025-05-20 18:16:07] [INFO] [sound_recognition_service] - Using real speech recognition engine
[2025-05-20 18:16:07] [INFO] [sound_recognition_service] - SoundRecognitionService initialized
[2025-05-20 18:16:07] [INFO] [behavior_capture] - Initialized behavior capture processors
[2025-05-20 18:16:07] [INFO] [root] - Behavior capture system initialized
[2025-05-20 18:16:07] [INFO] [root] - Initialized AI self-learning and self-modification capabilities
[2025-05-20 18:16:07] [INFO] [nonverbal_engine] - Initializing NonverbalEngine with self-learning capabilities
[2025-05-20 18:16:07] [INFO] [nonverbal_engine] - Loaded usage stats with 2 entries
[2025-05-20 18:16:07] [INFO] [nonverbal_engine] - NonverbalEngine initialized with self-modification capabilities
[2025-05-20 18:16:07] [INFO] [conversation_engine] - Conversation engine initialized
[2025-05-20 18:16:07] [INFO] [input_analyzer] - Input analyzer initialized
[2025-05-20 18:16:07] [INFO] [behavioral_interpreter] - Behavioral interpreter initialized
[2025-05-20 18:16:07] [INFO] [interpreter] - Interpreter initialized
[2025-05-20 18:16:07] [INFO] [root] - Advanced AI interpreter initialized
[2025-05-20 18:16:07] [INFO] [root] - All advanced AI components initialized
[2025-05-20 18:16:07] [INFO] [modules.knowledge_integration] - Knowledge engine loaded
[2025-05-20 18:16:07] [INFO] [modules.knowledge_integration] - Loaded 15 facts from knowledge base
[2025-05-20 18:16:07] [INFO] [modules.knowledge_integration] - Loaded 10 topics from knowledge base
[2025-05-20 18:16:07] [INFO] [modules.knowledge_integration] - Loaded knowledge graph with 2 nodes
[2025-05-20 18:16:07] [INFO] [modules.knowledge_integration] - Knowledge Integration initialized
[2025-05-20 18:16:07] [INFO] [root] - Knowledge integration initialized
[2025-05-20 18:16:07] [ERROR] [root] - Error initializing integration modules: PortAudio library not found
[2025-05-20 18:16:07] [ERROR] [root] - Traceback (most recent call last):
  File "/home/runner/workspace/app.py", line 204, in init_services
    speech_integration = get_speech_integration()
                         ^^^^^^^^^^^^^^^^^^^^^^^^
  File "/home/runner/workspace/modules/speech_integration.py", line 177, in get_speech_integration
    _speech_integration = SpeechIntegration()
                          ^^^^^^^^^^^^^^^^^^^
  File "/home/runner/workspace/modules/speech_integration.py", line 45, in __init__
    self._initialize_components()
  File "/home/runner/workspace/modules/speech_integration.py", line 53, in _initialize_components
    from real_speech_recognition import get_speech_recognition_engine
  File "/home/runner/workspace/real_speech_recognition.py", line 13, in <module>
    import sounddevice as sd
  File "/home/runner/workspace/.pythonlibs/lib/python3.11/site-packages/sounddevice.py", line 71, in <module>
    raise OSError('PortAudio library not found')
OSError: PortAudio library not found

[2025-05-20 18:16:07] [ERROR] [root] - Error getting color scheme: Entity namespace for "user_preference" has no property "preference_type"
[2025-05-20 18:16:39] [INFO] [root] - Default logging configuration applied
[2025-05-20 18:16:39] [INFO] [adaptive_conversation] - Conversation Complexity Engine initialized
[2025-05-20 18:16:39] [INFO] [routes.adaptive_conversation_routes] - Adaptive conversation routes registered
[2025-05-20 18:16:40] [INFO] [routes.learning_routes] - Learning routes registered
[2025-05-20 18:16:40] [INFO] [routes.health_routes] - Health routes registered
[2025-05-20 18:16:40] [INFO] [main] - AlphaVox application initialized
[2025-05-20 18:16:40] [INFO] [root] - Using voice: US Male (us_male)
[2025-05-20 18:16:41] [INFO] [root] - Generated speech with advanced TTS: 28989e304f63e5a009ced8b0e9fd1622.mp3
[2025-05-20 18:16:41] [INFO] [root] - Speaking greeting: Good afternoon! Welcome back, ...
[2025-05-20 18:16:41] [INFO] [root] - Using voice: US Male (us_male)
[2025-05-20 18:16:41] [INFO] [root] - Generated speech with advanced TTS: 28989e304f63e5a009ced8b0e9fd1622.mp3
[2025-05-20 18:16:41] [INFO] [root] - Speaking greeting: Good afternoon! Welcome back, ...
[2025-05-20 18:16:48] [INFO] [learning_journey] - LearningJourney initialized
[2025-05-20 18:16:48] [ERROR] [root] - Error getting color scheme: Entity namespace for "user_preference" has no property "preference_type"
[2025-05-20 18:17:02] [ERROR] [root] - Error getting color scheme: Entity namespace for "user_preference" has no property "preference_type"
